Workbook

Sheet 销售需求表
A1: 2025年7月外贸印尼计划需求
A2: 产品名称
A3: ID10.00-20-14PR[CR918]威狮 | B3: 450 | C3: 北美 | D3: =MID(A3,FIND("-",A3)+1,2) | E3: 载重 | F3: =E3&D3&"寸"
A4: ID10.00-20-16PR[CR952]146/142G 威狮 | B4: 280 | C4: 亚 | D4: =MID(A4,FIND("-",A4)+1,2) | E4: 载重 | F4: =E4&D4&"寸"
A5: ID10.00-20-16PR[R9037]146/142G 朝阳 | B5: 2000 | C5: 亚 | D5: =MID(A5,FIND("-",A5)+1,2) | E5: 载重 | F5: =E5&D5&"寸"
A6: ID10.00-20-16PR[R9037]146/142G 金冠 | B6: 2000 | C6: 亚 | D6: =MID(A6,FIND("-",A6)+1,2) | E6: 载重 | F6: =E6&D6&"寸"
A7: ID10.00-20-18PR[AB111]150/145G ASCENDO | B7: 180 | C7: 亚 | D7: =MID(A7,FIND("-",A7)+1,2) | E7: 载重 | F7: =E7&D7&"寸"
A8: ID10.00-20-18PR[AB316]150/145G ASCENDO | B8: 500 | C8: 亚 | D8: =MID(A8,FIND("-",A8)+1,2) | E8: 载重 | F8: =E8&D8&"寸"
A9: ID10.00-20-18PR[CL956]150/145G 金冠 | B9: 1000 | C9: 亚 | D9: =MID(A9,FIND("-",A9)+1,2) | E9: 载重 | F9: =E9&D9&"寸"
A10: ID10.00-20-18PR[CR952]150/145G TRAZANO(全诺) | B10: 2000 | C10: 亚 | D10: =MID(A10,FIND("-",A10)+1,2) | E10: 载重 | F10: =E10&D10&"寸"
A11: ID10.00-20-18PR[CR952]150/145G 金冠 | B11: 2000 | C11: 亚 | D11: =MID(A11,FIND("-",A11)+1,2) | E11: 载重 | F11: =E11&D11&"寸"
A12: ID10.00-20-18PR[CR952]150/145G 威狮 | B12: 560 | C12: 亚 | D12: =MID(A12,FIND("-",A12)+1,2) | E12: 载重 | F12: =E12&D12&"寸"
A13: ID10.00-20-18PR[M9097]150/145G 朝阳 | B13: 2000 | C13: 亚 | D13: =MID(A13,FIND("-",A13)+1,2) | E13: 载重 | F13: =E13&D13&"寸"
A14: ID10.00-20-18PR[M9097]150/145G 金冠 | B14: 850 | C14: 亚 | D14: =MID(A14,FIND("-",A14)+1,2) | E14: 载重 | F14: =E14&D14&"寸"
... A41: ID7.50-16LT-14PR[MX882]122/118K 威狮 | B41: 1300 | C41: 亚 | D41: =MID(A41,FIND("-",A41)+1,2) | E41: 轻卡 | F41: =E41&D41&"寸"
A42: IDST205/75D15-6PR[TE898]101/97L TRANSEAGLE无内 | B42: 500 | C42: 北美 | D42: =MID(A42,FIND("-",A42)-2,2) | E42: ST | F42: =E42&D42&"寸"
A43: IDST205/75R14-8PR[ST Radial]105/101M Tamarack无内 NR | B43: 12000 | C43: 北美 | D43: =MID(A43,FIND("-",A43)-2,2) | E43: 半钢ST | F43: =E43&D43&"寸"
A44: IDST205/75R15-8PR[ST226]107/102L CASTLE ROCK无内 NR | B44: 5900 | C44: 北美 | D44: =MID(A44,FIND("-",A44)-2,2) | E44: 半钢ST | F44: =E44&D44&"寸"
A45: IDST225/75R15-10PR[ST Radial]117/112M Tamarack无内 NR | B45: 1000 | C45: 北美 | D45: =MID(A45,FIND("-",A45)-2,2) | E45: 半钢ST | F45: =E45&D45&"寸"
A46: IDST225/75R15-8PR[ST Radial]113/108M Tamarack无内 NR | B46: 1300 | C46: 北美 | D46: =MID(A46,FIND("-",A46)-2,2) | E46: 半钢ST | F46: =E46&D46&"寸"
A47: IDST235/80R16-10PR[ST226]124/120L CASTLE ROCK无内 NR | B47: 5300 | C47: 北美 | D47: =MID(A47,FIND("-",A47)-2,2) | E47: 半钢ST | F47: =E47&D47&"寸"
A48: IDST235/85R16-12PR[ST Radial]128/124M Tamarack无内 NR | B48: 350 | C48: 北美 | D48: =MID(A48,FIND("-",A48)-2,2) | E48: 半钢ST | F48: =E48&D48&"寸"
A49: ID14.5/75-16.1SL-10PR[STRONG GUARD F-3]121A8 HERCULES无内 | B49: 140 | C49: 天津 | D49: =MID(A49,FIND("-",A49)+1,4) | E49: ATD | F49: =E49&D49&"寸"
A50: ID23.5-25-20PR[T318]天力 | B50: 40 | C50: OTR | D50: =MID(A50,FIND("-",A50)+1,2) | E50: 工程胎 | F50: =E50&D50&"寸"
A51: ID23.5-25-24PR[CL728]威狮 东南亚 | B51: 240 | C51: 亚 | D51: =MID(A51,FIND("-",A51)+1,2) | E51: 工程胎 | F51: =E51&D51&"寸"
A52: ID23×8.50-12-6PR[STRONG GUARD SS]101A2 HERCULES无内 | B52: 160 | C52: 天津 | D52: =MID(A52,FIND("-",A52)+1,2) | E52: ATD | F52: =E52&D52&"寸"
A53: ID26×12-12-8PR[STRONG GUARD R1]119A2 HERCULES无内 | B53: 250 | C53: 天津 | D53: =MID(A53,FIND("-",A53)+1,2) | E53: ATD | F53: =E53&D53&"寸"
A54: ID27×8.5-15-8PR[STRONG GUARD SS]HERCULES无内 | B54: 420 | C54: 天津 | D54: =MID(A54,FIND("-",A54)+1,2) | E54: ATD | F54: =E54&D54&"寸"
A55: ID29×12.5-15-8PR[STRONG GUARD R1]123A2 HERCULES无内 | B55: 100 | C55: 天津 | D55: =MID(A55,FIND("-",A55)+1,2) | E55: ATD | F55: =E55&D55&"寸"
A56: ID5.70-12-6PR[STRONG GUARD SS]97A2 HERCULES无内 | B56: 180 | C56: 天津 | D56: =MID(A56,FIND("-",A56)+1,2) | E56: ATD | F56: =E56&D56&"寸"
B58: =SUM(B3:B57)
A63: ID11R22.5-14PR(144/142M)[AT552]ARISUN无内 | B63: 700 | C63: 亚 | D63: =MID(A63,FIND("R",A63)+1,4) | E63: =_xlfn.XLOOKUP(A63,'7月排产计划'!G:G,'7月排产计划'!B:B) | F63: =E63&D63&"寸" | G63: 全钢 | H63: =D63&G63
A64: ID11R22.5-14PR(144/142M)[AT563]ARISUN无内 | B64: 300 | C64: 北美 | D64: =MID(A64,FIND("R",A64)+1,4) | E64: =_xlfn.XLOOKUP(A64,'7月排产计划'!G:G,'7月排产计划'!B:B) | F64: =E64&D64&"寸" | G64: 全钢 | H64: =D64&G64
A65: ID11R22.5-14PR(144/142M)[CR915]威狮无内 | B65: 500 | C65: 北美 | D65: =MID(A65,FIND("R",A65)+1,4) | E65: =_xlfn.XLOOKUP(A65,'7月排产计划'!G:G,'7月排产计划'!B:B) | F65: =E65&D65&"寸" | G65: 全钢 | H65: =D65&G65
A66: ID11R22.5-14PR(144/142M)[HT1 Plus]SUPERMAX无内 | B66: 580 | C66: 北美 | D66: =MID(A66,FIND("R",A66)+1,4) | E66: =_xlfn.XLOOKUP(A66,'7月排产计划'!G:G,'7月排产计划'!B:B) | F66: =E66&D66&"寸" | G66: 全钢 | H66: =D66&G66
A67: ID11R22.5-14PR(144/142M)[I-48T]IRONMAN无内 SMARTWAY | B67: 800 | C67: 北美 | D67: =MID(A67,FIND("R",A67)+1,4) | E67: =_xlfn.XLOOKUP(A67,'7月排产计划'!G:G,'7月排产计划'!B:B) | F67: =E67&D67&"寸" | G67: 全钢 | H67: =D67&G67
A68: ID11R22.5-14PR(144/142M)[M-TRAC TR]MASTERTRACK无内 | B68: 620 | C68: 北美 | D68: =MID(A68,FIND("R",A68)+1,4) | E68: =_xlfn.XLOOKUP(A68,'7月排产计划'!G:G,'7月排产计划'!B:B) | F68: =E68&D68&"寸" | G68: 全钢 | H68: =D68&G68
A69: ID11R22.5-14PR(144/142M)[Strong Guard H-TL]HERCULES无内 | B69: 280 | C69: 北美 | D69: =MID(A69,FIND("R",A69)+1,4) | E69: =_xlfn.XLOOKUP(A69,'7月排产计划'!G:G,'7月排产计划'!B:B) | F69: =E69&D69&"寸" | G69: 全钢 | H69: =D69&G69
A70: ID11R22.5-16PR(146/143L)[DOMINATE D01]BLACKARROW无内 | B70: 280 | C70: 北美 | D70: =MID(A70,FIND("R",A70)+1,4) | E70: =_xlfn.XLOOKUP(A70,'7月排产计划'!G:G,'7月排产计划'!B:B) | F70: =E70&D70&"寸" | G70: 全钢 | H70: =D70&G70
A71: ID11R22.5-16PR(146/143L)[HD1 PlusX]SUPERMAX ECO无内 | B71: 750 | C71: 北美 | D71: =MID(A71,FIND("R",A71)+1,4) | E71: =_xlfn.XLOOKUP(A71,'7月排产计划'!G:G,'7月排产计划'!B:B) | F71: =E71&D71&"寸" | G71: 全钢 | H71: =D71&G71
...

Sheet 7月排产计划
G1: , | I1: {=SUM((I3:I376)/2)} | L1: 350 | Q1: =SUM(Q3:Q375) | AZ1: 定额 | BE1: 计划产生
B2: 市场 | C2: 尺寸 | E2: 规格花纹 | G2: 全钢规格 | H2: 订单数 | I2: 模具 | J2: 发出模具 | K2: 优先级别 | L2: 硫化时间 | M2: 运转率 | N2: 轮胎库存 | O2: 单胎重量 | P2: 中策价 | Q2: 硫化机 条/天 | R2: 1 | S2: 2 | T2: 3 | U2: 4 | V2: 5 | W2: 6 | X2: 7 | Y2: 8 | Z2: 9 | AA2: 10 | AB2: 11 | AC2: 12 | AD2: 13 | AE2: 14 | AF2: 15 | AG2: 16 | AH2: 17 | AI2: 18 | AJ2: 19 | AK2: 20 | AL2: 21 | AM2: 22 | AN2: 23 | AO2: 24 | AP2: 25 | AQ2: 26 | AR2: 27 | AS2: 28 | AT2: 29 | AU2: 30 | AV2: 31 | AW2: 合计 | AX2: 吨位 | AY2: 产值(万元) | AZ2: 原材料 | BA2: 动力 | BB2: 工资 | BC2: 车间经费 | BE2: 原材料 | BF2: 动力 | BG2: 工资 | BH2: 车间经费 | BY2: =SUM(BY3:BY376) | BZ2: =SUM(BZ3:BZ376) | CA2: =SUM(CA3:CA376) | CB2: =SUM(CB3:CB376) | CD2: Label di Portal
B3: =_xlfn.XLOOKUP(G3,销售需求表!A:A,销售需求表!C:C) | C3: =IFERROR(MID(F3,FIND("R",F3)+1,4),"") | D3: =B3&C3&"寸" | E3: =LEFT(REPLACE(G3,1,2,""),FIND("[",REPLACE(G3,1,2,""))-1)&"-"&MID(REPLACE(G3,1,2,""),FIND("[",REPLACE(G3,1,2,""))+1,FIND("]",REPLACE(G3,1,2,""))-FIND("[",REPLACE(G3,1,2,""))-1) | F3: =IFERROR(MID(G3,3,FIND("(",G3)-3)&"-"&SUBSTITUTE(MID(G3,FIND("[",G3)+1,FIND("]",G3)-FIND("[",G3)-1),"Strong Guard ",""),"") | G3: ID11R22.5-14PR(144/142M)[AT552]ARISUN无内 | H3: 700 | J3: =IFERROR(LEFT(F3,FIND("-",F3))&MID(F3,FIND("PR",F3,FIND("-",F3))+3,LEN(F3)),F3) | K3: =_xlfn.XLOOKUP(F3,投产规格!E:E,投产规格!D:D,"未投产") | L3: =IFERROR(_xlfn.XLOOKUP(F3,硫化工艺!B:B,硫化工艺!C:C),"") | M3: =IF(L3="","",L3/(L3+$L$1/60)) | N3: =C3&"全钢" | O3: =IFERROR(_xlfn.XLOOKUP(F3,轮胎重量!J:J,轮胎重量!G:G),"") | P3: =IFERROR(_xlfn.XLOOKUP(G3,硫化工艺!I:I,硫化工艺!J:J),"") | Q3: =IFERROR(ROUND(1440/L3*(I3)*M3,0),"") | AR3: 130 | AS3: 130 | AT3: 130 | AU3: 130 | AV3: 130 | AW3: =IF(SUM(R3:AV3)=0,"",SUM(R3:AV3)) | AX3: =IFERROR(AW3*O3/1000,"") | AY3: =IFERROR(ROUND(AW3*P3/10000,3),"") | AZ3: 464.56 | BA3: 29.9 | BB3: 49.85 | BC3: 52.38 | BE3: =AZ3*AW3 | BF3: =BA3*AW3 | BG3: =BB3*AW3 | BH3: =BC3*AW3 | BJ3: {=_xlfn.LET(_xlpm.data,$R3:$AV3,_xlpm.starts,{1,8,16,23},_xlpm.lengths,{7,7,8,9},_xlpm.arr,_xlfn.MAP(_xlpm.starts,_xlpm.lengths,_xlfn.LAMBDA(_xlpm.s,_xlpm.l,SUM(INDEX(_xlpm.data,,_xlfn.SEQUENCE(,_xlpm.l,_xlpm.s))))),ROUND(_xlpm.arr*$O3/1000,2))} | BK3: 0 | BL3: 0 | BM3: 31.3 | BN3: =SUM(BJ3:BM3) | BO3: 0 | BP3: 0 | BQ3: 0 | BR3: 0 | BT3: {=_xlfn.HSTACK(SUM(INDEX($R3:$AV3,1,1):INDEX($R3:$AV3,1,7)),SUM(INDEX($R3:$AV3,1,7):INDEX($R3:$AV3,1,13)),SUM(INDEX($R3:$AV3,1,16):INDEX($R3:$AV3,1,23)),SUM(INDEX($R3:$AV3,1,23):INDEX($R3:$AV3,1,31)))} | BU3: 0 | BV3: 0 | BW3: 650 | BX3: 全钢 | BY3: =SUM(R3:X3) | BZ3: =SUM(Y3:AE3) | CA3: =SUM(AF3:AM3) | CB3: =SUM(AN3:AV3) | CD3: ADA | CE3: =ROUND(BY3*$O3/1000,2) | CF3: =ROUND(BZ3*$O3/1000,2) | CG3: =ROUND(CA3*$O3/1000,2) | CH3: =ROUND(CB3*$O3/1000,2) | CI3: =SUM(CE3:CH3) | CK3: =IFERROR(ROUND(BY3*$P3,2),"") | CL3: =IFERROR(ROUND(BZ3*$P3,2),"") | CM3: =IFERROR(ROUND(CA3*$P3,2),"") | CN3: =IFERROR(ROUND(CB3*$P3,2),"") | CO3: =SUM(CK3:CN3)
B4: =_xlfn.XLOOKUP(G4,销售需求表!A:A,销售需求表!C:C) | C4: =IFERROR(MID(F4,FIND("R",F4)+1,4),"") | D4: =B4&C4&"寸" | E4: =LEFT(REPLACE(G4,1,2,""),FIND("[",REPLACE(G4,1,2,""))-1)&"-"&MID(REPLACE(G4,1,2,""),FIND("[",REPLACE(G4,1,2,""))+1,FIND("]",REPLACE(G4,1,2,""))-FIND("[",REPLACE(G4,1,2,""))-1) | F4: =IFERROR(MID(G4,3,FIND("(",G4)-3)&"-"&SUBSTITUTE(MID(G4,FIND("[",G4)+1,FIND("]",G4)-FIND("[",G4)-1),"Strong Guard ",""),"") | G4: ID11R22.5-14PR(144/142M)[AT563]ARISUN无内 | H4: 300 | J4: =IFERROR(LEFT(F4,FIND("-",F4))&MID(F4,FIND("PR",F4,FIND("-",F4))+3,LEN(F4)),F4) | K4: =_xlfn.XLOOKUP(F4,投产规格!E:E,投产规格!D:D,"未投产") | L4: =IFERROR(_xlfn.XLOOKUP(F4,硫化工艺!B:B,硫化工艺!C:C),"") | M4: =IF(L4="","",L4/(L4+$L$1/60)) | N4: =C4&"全钢" | O4: =IFERROR(_xlfn.XLOOKUP(F4,轮胎重量!J:J,轮胎重量!G:G),"") | P4: =IFERROR(_xlfn.XLOOKUP(G4,硫化工艺!I:I,硫化工艺!J:J),"") | Q4: =IFERROR(ROUND(1440/L4*(I4)*M4,0),"") | AN4: 60 | AO4: 60 | AP4: 60 | AQ4: 60 | AR4: 60 | AS4: 60 | AT4: 60 | AU4: 60 | AV4: 60 | AW4: =IF(SUM(R4:AV4)=0,"",SUM(R4:AV4)) | AX4: =IFERROR(AW4*O4/1000,"") | AY4: =IFERROR(ROUND(AW4*P4/10000,3),"") | AZ4: 464.56 | BA4: 29.9 | BB4: 49.85 | BC4: 52.38 | BE4: =AZ4*AW4 | BF4: =BA4*AW4 | BG4: =BB4*AW4 | BH4: =BC4*AW4 | BJ4: {=_xlfn.LET(_xlpm.data,$R4:$AV4,_xlpm.starts,{1,8,16,23},_xlpm.lengths,{7,7,8,9},_xlpm.arr,_xlfn.MAP(_xlpm.starts,_xlpm.lengths,_xlfn.LAMBDA(_xlpm.s,_xlpm.l,SUM(INDEX(_xlpm.data,,_xlfn.SEQUENCE(,_xlpm.l,_xlpm.s))))),ROUND(_xlpm.arr*$O4/1000,2))} | BK4: 0 | BL4: 3.06 | BM4: 27.53 | BN4: =SUM(BJ4:BM4) | BO4: 0 | BP4: 0 | BQ4: 0 | BR4: 0 | BT4: {=_xlfn.HSTACK(SUM(INDEX($R4:$AV4,1,1):INDEX($R4:$AV4,1,7)),SUM(INDEX($R4:$AV4,1,7):INDEX($R4:$AV4,1,13)),SUM(INDEX($R4:$AV4,1,16):INDEX($R4:$AV4,1,23)),SUM(INDEX($R4:$AV4,1,23):INDEX($R4:$AV4,1,31)))} | BU4: 0 | BV4: 60 | BW4: 540 | BY4: =SUM(R4:X4) | BZ4: =SUM(Y4:AE4) | CA4: =SUM(AF4:AM4) | CB4: =SUM(AN4:AV4) | CD4: ADA | CE4: =ROUND(BY4*$O4/1000,2) | CF4: =ROUND(BZ4*$O4/1000,2) | CG4: =ROUND(CA4*$O4/1000,2) | CH4: =ROUND(CB4*$O4/1000,2) | CI4: =SUM(CE4:CH4) | CK4: =IFERROR(ROUND(BY4*$P4,2),"") | CL4: =IFERROR(ROUND(BZ4*$P4,2),"") | CM4: =IFERROR(ROUND(CA4*$P4,2),"") | CN4: =IFERROR(ROUND(CB4*$P4,2),"") | CO4: =SUM(CK4:CN4)
B5: =_xlfn.XLOOKUP(G5,销售需求表!A:A,销售需求表!C:C) | C5: =IFERROR(MID(F5,FIND("R",F5)+1,4),"") | D5: =B5&C5&"寸" | E5: =LEFT(REPLACE(G5,1,2,""),FIND("[",REPLACE(G5,1,2,""))-1)&"-"&MID(REPLACE(G5,1,2,""),FIND("[",REPLACE(G5,1,2,""))+1,FIND("]",REPLACE(G5,1,2,""))-FIND("[",REPLACE(G5,1,2,""))-1) | F5: =IFERROR(MID(G5,3,FIND("(",G5)-3)&"-"&SUBSTITUTE(MID(G5,FIND("[",G5)+1,FIND("]",G5)-FIND("[",G5)-1),"Strong Guard ",""),"") | G5: ID11R22.5-14PR(144/142M)[CR915]威狮无内 | H5: 500 | J5: =IFERROR(LEFT(F5,FIND("-",F5))&MID(F5,FIND("PR",F5,FIND("-",F5))+3,LEN(F5)),F5) | K5: =_xlfn.XLOOKUP(F5,投产规格!E:E,投产规格!D:D,"未投产") | L5: =IFERROR(_xlfn.XLOOKUP(F5,硫化工艺!B:B,硫化工艺!C:C),"") | M5: =IF(L5="","",L5/(L5+$L$1/60)) | N5: =C5&"全钢" | O5: =IFERROR(_xlfn.XLOOKUP(F5,轮胎重量!J:J,轮胎重量!G:G),"") | P5: =IFERROR(_xlfn.XLOOKUP(G5,硫化工艺!I:I,硫化工艺!J:J),"") | Q5: =IFERROR(ROUND(1440/L5*(I5)*M5,0),"") | AK5: 60 | AL5: 60 | AM5: 60 | AN5: 60 | AO5: 60 | AP5: 60 | AQ5: 60 | AR5: 60 | AS5: 60 | AT5: 60 | AU5: 60 | AV5: 60 | AW5: =IF(SUM(R5:AV5)=0,"",SUM(R5:AV5)) | AX5: =IFERROR(AW5*O5/1000,"") | AY5: =IFERROR(ROUND(AW5*P5/10000,3),"") | AZ5: 461.01 | BA5: 30.13 | BB5: 49.93 | BC5: 53.65 | BE5: =AZ5*AW5 | BF5: =BA5*AW5 | BG5: =BB5*AW5 | BH5: =BC5*AW5 | BJ5: {=_xlfn.LET(_xlpm.data,$R5:$AV5,_xlpm.starts,{1,8,16,23},_xlpm.lengths,{7,7,8,9},_xlpm.arr,_xlfn.MAP(_xlpm.starts,_xlpm.lengths,_xlfn.LAMBDA(_xlpm.s,_xlpm.l,SUM(INDEX(_xlpm.data,,_xlfn.SEQUENCE(,_xlpm.l,_xlpm.s))))),ROUND(_xlpm.arr*$O5/1000,2))} | BK5: 0 | BL5: 11.64 | BM5: 26.2 | BN5: =SUM(BJ5:BM5) | BO5: 111.71 | BP5: 91.4 | BQ5: 46.43 | BR5: 52.23 | BT5: {=_xlfn.HSTACK(SUM(INDEX($R5:$AV5,1,1):INDEX($R5:$AV5,1,7)),SUM(INDEX($R5:$AV5,1,7):INDEX($R5:$AV5,1,13)),SUM(INDEX($R5:$AV5,1,16):INDEX($R5:$AV5,1,23)),SUM(INDEX($R5:$AV5,1,23):INDEX($R5:$AV5,1,31)))} | BU5: 0 | BV5: 240 | BW5: 540 | BY5: =SUM(R5:X5) | BZ5: =SUM(Y5:AE5) | CA5: =SUM(AF5:AM5) | CB5: =SUM(AN5:AV5) | CD5: ADA | CE5: =ROUND(BY5*$O5/1000,2) | CF5: =ROUND(BZ5*$O5/1000,2) | CG5: =ROUND(CA5*$O5/1000,2) | CH5: =ROUND(CB5*$O5/1000,2) | CI5: =SUM(CE5:CH5) | CK5: =IFERROR(ROUND(BY5*$P5,2),"") | CL5: =IFERROR(ROUND(BZ5*$P5,2),"") | CM5: =IFERROR(ROUND(CA5*$P5,2),"") | CN5: =IFERROR(ROUND(CB5*$P5,2),"") | CO5: =SUM(CK5:CN5)
B6: =_xlfn.XLOOKUP(G6,销售需求表!A:A,销售需求表!C:C) | C6: =IFERROR(MID(F6,FIND("R",F6)+1,4),"") | D6: =B6&C6&"寸" | E6: =LEFT(REPLACE(G6,1,2,""),FIND("[",REPLACE(G6,1,2,""))-1)&"-"&MID(REPLACE(G6,1,2,""),FIND("[",REPLACE(G6,1,2,""))+1,FIND("]",REPLACE(G6,1,2,""))-FIND("[",REPLACE(G6,1,2,""))-1) | F6: =IFERROR(MID(G6,3,FIND("(",G6)-3)&"-"&SUBSTITUTE(MID(G6,FIND("[",G6)+1,FIND("]",G6)-FIND("[",G6)-1),"Strong Guard ",""),"") | G6: ID11R22.5-14PR(144/142M)[HT1 Plus]SUPERMAX无内 | H6: 580 | I6: 2 | J6: =IFERROR(LEFT(F6,FIND("-",F6))&MID(F6,FIND("PR",F6,FIND("-",F6))+3,LEN(F6)),F6) | K6: =_xlfn.XLOOKUP(F6,投产规格!E:E,投产规格!D:D,"未投产") | L6: =IFERROR(_xlfn.XLOOKUP(F6,硫化工艺!B:B,硫化工艺!C:C),"") | M6: =IF(L6="","",L6/(L6+$L$1/60)) | N6: =C6&"全钢" | O6: =IFERROR(_xlfn.XLOOKUP(F6,轮胎重量!J:J,轮胎重量!G:G),"") | P6: =O6*13.9 | Q6: =IFERROR(ROUND(1440/L6*(I6)*M6,0),"") | R6: 66 | S6: 66 | T6: 66 | U6: 66 | V6: 66 | AW6: =IF(SUM(R6:AV6)=0,"",SUM(R6:AV6)) | AX6: =IFERROR(AW6*O6/1000,"") | AY6: =IFERROR(ROUND(AW6*P6/10000,3),"") | BE6: =AZ6*AW6 | BF6: =BA6*AW6 | BG6: =BB6*AW6 | BH6: =BC6*AW6 | BJ6: {=_xlfn.LET(_xlpm.data,$R6:$AV6,_xlpm.starts,{1,8,16,23},_xlpm.lengths,{7,7,8,9},_xlpm.arr,_xlfn.MAP(_xlpm.starts,_xlpm.lengths,_xlfn.LAMBDA(_xlpm.s,_xlpm.l,SUM(INDEX(_xlpm.data,,_xlfn.SEQUENCE(,_xlpm.l,_xlpm.s))))),ROUND(_xlpm.arr*$O6/1000,2))} | BK6: 0 | BL6: 0 | BM6: 0 | BN6: =SUM(BJ6:BM6) | BO6: 15.39 | BP6: 0 | BQ6: 0 | BR6: 0 | BT6: {=_xlfn.HSTACK(SUM(INDEX($R6:$AV6,1,1):INDEX($R6:$AV6,1,7)),SUM(INDEX($R6:$AV6,1,7):INDEX($R6:$AV6,1,13)),SUM(INDEX($R6:$AV6,1,16):INDEX($R6:$AV6,1,23)),SUM(INDEX($R6:$AV6,1,23):INDEX($R6:$AV6,1,31)))} | BU6: 0 | BV6: 0 | BW6: 0 | BY6: =SUM(R6:X6) | BZ6: =SUM(Y6:AE6) | CA6: =SUM(AF6:AM6) | CB6: =SUM(AN6:AV6) | CD6: ADA | CE6: =ROUND(BY6*$O6/1000,2) | CF6: =ROUND(BZ6*$O6/1000,2) | CG6: =ROUND(CA6*$O6/1000,2) | CH6: =ROUND(CB6*$O6/1000,2) | CI6: =SUM(CE6:CH6) | CK6: =IFERROR(ROUND(BY6*$P6,2),"") | CL6: =IFERROR(ROUND(BZ6*$P6,2),"") | CM6: =IFERROR(ROUND(CA6*$P6,2),"") | CN6: =IFERROR(ROUND(CB6*$P6,2),"") | CO6: =SUM(CK6:CN6)
B7: =_xlfn.XLOOKUP(G7,销售需求表!A:A,销售需求表!C:C) | C7: =IFERROR(MID(F7,FIND("R",F7)+1,4),"") | D7: =B7&C7&"寸" | E7: =LEFT(REPLACE(G7,1,2,""),FIND("[",REPLACE(G7,1,2,""))-1)&"-"&MID(REPLACE(G7,1,2,""),FIND("[",REPLACE(G7,1,2,""))+1,FIND("]",REPLACE(G7,1,2,""))-FIND("[",REPLACE(G7,1,2,""))-1) | F7: =IFERROR(MID(G7,3,FIND("(",G7)-3)&"-"&SUBSTITUTE(MID(G7,FIND("[",G7)+1,FIND("]",G7)-FIND("[",G7)-1),"Strong Guard ",""),"") | G7: ID11R22.5-14PR(144/142M)[I-48T]IRONMAN无内 SMARTWAY | H7: 800 | J7: =IFERROR(LEFT(F7,FIND("-",F7))&MID(F7,FIND("PR",F7,FIND("-",F7))+3,LEN(F7)),F7) | K7: =_xlfn.XLOOKUP(F7,投产规格!E:E,投产规格!D:D,"未投产") | L7: =IFERROR(_xlfn.XLOOKUP(F7,硫化工艺!B:B,硫化工艺!C:C),"") | M7: =IF(L7="","",L7/(L7+$L$1/60)) | N7: =C7&"全钢" | O7: =IFERROR(_xlfn.XLOOKUP(F7,轮胎重量!J:J,轮胎重量!G:G),"") | P7: =IFERROR(_xlfn.XLOOKUP(G7,硫化工艺!I:I,硫化工艺!J:J),"") | Q7: =IFERROR(ROUND(1440/L7*(I7)*M7,0),"") | AI7: 60 | AJ7: 60 | AK7: 60 | AL7: 60 | AM7: 60 | AN7: 60 | AO7: 60 | AP7: 60 | AQ7: 60 | AR7: 60 | AS7: 60 | AT7: 60 | AU7: 60 | AV7: 60 | AW7: =IF(SUM(R7:AV7)=0,"",SUM(R7:AV7)) | AX7: =IFERROR(AW7*O7/1000,"") | AY7: =IFERROR(ROUND(AW7*P7/10000,3),"") | BE7: =AZ7*AW7 | BF7: =BA7*AW7 | BG7: =BB7*AW7 | BH7: =BC7*AW7 | BJ7: {=_xlfn.LET(_xlpm.data,$R7:$AV7,_xlpm.starts,{1,8,16,23},_xlpm.lengths,{7,7,8,9},_xlpm.arr,_xlfn.MAP(_xlpm.starts,_xlpm.lengths,_xlfn.LAMBDA(_xlpm.s,_xlpm.l,SUM(INDEX(_xlpm.data,,_xlfn.SEQUENCE(,_xlpm.l,_xlpm.s))))),ROUND(_xlpm.arr*$O7/1000,2))} | BK7: 0 | BL7: 17.46 | BM7: 26.2 | BN7: =SUM(BJ7:BM7) | BO7: 22.16 | BP7: 22.16 | BQ7: 25.32 | BR7: 28.49 | BT7: {=_xlfn.HSTACK(SUM(INDEX($R7:$AV7,1,1):INDEX($R7:$AV7,1,7)),SUM(INDEX($R7:$AV7,1,7):INDEX($R7:$AV7,1,13)),SUM(INDEX($R7:$AV7,1,16):INDEX($R7:$AV7,1,23)),SUM(INDEX($R7:$AV7,1,23):INDEX($R7:$AV7,1,31)))} | BU7: 0 | BV7: 360 | BW7: 540 | BY7: =SUM(R7:X7) | BZ7: =SUM(Y7:AE7) | CA7: =SUM(AF7:AM7) | CB7: =SUM(AN7:AV7) | CD7: ADA | CE7: =ROUND(BY7*$O7/1000,2) | CF7: =ROUND(BZ7*$O7/1000,2) | CG7: =ROUND(CA7*$O7/1000,2) | CH7: =ROUND(CB7*$O7/1000,2) | CI7: =SUM(CE7:CH7) | CK7: =IFERROR(ROUND(BY7*$P7,2),"") | CL7: =IFERROR(ROUND(BZ7*$P7,2),"") | CM7: =IFERROR(ROUND(CA7*$P7,2),"") | CN7: =IFERROR(ROUND(CB7*$P7,2),"") | CO7: =SUM(CK7:CN7)
B8: =_xlfn.XLOOKUP(G8,销售需求表!A:A,销售需求表!C:C) | C8: =IFERROR(MID(F8,FIND("R",F8)+1,4),"") | D8: =B8&C8&"寸" | E8: =LEFT(REPLACE(G8,1,2,""),FIND("[",REPLACE(G8,1,2,""))-1)&"-"&MID(REPLACE(G8,1,2,""),FIND("[",REPLACE(G8,1,2,""))+1,FIND("]",REPLACE(G8,1,2,""))-FIND("[",REPLACE(G8,1,2,""))-1) | F8: =IFERROR(MID(G8,3,FIND("(",G8)-3)&"-"&SUBSTITUTE(MID(G8,FIND("[",G8)+1,FIND("]",G8)-FIND("[",G8)-1),"Strong Guard ",""),"") | G8: ID11R22.5-14PR(144/142M)[M-TRAC TR]MASTERTRACK无内 | H8: 620 | J8: =IFERROR(LEFT(F8,FIND("-",F8))&MID(F8,FIND("PR",F8,FIND("-",F8))+3,LEN(F8)),F8) | K8: =_xlfn.XLOOKUP(F8,投产规格!E:E,投产规格!D:D,"未投产") | L8: =IFERROR(_xlfn.XLOOKUP(F8,硫化工艺!B:B,硫化工艺!C:C),"") | M8: =IF(L8="","",L8/(L8+$L$1/60)) | N8: =C8&"全钢" | O8: =IFERROR(_xlfn.XLOOKUP(F8,轮胎重量!J:J,轮胎重量!G:G),"") | P8: =O8*13.9 | Q8: =IFERROR(ROUND(1440/L8*(I8)*M8,0),"") | AI8: 60 | AJ8: 60 | AK8: 60 | AL8: 60 | AM8: 60 | AN8: 60 | AO8: 60 | AP8: 60 | AQ8: 60 | AR8: 60 | AW8: =IF(SUM(R8:AV8)=0,"",SUM(R8:AV8)) | AX8: =IFERROR(AW8*O8/1000,"") | AY8: =IFERROR(ROUND(AW8*P8/10000,3),"") | BE8: =AZ8*AW8 | BF8: =BA8*AW8 | BG8: =BB8*AW8 | BH8: =BC8*AW8 | BJ8: {=_xlfn.LET(_xlpm.data,$R8:$AV8,_xlpm.starts,{1,8,16,23},_xlpm.lengths,{7,7,8,9},_xlpm.arr,_xlfn.MAP(_xlpm.starts,_xlpm.lengths,_xlfn.LAMBDA(_xlpm.s,_xlpm.l,SUM(INDEX(_xlpm.data,,_xlfn.SEQUENCE(,_xlpm.l,_xlpm.s))))),ROUND(_xlpm.arr*$O8/1000,2))} | BK8: 0 | BL8: 21.45 | BM8: 17.87 | BN8: =SUM(BJ8:BM8) | BO8: 0 | BP8: 0 | BQ8: 0 | BR8: 0 | BT8: {=_xlfn.HSTACK(SUM(INDEX($R8:$AV8,1,1):INDEX($R8:$AV8,1,7)),SUM(INDEX($R8:$AV8,1,7):INDEX($R8:$AV8,1,13)),SUM(INDEX($R8:$AV8,1,16):INDEX($R8:$AV8,1,23)),SUM(INDEX($R8:$AV8,1,23):INDEX($R8:$AV8,1,31)))} | BU8: 0 | BV8: 360 | BW8: 300 | BY8: =SUM(R8:X8) | BZ8: =SUM(Y8:AE8) | CA8: =SUM(AF8:AM8) | CB8: =SUM(AN8:AV8) | CD8: ADA | CE8: =ROUND(BY8*$O8/1000,2) | CF8: =ROUND(BZ8*$O8/1000,2) | CG8: =ROUND(CA8*$O8/1000,2) | CH8: =ROUND(CB8*$O8/1000,2) | CI8: =SUM(CE8:CH8) | CK8: =IFERROR(ROUND(BY8*$P8,2),"") | CL8: =IFERROR(ROUND(BZ8*$P8,2),"") | CM8: =IFERROR(ROUND(CA8*$P8,2),"") | CN8: =IFERROR(ROUND(CB8*$P8,2),"") | CO8: =SUM(CK8:CN8)
B9: =_xlfn.XLOOKUP(G9,销售需求表!A:A,销售需求表!C:C) | C9: =IFERROR(MID(F9,FIND("R",F9)+1,4),"") | D9: =B9&C9&"寸" | E9: =LEFT(REPLACE(G9,1,2,""),FIND("[",REPLACE(G9,1,2,""))-1)&"-"&MID(REPLACE(G9,1,2,""),FIND("[",REPLACE(G9,1,2,""))+1,FIND("]",REPLACE(G9,1,2,""))-FIND("[",REPLACE(G9,1,2,""))-1) | F9: =IFERROR(MID(G9,3,FIND("(",G9)-3)&"-"&SUBSTITUTE(MID(G9,FIND("[",G9)+1,FIND("]",G9)-FIND("[",G9)-1),"Strong Guard ",""),"") | G9: ID11R22.5-14PR(144/142M)[Strong Guard H-TL]HERCULES无内 | H9: 280 | J9: =IFERROR(LEFT(F9,FIND("-",F9))&MID(F9,FIND("PR",F9,FIND("-",F9))+3,LEN(F9)),F9) | K9: =_xlfn.XLOOKUP(F9,投产规格!E:E,投产规格!D:D,"未投产") | L9: =IFERROR(_xlfn.XLOOKUP(F9,硫化工艺!B:B,硫化工艺!C:C),"") | M9: =IF(L9="","",L9/(L9+$L$1/60)) | N9: =C9&"全钢" | O9: =IFERROR(_xlfn.XLOOKUP(F9,轮胎重量!J:J,轮胎重量!G:G),"") | P9: =IFERROR(_xlfn.XLOOKUP(G9,硫化工艺!I:I,硫化工艺!J:J),"") | Q9: =IFERROR(ROUND(1440/L9*(I9)*M9,0),"") | AN9: 60 | AO9: 60 | AP9: 60 | AQ9: 60 | AR9: 60 | AS9: 60 | AT9: 60 | AU9: 60 | AV9: 60 | AW9: =IF(SUM(R9:AV9)=0,"",SUM(R9:AV9)) | AX9: =IFERROR(AW9*O9/1000,"") | AY9: =IFERROR(ROUND(AW9*P9/10000,3),"") | BE9: =AZ9*AW9 | BF9: =BA9*AW9 | BG9: =BB9*AW9 | BH9: =BC9*AW9 | BJ9: {=_xlfn.LET(_xlpm.data,$R9:$AV9,_xlpm.starts,{1,8,16,23},_xlpm.lengths,{7,7,8,9},_xlpm.arr,_xlfn.MAP(_xlpm.starts,_xlpm.lengths,_xlfn.LAMBDA(_xlpm.s,_xlpm.l,SUM(INDEX(_xlpm.data,,_xlfn.SEQUENCE(,_xlpm.l,_xlpm.s))))),ROUND(_xlpm.arr*$O9/1000,2))} | BK9: 0 | BL9: 2.94 | BM9: 26.5 | BN9: =SUM(BJ9:BM9) | BO9: 0 | BP9: 0 | BQ9: 0 | BR9: 0 | BT9: {=_xlfn.HSTACK(SUM(INDEX($R9:$AV9,1,1):INDEX($R9:$AV9,1,7)),SUM(INDEX($R9:$AV9,1,7):INDEX($R9:$AV9,1,13)),SUM(INDEX($R9:$AV9,1,16):INDEX($R9:$AV9,1,23)),SUM(INDEX($R9:$AV9,1,23):INDEX($R9:$AV9,1,31)))} | BU9: 0 | BV9: 60 | BW9: 540 | BY9: =SUM(R9:X9) | BZ9: =SUM(Y9:AE9) | CA9: =SUM(AF9:AM9) | CB9: =SUM(AN9:AV9) | CD9: ADA | CE9: =ROUND(BY9*$O9/1000,2) | CF9: =ROUND(BZ9*$O9/1000,2) | CG9: =ROUND(CA9*$O9/1000,2) | CH9: =ROUND(CB9*$O9/1000,2) | CI9: =SUM(CE9:CH9) | CK9: =IFERROR(ROUND(BY9*$P9,2),"") | CL9: =IFERROR(ROUND(BZ9*$P9,2),"") | CM9: =IFERROR(ROUND(CA9*$P9,2),"") | CN9: =IFERROR(ROUND(CB9*$P9,2),"") | CO9: =SUM(CK9:CN9)
B10: =_xlfn.XLOOKUP(G10,销售需求表!A:A,销售需求表!C:C) | C10: =IFERROR(MID(F10,FIND("R",F10)+1,4),"") | D10: =B10&C10&"寸" | E10: =LEFT(REPLACE(G10,1,2,""),FIND("[",REPLACE(G10,1,2,""))-1)&"-"&MID(REPLACE(G10,1,2,""),FIND("[",REPLACE(G10,1,2,""))+1,FIND("]",REPLACE(G10,1,2,""))-FIND("[",REPLACE(G10,1,2,""))-1) | F10: =IFERROR(MID(G10,3,FIND("(",G10)-3)&"-"&SUBSTITUTE(MID(G10,FIND("[",G10)+1,FIND("]",G10)-FIND("[",G10)-1),"Strong Guard ",""),"") | G10: ID11R22.5-16PR(146/143L)[DOMINATE D01]BLACKARROW无内 | H10: 280 | J10: =IFERROR(LEFT(F10,FIND("-",F10))&MID(F10,FIND("PR",F10,FIND("-",F10))+3,LEN(F10)),F10) | K10: =_xlfn.XLOOKUP(F10,投产规格!E:E,投产规格!D:D,"未投产") | L10: =IFERROR(_xlfn.XLOOKUP(F10,硫化工艺!B:B,硫化工艺!C:C),"") | M10: =IF(L10="","",L10/(L10+$L$1/60)) | N10: =C10&"全钢" | O10: =IFERROR(_xlfn.XLOOKUP(F10,轮胎重量!J:J,轮胎重量!G:G),"") | P10: =IFERROR(_xlfn.XLOOKUP(G10,硫化工艺!I:I,硫化工艺!J:J),"") | Q10: =IFERROR(ROUND(1440/L10*(I10)*M10,0),"") | AW10: =IF(SUM(R10:AV10)=0,"",SUM(R10:AV10)) | AX10: =IFERROR(AW10*O10/1000,"") | AY10: =IFERROR(ROUND(AW10*P10/10000,3),"") | BE10: =AZ10*AW10 | BF10: =BA10*AW10 | BG10: =BB10*AW10 | BH10: =BC10*AW10 | BJ10: {=_xlfn.LET(_xlpm.data,$R10:$AV10,_xlpm.starts,{1,8,16,23},_xlpm.lengths,{7,7,8,9},_xlpm.arr,_xlfn.MAP(_xlpm.starts,_xlpm.lengths,_xlfn.LAMBDA(_xlpm.s,_xlpm.l,SUM(INDEX(_xlpm.data,,_xlfn.SEQUENCE(,_xlpm.l,_xlpm.s))))),ROUND(_xlpm.arr*$O10/1000,2))} | BK10: 0 | BL10: 0 | BM10: 0 | BN10: =SUM(BJ10:BM10) | BO10: 0 | BP10: 0 | BQ10: 0 | BR10: 0 | BT10: {=_xlfn.HSTACK(SUM(INDEX($R10:$AV10,1,1):INDEX($R10:$AV10,1,7)),SUM(INDEX($R10:$AV10,1,7):INDEX($R10:$AV10,1,13)),SUM(INDEX($R10:$AV10,1,16):INDEX($R10:$AV10,1,23)),SUM(INDEX($R10:$AV10,1,23):INDEX($R10:$AV10,1,31)))} | BU10: 0 | BV10: 0 | BW10: 0 | BY10: =SUM(R10:X10) | BZ10: =SUM(Y10:AE10) | CA10: =SUM(AF10:AM10) | CB10: =SUM(AN10:AV10) | CD10: ADA | CE10: =ROUND(BY10*$O10/1000,2) | CF10: =ROUND(BZ10*$O10/1000,2) | CG10: =ROUND(CA10*$O10/1000,2) | CH10: =ROUND(CB10*$O10/1000,2) | CI10: =SUM(CE10:CH10) | CK10: =IFERROR(ROUND(BY10*$P10,2),"") | CL10: =IFERROR(ROUND(BZ10*$P10,2),"") | CM10: =IFERROR(ROUND(CA10*$P10,2),"") | CN10: =IFERROR(ROUND(CB10*$P10,2),"") | CO10: =SUM(CK10:CN10)
B11: =_xlfn.XLOOKUP(G11,销售需求表!A:A,销售需求表!C:C) | C11: =IFERROR(MID(F11,FIND("R",F11)+1,4),"") | D11: =B11&C11&"寸" | E11: =LEFT(REPLACE(G11,1,2,""),FIND("[",REPLACE(G11,1,2,""))-1)&"-"&MID(REPLACE(G11,1,2,""),FIND("[",REPLACE(G11,1,2,""))+1,FIND("]",REPLACE(G11,1,2,""))-FIND("[",REPLACE(G11,1,2,""))-1) | F11: =IFERROR(MID(G11,3,FIND("(",G11)-3)&"-"&SUBSTITUTE(MID(G11,FIND("[",G11)+1,FIND("]",G11)-FIND("[",G11)-1),"Strong Guard ",""),"") | G11: ID11R22.5-16PR(146/143L)[HD1 PlusX]SUPERMAX ECO无内 | H11: 750 | J11: =IFERROR(LEFT(F11,FIND("-",F11))&MID(F11,FIND("PR",F11,FIND("-",F11))+3,LEN(F11)),F11) | K11: =_xlfn.XLOOKUP(F11,投产规格!E:E,投产规格!D:D,"未投产") | L11: =IFERROR(_xlfn.XLOOKUP(F11,硫化工艺!B:B,硫化工艺!C:C),"") | M11: =IF(L11="","",L11/(L11+$L$1/60)) | N11: =C11&"全钢" | O11: =IFERROR(_xlfn.XLOOKUP(F11,轮胎重量!J:J,轮胎重量!G:G),"") | P11: =IFERROR(_xlfn.XLOOKUP(G11,硫化工艺!I:I,硫化工艺!J:J),"") | Q11: =IFERROR(ROUND(1440/L11*(I11)*M11,0),"") | AW11: =IF(SUM(R11:AV11)=0,"",SUM(R11:AV11)) | AX11: =IFERROR(AW11*O11/1000,"") | AY11: =IFERROR(ROUND(AW11*P11/10000,3),"") | BE11: =AZ11*AW11 | BF11: =BA11*AW11 | BG11: =BB11*AW11 | BH11: =BC11*AW11 | BJ11: {=_xlfn.LET(_xlpm.data,$R11:$AV11,_xlpm.starts,{1,8,16,23},_xlpm.lengths,{7,7,8,9},_xlpm.arr,_xlfn.MAP(_xlpm.starts,_xlpm.lengths,_xlfn.LAMBDA(_xlpm.s,_xlpm.l,SUM(INDEX(_xlpm.data,,_xlfn.SEQUENCE(,_xlpm.l,_xlpm.s))))),ROUND(_xlpm.arr*$O11/1000,2))} | BK11: 0 | BL11: 0 | BM11: 0 | BN11: =SUM(BJ11:BM11) | BO11: 0 | BP11: 0 | BQ11: 0 | BR11: 0 | BT11: {=_xlfn.HSTACK(SUM(INDEX($R11:$AV11,1,1):INDEX($R11:$AV11,1,7)),SUM(INDEX($R11:$AV11,1,7):INDEX($R11:$AV11,1,13)),SUM(INDEX($R11:$AV11,1,16):INDEX($R11:$AV11,1,23)),SUM(INDEX($R11:$AV11,1,23):INDEX($R11:$AV11,1,31)))} | BU11: 0 | BV11: 0 | BW11: 0 | BY11: =SUM(R11:X11) | BZ11: =SUM(Y11:AE11) | CA11: =SUM(AF11:AM11) | CB11: =SUM(AN11:AV11) | CD11: ADA | CE11: =ROUND(BY11*$O11/1000,2) | CF11: =ROUND(BZ11*$O11/1000,2) | CG11: =ROUND(CA11*$O11/1000,2) | CH11: =ROUND(CB11*$O11/1000,2) | CI11: =SUM(CE11:CH11) | CK11: =IFERROR(ROUND(BY11*$P11,2),"") | CL11: =IFERROR(ROUND(BZ11*$P11,2),"") | CM11: =IFERROR(ROUND(CA11*$P11,2),"") | CN11: =IFERROR(ROUND(CB11*$P11,2),"") | CO11: =SUM(CK11:CN11)
B12: =_xlfn.XLOOKUP(G12,销售需求表!A:A,销售需求表!C:C) | C12: =IFERROR(MID(F12,FIND("R",F12)+1,4),"") | D12: =B12&C12&"寸" | E12: =LEFT(REPLACE(G12,1,2,""),FIND("[",REPLACE(G12,1,2,""))-1)&"-"&MID(REPLACE(G12,1,2,""),FIND("[",REPLACE(G12,1,2,""))+1,FIND("]",REPLACE(G12,1,2,""))-FIND("[",REPLACE(G12,1,2,""))-1) | F12: =IFERROR(MID(G12,3,FIND("(",G12)-3)&"-"&SUBSTITUTE(MID(G12,FIND("[",G12)+1,FIND("]",G12)-FIND("[",G12)-1),"Strong Guard ",""),"") | G12: ID11R22.5-16PR(146/143L)[KOBE DPM]ITARO无内 | H12: 1700 | I12: 2 | J12: =IFERROR(LEFT(F12,FIND("-",F12))&MID(F12,FIND("PR",F12,FIND("-",F12))+3,LEN(F12)),F12) | K12: =_xlfn.XLOOKUP(F12,投产规格!E:E,投产规格!D:D,"未投产") | L12: =IFERROR(_xlfn.XLOOKUP(F12,硫化工艺!B:B,硫化工艺!C:C),"") | M12: =IF(L12="","",L12/(L12+$L$1/60)) | N12: =C12&"全钢" | O12: =IFERROR(_xlfn.XLOOKUP(F12,轮胎重量!J:J,轮胎重量!G:G),"") | P12: =IFERROR(_xlfn.XLOOKUP(G12,硫化工艺!I:I,硫化工艺!J:J),"") | Q12: =IFERROR(ROUND(1440/L12*(I12)*M12,0),"") | R12: 60 | S12: 60 | T12: 60 | U12: 60 | V12: 60 | W12: 120 | X12: 120 | Y12: 120 | Z12: 120 | AA12: 120 | AB12: 120 | AC12: 120 | AD12: 120 | AE12: 120 | AF12: 120 | AG12: 120 | AH12: 120 | AW12: =IF(SUM(R12:AV12)=0,"",SUM(R12:AV12)) | AX12: =IFERROR(AW12*O12/1000,"") | AY12: =IFERROR(ROUND(AW12*P12/10000,3),"") | BE12: =AZ12*AW12 | BF12: =BA12*AW12 | BG12: =BB12*AW12 | BH12: =BC12*AW12 | BJ12: {=_xlfn.LET(_xlpm.data,$R12:$AV12,_xlpm.starts,{1,8,16,23},_xlpm.lengths,{7,7,8,9},_xlpm.arr,_xlfn.MAP(_xlpm.starts,_xlpm.lengths,_xlfn.LAMBDA(_xlpm.s,_xlpm.l,SUM(INDEX(_xlpm.data,,_xlfn.SEQUENCE(,_xlpm.l,_xlpm.s))))),ROUND(_xlpm.arr*$O12/1000,2))} | BK12: 45.81 | BL12: 13.09 | BM12: 0 | BN12: =SUM(BJ12:BM12) | BO12: 0 | BP12: 0 | BQ12: 0 | BR12: 0 | BT12: {=_xlfn.HSTACK(SUM(INDEX($R12:$AV12,1,1):INDEX($R12:$AV12,1,7)),SUM(INDEX($R12:$AV12,1,7):INDEX($R12:$AV12,1,13)),SUM(INDEX($R12:$AV12,1,16):INDEX($R12:$AV12,1,23)),SUM(INDEX($R12:$AV12,1,23):INDEX($R12:$AV12,1,31)))} | BU12: 840 | BV12: 240 | BW12: 0 | BY12: =SUM(R12:X12) | BZ12: =SUM(Y12:AE12) | CA12: =SUM(AF12:AM12) | CB12: =SUM(AN12:AV12) | CD12: ADA | CE12: =ROUND(BY12*$O12/1000,2) | CF12: =ROUND(BZ12*$O12/1000,2) | CG12: =ROUND(CA12*$O12/1000,2) | CH12: =ROUND(CB12*$O12/1000,2) | CI12: =SUM(CE12:CH12) | CK12: =IFERROR(ROUND(BY12*$P12,2),"") | CL12: =IFERROR(ROUND(BZ12*$P12,2),"") | CM12: =IFERROR(ROUND(CA12*$P12,2),"") | CN12: =IFERROR(ROUND(CB12*$P12,2),"") | CO12: =SUM(CK12:CN12)
B13: =_xlfn.XLOOKUP(G13,销售需求表!A:A,销售需求表!C:C) | C13: =IFERROR(MID(F13,FIND("R",F13)+1,4),"") | D13: =B13&C13&"寸" | E13: =LEFT(REPLACE(G13,1,2,""),FIND("[",REPLACE(G13,1,2,""))-1)&"-"&MID(REPLACE(G13,1,2,""),FIND("[",REPLACE(G13,1,2,""))+1,FIND("]",REPLACE(G13,1,2,""))-FIND("[",REPLACE(G13,1,2,""))-1) | F13: =IFERROR(MID(G13,3,FIND("(",G13)-3)&"-"&SUBSTITUTE(MID(G13,FIND("[",G13)+1,FIND("]",G13)-FIND("[",G13)-1),"Strong Guard ",""),"") | G13: ID11R22.5-16PR(146/143L)[M-TRAC CSD+]MASTERTRACK无内 | H13: 280 | J13: =IFERROR(LEFT(F13,FIND("-",F13))&MID(F13,FIND("PR",F13,FIND("-",F13))+3,LEN(F13)),F13) | K13: =_xlfn.XLOOKUP(F13,投产规格!E:E,投产规格!D:D,"未投产") | L13: =IFERROR(_xlfn.XLOOKUP(F13,硫化工艺!B:B,硫化工艺!C:C),"") | M13: =IF(L13="","",L13/(L13+$L$1/60)) | N13: =C13&"全钢" | O13: =IFERROR(_xlfn.XLOOKUP(F13,轮胎重量!J:J,轮胎重量!G:G),"") | P13: =O13*13.9 | Q13: =IFERROR(ROUND(1440/L13*(I13)*M13,0),"") | AW13: =IF(SUM(R13:AV13)=0,"",SUM(R13:AV13)) | AX13: =IFERROR(AW13*O13/1000,"") | AY13: =IFERROR(ROUND(AW13*P13/10000,3),"") | BE13: =AZ13*AW13 | BF13: =BA13*AW13 | BG13: =BB13*AW13 | BH13: =BC13*AW13 | BJ13: {=_xlfn.LET(_xlpm.data,$R13:$AV13,_xlpm.starts,{1,8,16,23},_xlpm.lengths,{7,7,8,9},_xlpm.arr,_xlfn.MAP(_xlpm.starts,_xlpm.lengths,_xlfn.LAMBDA(_xlpm.s,_xlpm.l,SUM(INDEX(_xlpm.data,,_xlfn.SEQUENCE(,_xlpm.l,_xlpm.s))))),ROUND(_xlpm.arr*$O13/1000,2))} | BK13: 0 | BL13: 0 | BM13: 0 | BN13: =SUM(BJ13:BM13) | BO13: 0 | BP13: 0 | BQ13: 0 | BR13: 0 | BT13: {=_xlfn.HSTACK(SUM(INDEX($R13:$AV13,1,1):INDEX($R13:$AV13,1,7)),SUM(INDEX($R13:$AV13,1,7):INDEX($R13:$AV13,1,13)),SUM(INDEX($R13:$AV13,1,16):INDEX($R13:$AV13,1,23)),SUM(INDEX($R13:$AV13,1,23):INDEX($R13:$AV13,1,31)))} | BU13: 0 | BV13: 0 | BW13: 0 | BY13: =SUM(R13:X13) | BZ13: =SUM(Y13:AE13) | CA13: =SUM(AF13:AM13) | CB13: =SUM(AN13:AV13) | CD13: TIDAK ADA | CE13: =ROUND(BY13*$O13/1000,2) | CF13: =ROUND(BZ13*$O13/1000,2) | CG13: =ROUND(CA13*$O13/1000,2) | CH13: =ROUND(CB13*$O13/1000,2) | CI13: =SUM(CE13:CH13) | CK13: =IFERROR(ROUND(BY13*$P13,2),"") | CL13: =IFERROR(ROUND(BZ13*$P13,2),"") | CM13: =IFERROR(ROUND(CA13*$P13,2),"") | CN13: =IFERROR(ROUND(CB13*$P13,2),"") | CO13: =SUM(CK13:CN13)
B14: =_xlfn.XLOOKUP(G14,销售需求表!A:A,销售需求表!C:C) | C14: =IFERROR(MID(F14,FIND("R",F14)+1,4),"") | D14: =B14&C14&"寸" | E14: =LEFT(REPLACE(G14,1,2,""),FIND("[",REPLACE(G14,1,2,""))-1)&"-"&MID(REPLACE(G14,1,2,""),FIND("[",REPLACE(G14,1,2,""))+1,FIND("]",REPLACE(G14,1,2,""))-FIND("[",REPLACE(G14,1,2,""))-1) | F14: =IFERROR(MID(G14,3,FIND("(",G14)-3)&"-"&SUBSTITUTE(MID(G14,FIND("[",G14)+1,FIND("]",G14)-FIND("[",G14)-1),"Strong Guard ",""),"") | G14: ID11R22.5-16PR(146/143L)[M-TRAC HS+]MASTERTRACK无内 | H14: 280 | J14: =IFERROR(LEFT(F14,FIND("-",F14))&MID(F14,FIND("PR",F14,FIND("-",F14))+3,LEN(F14)),F14) | K14: =_xlfn.XLOOKUP(F14,投产规格!E:E,投产规格!D:D,"未投产") | L14: =IFERROR(_xlfn.XLOOKUP(F14,硫化工艺!B:B,硫化工艺!C:C),"") | M14: =IF(L14="","",L14/(L14+$L$1/60)) | N14: =C14&"全钢" | O14: =IFERROR(_xlfn.XLOOKUP(F14,轮胎重量!J:J,轮胎重量!G:G),"") | P14: =O14*13.9 | Q14: =IFERROR(ROUND(1440/L14*(I14)*M14,0),"") | AW14: =IF(SUM(R14:AV14)=0,"",SUM(R14:AV14)) | AX14: =IFERROR(AW14*O14/1000,"") | AY14: =IFERROR(ROUND(AW14*P14/10000,3),"") | BE14: =AZ14*AW14 | BF14: =BA14*AW14 | BG14: =BB14*AW14 | BH14: =BC14*AW14 | BJ14: {=_xlfn.LET(_xlpm.data,$R14:$AV14,_xlpm.starts,{1,8,16,23},_xlpm.lengths,{7,7,8,9},_xlpm.arr,_xlfn.MAP(_xlpm.starts,_xlpm.lengths,_xlfn.LAMBDA(_xlpm.s,_xlpm.l,SUM(INDEX(_xlpm.data,,_xlfn.SEQUENCE(,_xlpm.l,_xlpm.s))))),ROUND(_xlpm.arr*$O14/1000,2))} | BK14: 0 | BL14: 0 | BM14: 0 | BN14: =SUM(BJ14:BM14) | BO14: 0 | BP14: 0 | BQ14: 0 | BR14: 0 | BT14: {=_xlfn.HSTACK(SUM(INDEX($R14:$AV14,1,1):INDEX($R14:$AV14,1,7)),SUM(INDEX($R14:$AV14,1,7):INDEX($R14:$AV14,1,13)),SUM(INDEX($R14:$AV14,1,16):INDEX($R14:$AV14,1,23)),SUM(INDEX($R14:$AV14,1,23):INDEX($R14:$AV14,1,31)))} | BU14: 0 | BV14: 0 | BW14: 0 | BY14: =SUM(R14:X14) | BZ14: =SUM(Y14:AE14) | CA14: =SUM(AF14:AM14) | CB14: =SUM(AN14:AV14) | CD14: TIDAK ADA | CE14: =ROUND(BY14*$O14/1000,2) | CF14: =ROUND(BZ14*$O14/1000,2) | CG14: =ROUND(CA14*$O14/1000,2) | CH14: =ROUND(CB14*$O14/1000,2) | CI14: =SUM(CE14:CH14) | CK14: =IFERROR(ROUND(BY14*$P14,2),"") | CL14: =IFERROR(ROUND(BZ14*$P14,2),"") | CM14: =IFERROR(ROUND(CA14*$P14,2),"") | CN14: =IFERROR(ROUND(CB14*$P14,2),"") | CO14: =SUM(CK14:CN14)
B15: =_xlfn.XLOOKUP(G15,销售需求表!A:A,销售需求表!C:C) | C15: =IFERROR(MID(F15,FIND("R",F15)+1,4),"") | D15: =B15&C15&"寸" | E15: =LEFT(REPLACE(G15,1,2,""),FIND("[",REPLACE(G15,1,2,""))-1)&"-"&MID(REPLACE(G15,1,2,""),FIND("[",REPLACE(G15,1,2,""))+1,FIND("]",REPLACE(G15,1,2,""))-FIND("[",REPLACE(G15,1,2,""))-1) | F15: =IFERROR(MID(G15,3,FIND("(",G15)-3)&"-"&SUBSTITUTE(MID(G15,FIND("[",G15)+1,FIND("]",G15)-FIND("[",G15)-1),"Strong Guard ",""),"") | G15: ID11R22.5-16PR(146/143L)[M-TRAC MS]MASTERTRACK无内 | H15: 600 | J15: =IFERROR(LEFT(F15,FIND("-",F15))&MID(F15,FIND("PR",F15,FIND("-",F15))+3,LEN(F15)),F15) | K15: =_xlfn.XLOOKUP(F15,投产规格!E:E,投产规格!D:D,"未投产") | L15: =IFERROR(_xlfn.XLOOKUP(F15,硫化工艺!B:B,硫化工艺!C:C),"") | M15: =IF(L15="","",L15/(L15+$L$1/60)) | N15: =C15&"全钢" | O15: =IFERROR(_xlfn.XLOOKUP(F15,轮胎重量!J:J,轮胎重量!G:G),"") | P15: =O15*13.9 | Q15: =IFERROR(ROUND(1440/L15*(I15)*M15,0),"") | AK15: 60 | AL15: 60 | AM15: 60 | AN15: 60 | AO15: 60 | AP15: 60 | AQ15: 60 | AR15: 60 | AS15: 60 | AT15: 60 | AU15: 60 | AV15: 60 | AW15: =IF(SUM(R15:AV15)=0,"",SUM(R15:AV15)) | AX15: =IFERROR(AW15*O15/1000,"") | AY15: =IFERROR(ROUND(AW15*P15/10000,3),"") | BE15: =AZ15*AW15 | BF15: =BA15*AW15 | BG15: =BB15*AW15 | BH15: =BC15*AW15 | BJ15: {=_xlfn.LET(_xlpm.data,$R15:$AV15,_xlpm.starts,{1,8,16,23},_xlpm.lengths,{7,7,8,9},_xlpm.arr,_xlfn.MAP(_xlpm.starts,_xlpm.lengths,_xlfn.LAMBDA(_xlpm.s,_xlpm.l,SUM(INDEX(_xlpm.data,,_xlfn.SEQUENCE(,_xlpm.l,_xlpm.s))))),ROUND(_xlpm.arr*$O15/1000,2))} | BK15: 0 | BL15: 14.3 | BM15: 32.17 | BN15: =SUM(BJ15:BM15) | BO15: 0 | BP15: 0 | BQ15: 0 | BR15: 0 | BT15: {=_xlfn.HSTACK(SUM(INDEX($R15:$AV15,1,1):INDEX($R15:$AV15,1,7)),SUM(INDEX($R15:$AV15,1,7):INDEX($R15:$AV15,1,13)),SUM(INDEX($R15:$AV15,1,16):INDEX($R15:$AV15,1,23)),SUM(INDEX($R15:$AV15,1,23):INDEX($R15:$AV15,1,31)))} | BU15: 0 | BV15: 240 | BW15: 540 | BY15: =SUM(R15:X15) | BZ15: =SUM(Y15:AE15) | CA15: =SUM(AF15:AM15) | CB15: =SUM(AN15:AV15) | CD15: ADA | CE15: =ROUND(BY15*$O15/1000,2) | CF15: =ROUND(BZ15*$O15/1000,2) | CG15: =ROUND(CA15*$O15/1000,2) | CH15: =ROUND(CB15*$O15/1000,2) | CI15: =SUM(CE15:CH15) | CK15: =IFERROR(ROUND(BY15*$P15,2),"") | CL15: =IFERROR(ROUND(BZ15*$P15,2),"") | CM15: =IFERROR(ROUND(CA15*$P15,2),"") | CN15: =IFERROR(ROUND(CB15*$P15,2),"") | CO15: =SUM(CK15:CN15)
B16: =_xlfn.XLOOKUP(G16,销售需求表!A:A,销售需求表!C:C) | C16: =IFERROR(MID(F16,FIND("R",F16)+1,4),"") | D16: =B16&C16&"寸" | E16: =LEFT(REPLACE(G16,1,2,""),FIND("[",REPLACE(G16,1,2,""))-1)&"-"&MID(REPLACE(G16,1,2,""),FIND("[",REPLACE(G16,1,2,""))+1,FIND("]",REPLACE(G16,1,2,""))-FIND("[",REPLACE(G16,1,2,""))-1) | F16: =IFERROR(MID(G16,3,FIND("(",G16)-3)&"-"&SUBSTITUTE(MID(G16,FIND("[",G16)+1,FIND("]",G16)-FIND("[",G16)-1),"Strong Guard ",""),"") | G16: ID11R22.5-16PR(146/143L)[M-TRAC OSD]MASTERTRACK无内 | H16: 2000 | I16: 2 | J16: =IFERROR(LEFT(F16,FIND("-",F16))&MID(F16,FIND("PR",F16,FIND("-",F16))+3,LEN(F16)),F16) | K16: =_xlfn.XLOOKUP(F16,投产规格!E:E,投产规格!D:D,"未投产") | L16: =IFERROR(_xlfn.XLOOKUP(F16,硫化工艺!B:B,硫化工艺!C:C),"") | M16: =IF(L16="","",L16/(L16+$L$1/60)) | N16: =C16&"全钢" | O16: =IFERROR(_xlfn.XLOOKUP(F16,轮胎重量!J:J,轮胎重量!G:G),"") | P16: =O16*13.9 | Q16: =IFERROR(ROUND(1440/L16*(I16)*M16,0),"") | R16: 60 | S16: 60 | T16: 60 | U16: 60 | V16: 60 | W16: 60 | X16: 60 | Y16: 60 | Z16: 60 | AA16: 60 | AB16: 60 | AC16: 60 | AD16: 60 | AE16: 60 | AF16: 60 | AG16: 60 | AH16: 60 | AI16: 60 | AJ16: 60 | AK16: 60 | AL16: 60 | AM16: 60 | AN16: 60 | AO16: 60 | AP16: 60 | AQ16: 60 | AR16: 60 | AS16: 60 | AT16: 60 | AU16: 60 | AV16: 60 | AW16: =IF(SUM(R16:AV16)=0,"",SUM(R16:AV16)) | AX16: =IFERROR(AW16*O16/1000,"") | AY16: =IFERROR(ROUND(AW16*P16/10000,3),"") | BE16: =AZ16*AW16 | BF16: =BA16*AW16 | BG16: =BB16*AW16 | BH16: =BC16*AW16 | BJ16: {=_xlfn.LET(_xlpm.data,$R16:$AV16,_xlpm.starts,{1,8,16,23},_xlpm.lengths,{7,7,8,9},_xlpm.arr,_xlfn.MAP(_xlpm.starts,_xlpm.lengths,_xlfn.LAMBDA(_xlpm.s,_xlpm.l,SUM(INDEX(_xlpm.data,,_xlfn.SEQUENCE(,_xlpm.l,_xlpm.s))))),ROUND(_xlpm.arr*$O16/1000,2))} | BK16: 25.02 | BL16: 28.59 | BM16: 32.17 | BN16: =SUM(BJ16:BM16) | BO16: 0 | BP16: 0 | BQ16: 0 | BR16: 0 | BT16: {=_xlfn.HSTACK(SUM(INDEX($R16:$AV16,1,1):INDEX($R16:$AV16,1,7)),SUM(INDEX($R16:$AV16,1,7):INDEX($R16:$AV16,1,13)),SUM(INDEX($R16:$AV16,1,16):INDEX($R16:$AV16,1,23)),SUM(INDEX($R16:$AV16,1,23):INDEX($R16:$AV16,1,31)))} | BU16: 420 | BV16: 480 | BW16: 540 | BY16: =SUM(R16:X16) | BZ16: =SUM(Y16:AE16) | CA16: =SUM(AF16:AM16) | CB16: =SUM(AN16:AV16) | CD16: ADA | CE16: =ROUND(BY16*$O16/1000,2) | CF16: =ROUND(BZ16*$O16/1000,2) | CG16: =ROUND(CA16*$O16/1000,2) | CH16: =ROUND(CB16*$O16/1000,2) | CI16: =SUM(CE16:CH16) | CK16: =IFERROR(ROUND(BY16*$P16,2),"") | CL16: =IFERROR(ROUND(BZ16*$P16,2),"") | CM16: =IFERROR(ROUND(CA16*$P16,2),"") | CN16: =IFERROR(ROUND(CB16*$P16,2),"") | CO16: =SUM(CK16:CN16)
B17: =_xlfn.XLOOKUP(G17,销售需求表!A:A,销售需求表!C:C) | C17: =IFERROR(MID(F17,FIND("R",F17)+1,4),"") | D17: =B17&C17&"寸" | E17: =LEFT(REPLACE(G17,1,2,""),FIND("[",REPLACE(G17,1,2,""))-1)&"-"&MID(REPLACE(G17,1,2,""),FIND("[",REPLACE(G17,1,2,""))+1,FIND("]",REPLACE(G17,1,2,""))-FIND("[",REPLACE(G17,1,2,""))-1) | F17: =IFERROR(MID(G17,3,FIND("(",G17)-3)&"-"&SUBSTITUTE(MID(G17,FIND("[",G17)+1,FIND("]",G17)-FIND("[",G17)-1),"Strong Guard ",""),"") | G17: ID11R22.5-16PR(146/143L)[RLINE-S1]REDCLIFF无内 | H17: 280 | J17: =IFERROR(LEFT(F17,FIND("-",F17))&MID(F17,FIND("PR",F17,FIND("-",F17))+3,LEN(F17)),F17) | K17: =_xlfn.XLOOKUP(F17,投产规格!E:E,投产规格!D:D,"未投产") | L17: =IFERROR(_xlfn.XLOOKUP(F17,硫化工艺!B:B,硫化工艺!C:C),"") | M17: =IF(L17="","",L17/(L17+$L$1/60)) | N17: =C17&"全钢" | O17: =IFERROR(_xlfn.XLOOKUP(F17,轮胎重量!J:J,轮胎重量!G:G),"") | P17: =O17*13.9 | Q17: =IFERROR(ROUND(1440/L17*(I17)*M17,0),"") | AW17: =IF(SUM(R17:AV17)=0,"",SUM(R17:AV17)) | AX17: =IFERROR(AW17*O17/1000,"") | AY17: =IFERROR(ROUND(AW17*P17/10000,3),"") | BE17: =AZ17*AW17 | BF17: =BA17*AW17 | BG17: =BB17*AW17 | BH17: =BC17*AW17 | BJ17: {=_xlfn.LET(_xlpm.data,$R17:$AV17,_xlpm.starts,{1,8,16,23},_xlpm.lengths,{7,7,8,9},_xlpm.arr,_xlfn.MAP(_xlpm.starts,_xlpm.lengths,_xlfn.LAMBDA(_xlpm.s,_xlpm.l,SUM(INDEX(_xlpm.data,,_xlfn.SEQUENCE(,_xlpm.l,_xlpm.s))))),ROUND(_xlpm.arr*$O17/1000,2))} | BK17: 0 | BL17: 0 | BM17: 0 | BN17: =SUM(BJ17:BM17) | BO17: 0 | BP17: 0 | BQ17: 0 | BR17: 0 | BT17: {=_xlfn.HSTACK(SUM(INDEX($R17:$AV17,1,1):INDEX($R17:$AV17,1,7)),SUM(INDEX($R17:$AV17,1,7):INDEX($R17:$AV17,1,13)),SUM(INDEX($R17:$AV17,1,16):INDEX($R17:$AV17,1,23)),SUM(INDEX($R17:$AV17,1,23):INDEX($R17:$AV17,1,31)))} | BU17: 0 | BV17: 0 | BW17: 0 | BY17: =SUM(R17:X17) | BZ17: =SUM(Y17:AE17) | CA17: =SUM(AF17:AM17) | CB17: =SUM(AN17:AV17) | CD17: TIDAK ADA | CE17: =ROUND(BY17*$O17/1000,2) | CF17: =ROUND(BZ17*$O17/1000,2) | CG17: =ROUND(CA17*$O17/1000,2) | CH17: =ROUND(CB17*$O17/1000,2) | CI17: =SUM(CE17:CH17) | CK17: =IFERROR(ROUND(BY17*$P17,2),"") | CL17: =IFERROR(ROUND(BZ17*$P17,2),"") | CM17: =IFERROR(ROUND(CA17*$P17,2),"") | CN17: =IFERROR(ROUND(CB17*$P17,2),"") | CO17: =SUM(CK17:CN17)
B18: =_xlfn.XLOOKUP(G18,销售需求表!A:A,销售需求表!C:C) | C18: =IFERROR(MID(F18,FIND("R",F18)+1,4),"") | D18: =B18&C18&"寸" | E18: =LEFT(REPLACE(G18,1,2,""),FIND("[",REPLACE(G18,1,2,""))-1)&"-"&MID(REPLACE(G18,1,2,""),FIND("[",REPLACE(G18,1,2,""))+1,FIND("]",REPLACE(G18,1,2,""))-FIND("[",REPLACE(G18,1,2,""))-1) | F18: =IFERROR(MID(G18,3,FIND("(",G18)-3)&"-"&SUBSTITUTE(MID(G18,FIND("[",G18)+1,FIND("]",G18)-FIND("[",G18)-1),"Strong Guard ",""),"") | G18: ID11R22.5-16PR(146/143L)[Strong Guard H-RD]HERCULES无内 | H18: 750 | J18: =IFERROR(LEFT(F18,FIND("-",F18))&MID(F18,FIND("PR",F18,FIND("-",F18))+3,LEN(F18)),F18) | K18: =_xlfn.XLOOKUP(F18,投产规格!E:E,投产规格!D:D,"未投产") | L18: =IFERROR(_xlfn.XLOOKUP(F18,硫化工艺!B:B,硫化工艺!C:C),"") | M18: =IF(L18="","",L18/(L18+$L$1/60)) | N18: =C18&"全钢" | O18: =IFERROR(_xlfn.XLOOKUP(F18,轮胎重量!J:J,轮胎重量!G:G),"") | P18: =IFERROR(_xlfn.XLOOKUP(G18,硫化工艺!I:I,硫化工艺!J:J),"") | Q18: =IFERROR(ROUND(1440/L18*(I18)*M18,0),"") | AH18: 60 | AI18: 60 | AJ18: 60 | AK18: 60 | AL18: 60 | AM18: 60 | AN18: 60 | AO18: 60 | AP18: 60 | AQ18: 60 | AR18: 60 | AS18: 60 | AW18: =IF(SUM(R18:AV18)=0,"",SUM(R18:AV18)) | AX18: =IFERROR(AW18*O18/1000,"") | AY18: =IFERROR(ROUND(AW18*P18/10000,3),"") | BE18: =AZ18*AW18 | BF18: =BA18*AW18 | BG18: =BB18*AW18 | BH18: =BC18*AW18 | BJ18: {=_xlfn.LET(_xlpm.data,$R18:$AV18,_xlpm.starts,{1,8,16,23},_xlpm.lengths,{7,7,8,9},_xlpm.arr,_xlfn.MAP(_xlpm.starts,_xlpm.lengths,_xlfn.LAMBDA(_xlpm.s,_xlpm.l,SUM(INDEX(_xlpm.data,,_xlfn.SEQUENCE(,_xlpm.l,_xlpm.s))))),ROUND(_xlpm.arr*$O18/1000,2))} | BK18: 0 | BL18: 22.79 | BM18: 19.53 | BN18: =SUM(BJ18:BM18) | BO18: 0 | BP18: 0 | BQ18: 0 | BR18: 0 | BT18: {=_xlfn.HSTACK(SUM(INDEX($R18:$AV18,1,1):INDEX($R18:$AV18,1,7)),SUM(INDEX($R18:$AV18,1,7):INDEX($R18:$AV18,1,13)),SUM(INDEX($R18:$AV18,1,16):INDEX($R18:$AV18,1,23)),SUM(INDEX($R18:$AV18,1,23):INDEX($R18:$AV18,1,31)))} | BU18: 0 | BV18: 420 | BW18: 360 | BY18: =SUM(R18:X18) | BZ18: =SUM(Y18:AE18) | CA18: =SUM(AF18:AM18) | CB18: =SUM(AN18:AV18) | CD18: ADA | CE18: =ROUND(BY18*$O18/1000,2) | CF18: =ROUND(BZ18*$O18/1000,2) | CG18: =ROUND(CA18*$O18/1000,2) | CH18: =ROUND(CB18*$O18/1000,2) | CI18: =SUM(CE18:CH18) | CK18: =IFERROR(ROUND(BY18*$P18,2),"") | CL18: =IFERROR(ROUND(BZ18*$P18,2),"") | CM18: =IFERROR(ROUND(CA18*$P18,2),"") | CN18: =IFERROR(ROUND(CB18*$P18,2),"") | CO18: =SUM(CK18:CN18)
B19: =_xlfn.XLOOKUP(G19,销售需求表!A:A,销售需求表!C:C) | C19: =IFERROR(MID(F19,FIND("R",F19)+1,4),"") | D19: =B19&C19&"寸" | E19: =LEFT(REPLACE(G19,1,2,""),FIND("[",REPLACE(G19,1,2,""))-1)&"-"&MID(REPLACE(G19,1,2,""),FIND("[",REPLACE(G19,1,2,""))+1,FIND("]",REPLACE(G19,1,2,""))-FIND("[",REPLACE(G19,1,2,""))-1) | F19: =IFERROR(MID(G19,3,FIND("(",G19)-3)&"-"&SUBSTITUTE(MID(G19,FIND("[",G19)+1,FIND("]",G19)-FIND("[",G19)-1),"Strong Guard ",""),"") | G19: ID11R22.5-16PR(146/143M)[HF1 PlusX]SUPERMAX ECO无内 | H19: 400 | J19: =IFERROR(LEFT(F19,FIND("-",F19))&MID(F19,FIND("PR",F19,FIND("-",F19))+3,LEN(F19)),F19) | K19: =_xlfn.XLOOKUP(F19,投产规格!E:E,投产规格!D:D,"未投产") | L19: =IFERROR(_xlfn.XLOOKUP(F19,硫化工艺!B:B,硫化工艺!C:C),"") | M19: =IF(L19="","",L19/(L19+$L$1/60)) | N19: =C19&"全钢" | O19: =IFERROR(_xlfn.XLOOKUP(F19,轮胎重量!J:J,轮胎重量!G:G),"") | P19: =IFERROR(_xlfn.XLOOKUP(G19,硫化工艺!I:I,硫化工艺!J:J),"") | Q19: =IFERROR(ROUND(1440/L19*(I19)*M19,0),"") | AS19: 64 | AT19: 64 | AU19: 64 | AV19: 64 | AW19: =IF(SUM(R19:AV19)=0,"",SUM(R19:AV19)) | AX19: =IFERROR(AW19*O19/1000,"") | AY19: =IFERROR(ROUND(AW19*P19/10000,3),"") | BE19: =AZ19*AW19 | BF19: =BA19*AW19 | BG19: =BB19*AW19 | BH19: =BC19*AW19 | BJ19: {=_xlfn.LET(_xlpm.data,$R19:$AV19,_xlpm.starts,{1,8,16,23},_xlpm.lengths,{7,7,8,9},_xlpm.arr,_xlfn.MAP(_xlpm.starts,_xlpm.lengths,_xlfn.LAMBDA(_xlpm.s,_xlpm.l,SUM(INDEX(_xlpm.data,,_xlfn.SEQUENCE(,_xlpm.l,_xlpm.s))))),ROUND(_xlpm.arr*$O19/1000,2))} | BK19: 0 | BL19: 0 | BM19: 12.96 | BN19: =SUM(BJ19:BM19) | BO19: 0 | BP19: 0 | BQ19: 0 | BR19: 0 | BT19: {=_xlfn.HSTACK(SUM(INDEX($R19:$AV19,1,1):INDEX($R19:$AV19,1,7)),SUM(INDEX($R19:$AV19,1,7):INDEX($R19:$AV19,1,13)),SUM(INDEX($R19:$AV19,1,16):INDEX($R19:$AV19,1,23)),SUM(INDEX($R19:$AV19,1,23):INDEX($R19:$AV19,1,31)))} | BU19: 0 | BV19: 0 | BW19: 256 | BY19: =SUM(R19:X19) | BZ19: =SUM(Y19:AE19) | CA19: =SUM(AF19:AM19) | CB19: =SUM(AN19:AV19) | CD19: ADA | CE19: =ROUND(BY19*$O19/1000,2) | CF19: =ROUND(BZ19*$O19/1000,2) | CG19: =ROUND(CA19*$O19/1000,2) | CH19: =ROUND(CB19*$O19/1000,2) | CI19: =SUM(CE19:CH19) | CK19: =IFERROR(ROUND(BY19*$P19,2),"") | CL19: =IFERROR(ROUND(BZ19*$P19,2),"") | CM19: =IFERROR(ROUND(CA19*$P19,2),"") | CN19: =IFERROR(ROUND(CB19*$P19,2),"") | CO19: =SUM(CK19:CN19)
B20: =_xlfn.XLOOKUP(G20,销售需求表!A:A,销售需求表!C:C) | C20: =IFERROR(MID(F20,FIND("R",F20)+1,4),"") | D20: =B20&C20&"寸" | E20: =LEFT(REPLACE(G20,1,2,""),FIND("[",REPLACE(G20,1,2,""))-1)&"-"&MID(REPLACE(G20,1,2,""),FIND("[",REPLACE(G20,1,2,""))+1,FIND("]",REPLACE(G20,1,2,""))-FIND("[",REPLACE(G20,1,2,""))-1) | F20: =IFERROR(MID(G20,3,FIND("(",G20)-3)&"-"&SUBSTITUTE(MID(G20,FIND("[",G20)+1,FIND("]",G20)-FIND("[",G20)-1),"Strong Guard ",""),"") | G20: ID11R22.5-16PR(146/143M)[KOBE APM]ITARO无内 | H20: 750 | J20: =IFERROR(LEFT(F20,FIND("-",F20))&MID(F20,FIND("PR",F20,FIND("-",F20))+3,LEN(F20)),F20) | K20: =_xlfn.XLOOKUP(F20,投产规格!E:E,投产规格!D:D,"未投产") | L20: =IFERROR(_xlfn.XLOOKUP(F20,硫化工艺!B:B,硫化工艺!C:C),"") | M20: =IF(L20="","",L20/(L20+$L$1/60)) | N20: =C20&"全钢" | O20: =IFERROR(_xlfn.XLOOKUP(F20,轮胎重量!J:J,轮胎重量!G:G),"") | P20: =IFERROR(_xlfn.XLOOKUP(G20,硫化工艺!I:I,硫化工艺!J:J),"") | Q20: =IFERROR(ROUND(1440/L20*(I20)*M20,0),"") | AK20: 66 | AL20: 66 | AM20: 66 | AN20: 66 | AO20: 66 | AP20: 66 | AQ20: 66 | AR20: 66 | AS20: 66 | AT20: 66 | AU20: 66 | AV20: 66 | AW20: =IF(SUM(R20:AV20)=0,"",SUM(R20:AV20)) | AX20: =IFERROR(AW20*O20/1000,"") | AY20: =IFERROR(ROUND(AW20*P20/10000,3),"") | BE20: =AZ20*AW20 | BF20: =BA20*AW20 | BG20: =BB20*AW20 | BH20: =BC20*AW20 | BJ20: {=_xlfn.LET(_xlpm.data,$R20:$AV20,_xlpm.starts,{1,8,16,23},_xlpm.lengths,{7,7,8,9},_xlpm.arr,_xlfn.MAP(_xlpm.starts,_xlpm.lengths,_xlfn.LAMBDA(_xlpm.s,_xlpm.l,SUM(INDEX(_xlpm.data,,_xlfn.SEQUENCE(,_xlpm.l,_xlpm.s))))),ROUND(_xlpm.arr*$O20/1000,2))} | BK20: 0 | BL20: 13.37 | BM20: 30.08 | BN20: =SUM(BJ20:BM20) | BO20: 0 | BP20: 0 | BQ20: 0 | BR20: 0 | BT20: {=_xlfn.HSTACK(SUM(INDEX($R20:$AV20,1,1):INDEX($R20:$AV20,1,7)),SUM(INDEX($R20:$AV20,1,7):INDEX($R20:$AV20,1,13)),SUM(INDEX($R20:$AV20,1,16):INDEX($R20:$AV20,1,23)),SUM(INDEX($R20:$AV20,1,23):INDEX($R20:$AV20,1,31)))} | BU20: 0 | BV20: 264 | BW20: 594 | BY20: =SUM(R20:X20) | BZ20: =SUM(Y20:AE20) | CA20: =SUM(AF20:AM20) | CB20: =SUM(AN20:AV20) | CD20: ADA | CE20: =ROUND(BY20*$O20/1000,2) | CF20: =ROUND(BZ20*$O20/1000,2) | CG20: =ROUND(CA20*$O20/1000,2) | CH20: =ROUND(CB20*$O20/1000,2) | CI20: =SUM(CE20:CH20) | CK20: =IFERROR(ROUND(BY20*$P20,2),"") | CL20: =IFERROR(ROUND(BZ20*$P20,2),"") | CM20: =IFERROR(ROUND(CA20*$P20,2),"") | CN20: =IFERROR(ROUND(CB20*$P20,2),"") | CO20: =SUM(CK20:CN20)
B21: =_xlfn.XLOOKUP(G21,销售需求表!A:A,销售需求表!C:C) | C21: =IFERROR(MID(F21,FIND("R",F21)+1,4),"") | D21: =B21&C21&"寸" | E21: =LEFT(REPLACE(G21,1,2,""),FIND("[",REPLACE(G21,1,2,""))-1)&"-"&MID(REPLACE(G21,1,2,""),FIND("[",REPLACE(G21,1,2,""))+1,FIND("]",REPLACE(G21,1,2,""))-FIND("[",REPLACE(G21,1,2,""))-1) | F21: =IFERROR(MID(G21,3,FIND("(",G21)-3)&"-"&SUBSTITUTE(MID(G21,FIND("[",G21)+1,FIND("]",G21)-FIND("[",G21)-1),"Strong Guard ",""),"") | G21: ID11R22.5-16PR(148/145K)[Strong Guard H-MD]HERCULES无内 | H21: 1100 | I21: 2 | J21: =IFERROR(LEFT(F21,FIND("-",F21))&MID(F21,FIND("PR",F21,FIND("-",F21))+3,LEN(F21)),F21) | K21: =_xlfn.XLOOKUP(F21,投产规格!E:E,投产规格!D:D,"未投产") | L21: =IFERROR(_xlfn.XLOOKUP(F21,硫化工艺!B:B,硫化工艺!C:C),"") | M21: =IF(L21="","",L21/(L21+$L$1/60)) | N21: =C21&"全钢" | O21: =IFERROR(_xlfn.XLOOKUP(F21,轮胎重量!J:J,轮胎重量!G:G),"") | P21: =IFERROR(_xlfn.XLOOKUP(G21,硫化工艺!I:I,硫化工艺!J:J),"") | Q21: =IFERROR(ROUND(1440/L21*(I21)*M21,0),"") | R21: 58 | S21: 58 | T21: 58 | U21: 58 | V21: 58 | W21: 58 | X21: 58 | Y21: 58 | Z21: 58 | AA21: 58 | AB21: 58 | AC21: 58 | AD21: 58 | AE21: 58 | AF21: 58 | AG21: 58 | AW21: =IF(SUM(R21:AV21)=0,"",SUM(R21:AV21)) | AX21: =IFERROR(AW21*O21/1000,"") | AY21: =IFERROR(ROUND(AW21*P21/10000,3),"") | BE21: =AZ21*AW21 | BF21: =BA21*AW21 | BG21: =BB21*AW21 | BH21: =BC21*AW21 | BJ21: {=_xlfn.LET(_xlpm.data,$R21:$AV21,_xlpm.starts,{1,8,16,23},_xlpm.lengths,{7,7,8,9},_xlpm.arr,_xlfn.MAP(_xlpm.starts,_xlpm.lengths,_xlfn.LAMBDA(_xlpm.s,_xlpm.l,SUM(INDEX(_xlpm.data,,_xlfn.SEQUENCE(,_xlpm.l,_xlpm.s))))),ROUND(_xlpm.arr*$O21/1000,2))} | BK21: 24.49 | BL21: 3.5 | BM21: 0 | BN21: =SUM(BJ21:BM21) | BO21: 0 | BP21: 0 | BQ21: 0 | BR21: 0 | BT21: {=_xlfn.HSTACK(SUM(INDEX($R21:$AV21,1,1):INDEX($R21:$AV21,1,7)),SUM(INDEX($R21:$AV21,1,7):INDEX($R21:$AV21,1,13)),SUM(INDEX($R21:$AV21,1,16):INDEX($R21:$AV21,1,23)),SUM(INDEX($R21:$AV21,1,23):INDEX($R21:$AV21,1,31)))} | BU21: 406 | BV21: 58 | BW21: 0 | BY21: =SUM(R21:X21) | BZ21: =SUM(Y21:AE21) | CA21: =SUM(AF21:AM21) | CB21: =SUM(AN21:AV21) | CD21: ADA | CE21: =ROUND(BY21*$O21/1000,2) | CF21: =ROUND(BZ21*$O21/1000,2) | CG21: =ROUND(CA21*$O21/1000,2) | CH21: =ROUND(CB21*$O21/1000,2) | CI21: =SUM(CE21:CH21) | CK21: =IFERROR(ROUND(BY21*$P21,2),"") | CL21: =IFERROR(ROUND(BZ21*$P21,2),"") | CM21: =IFERROR(ROUND(CA21*$P21,2),"") | CN21: =IFERROR(ROUND(CB21*$P21,2),"") | CO21: =SUM(CK21:CN21)
B22: =_xlfn.XLOOKUP(G22,销售需求表!A:A,销售需求表!C:C) | C22: =IFERROR(MID(F22,FIND("R",F22)+1,4),"") | D22: =B22&C22&"寸" | E22: =LEFT(REPLACE(G22,1,2,""),FIND("[",REPLACE(G22,1,2,""))-1)&"-"&MID(REPLACE(G22,1,2,""),FIND("[",REPLACE(G22,1,2,""))+1,FIND("]",REPLACE(G22,1,2,""))-FIND("[",REPLACE(G22,1,2,""))-1) | F22: =IFERROR(MID(G22,3,FIND("(",G22)-3)&"-"&SUBSTITUTE(MID(G22,FIND("[",G22)+1,FIND("]",G22)-FIND("[",G22)-1),"Strong Guard ",""),"") | G22: ID11R22.5-16PR(148/145L)[AD716]GOODRIDE(好运)无内 | H22: 280 | J22: =IFERROR(LEFT(F22,FIND("-",F22))&MID(F22,FIND("PR",F22,FIND("-",F22))+3,LEN(F22)),F22) | K22: =_xlfn.XLOOKUP(F22,投产规格!E:E,投产规格!D:D,"未投产") | L22: =IFERROR(_xlfn.XLOOKUP(F22,硫化工艺!B:B,硫化工艺!C:C),"") | M22: =IF(L22="","",L22/(L22+$L$1/60)) | N22: =C22&"全钢" | O22: =IFERROR(_xlfn.XLOOKUP(F22,轮胎重量!J:J,轮胎重量!G:G),"") | P22: =IFERROR(_xlfn.XLOOKUP(G22,硫化工艺!I:I,硫化工艺!J:J),"") | Q22: =IFERROR(ROUND(1440/L22*(I22)*M22,0),"") | AT22: 60 | AU22: 60 | AV22: 60 | AW22: =IF(SUM(R22:AV22)=0,"",SUM(R22:AV22)) | AX22: =IFERROR(AW22*O22/1000,"") | AY22: =IFERROR(ROUND(AW22*P22/10000,3),"") | BE22: =AZ22*AW22 | BF22: =BA22*AW22 | BG22: =BB22*AW22 | BH22: =BC22*AW22 | BJ22: {=_xlfn.LET(_xlpm.data,$R22:$AV22,_xlpm.starts,{1,8,16,23},_xlpm.lengths,{7,7,8,9},_xlpm.arr,_xlfn.MAP(_xlpm.starts,_xlpm.lengths,_xlfn.LAMBDA(_xlpm.s,_xlpm.l,SUM(INDEX(_xlpm.data,,_xlfn.SEQUENCE(,_xlpm.l,_xlpm.s))))),ROUND(_xlpm.arr*$O22/1000,2))} | BK22: 0 | BL22: 0 | BM22: 10.05 | BN22: =SUM(BJ22:BM22) | BO22: 0 | BP22: 0 | BQ22: 0 | BR22: 0 | BT22: {=_xlfn.HSTACK(SUM(INDEX($R22:$AV22,1,1):INDEX($R22:$AV22,1,7)),SUM(INDEX($R22:$AV22,1,7):INDEX($R22:$AV22,1,13)),SUM(INDEX($R22:$AV22,1,16):INDEX($R22:$AV22,1,23)),SUM(INDEX($R22:$AV22,1,23):INDEX($R22:$AV22,1,31)))} | BU22: 0 | BV22: 0 | BW22: 180 | BY22: =SUM(R22:X22) | BZ22: =SUM(Y22:AE22) | CA22: =SUM(AF22:AM22) | CB22: =SUM(AN22:AV22) | CD22: ADA | CE22: =ROUND(BY22*$O22/1000,2) | CF22: =ROUND(BZ22*$O22/1000,2) | CG22: =ROUND(CA22*$O22/1000,2) | CH22: =ROUND(CB22*$O22/1000,2) | CI22: =SUM(CE22:CH22) | CK22: =IFERROR(ROUND(BY22*$P22,2),"") | CL22: =IFERROR(ROUND(BZ22*$P22,2),"") | CM22: =IFERROR(ROUND(CA22*$P22,2),"") | CN22: =IFERROR(ROUND(CB22*$P22,2),"") | CO22: =SUM(CK22:CN22)
B23: =_xlfn.XLOOKUP(G23,销售需求表!A:A,销售需求表!C:C) | C23: =IFERROR(MID(F23,FIND("R",F23)+1,4),"") | D23: =B23&C23&"寸" | E23: =LEFT(REPLACE(G23,1,2,""),FIND("[",REPLACE(G23,1,2,""))-1)&"-"&MID(REPLACE(G23,1,2,""),FIND("[",REPLACE(G23,1,2,""))+1,FIND("]",REPLACE(G23,1,2,""))-FIND("[",REPLACE(G23,1,2,""))-1) | F23: =IFERROR(MID(G23,3,FIND("(",G23)-3)&"-"&SUBSTITUTE(MID(G23,FIND("[",G23)+1,FIND("]",G23)-FIND("[",G23)-1),"Strong Guard ",""),"") | G23: ID11R22.5-16PR(148/145L)[AS858]GOODRIDE(好运)无内 | H23: 480 | J23: =IFERROR(LEFT(F23,FIND("-",F23))&MID(F23,FIND("PR",F23,FIND("-",F23))+3,LEN(F23)),F23) | K23: =_xlfn.XLOOKUP(F23,投产规格!E:E,投产规格!D:D,"未投产") | L23: =IFERROR(_xlfn.XLOOKUP(F23,硫化工艺!B:B,硫化工艺!C:C),"") | M23: =IF(L23="","",L23/(L23+$L$1/60)) | N23: =C23&"全钢" | O23: =IFERROR(_xlfn.XLOOKUP(F23,轮胎重量!J:J,轮胎重量!G:G),"") | P23: =IFERROR(_xlfn.XLOOKUP(G23,硫化工艺!I:I,硫化工艺!J:J),"") | Q23: =IFERROR(ROUND(1440/L23*(I23)*M23,0),"") | AN23: 60 | AO23: 60 | AP23: 60 | AQ23: 60 | AR23: 60 | AS23: 60 | AT23: 60 | AU23: 60 | AV23: 60 | AW23: =IF(SUM(R23:AV23)=0,"",SUM(R23:AV23)) | AX23: =IFERROR(AW23*O23/1000,"") | AY23: =IFERROR(ROUND(AW23*P23/10000,3),"") | BE23: =AZ23*AW23 | BF23: =BA23*AW23 | BG23: =BB23*AW23 | BH23: =BC23*AW23 | BJ23: {=_xlfn.LET(_xlpm.data,$R23:$AV23,_xlpm.starts,{1,8,16,23},_xlpm.lengths,{7,7,8,9},_xlpm.arr,_xlfn.MAP(_xlpm.starts,_xlpm.lengths,_xlfn.LAMBDA(_xlpm.s,_xlpm.l,SUM(INDEX(_xlpm.data,,_xlfn.SEQUENCE(,_xlpm.l,_xlpm.s))))),ROUND(_xlpm.arr*$O23/1000,2))} | BK23: 0 | BL23: 3.43 | BM23: 30.91 | BN23: =SUM(BJ23:BM23) | BO23: 0 | BP23: 0 | BQ23: 0 | BR23: 0 | BT23: {=_xlfn.HSTACK(SUM(INDEX($R23:$AV23,1,1):INDEX($R23:$AV23,1,7)),SUM(INDEX($R23:$AV23,1,7):INDEX($R23:$AV23,1,13)),SUM(INDEX($R23:$AV23,1,16):INDEX($R23:$AV23,1,23)),SUM(INDEX($R23:$AV23,1,23):INDEX($R23:$AV23,1,31)))} | BU23: 0 | BV23: 60 | BW23: 540 | BY23: =SUM(R23:X23) | BZ23: =SUM(Y23:AE23) | CA23: =SUM(AF23:AM23) | CB23: =SUM(AN23:AV23) | CD23: ADA | CE23: =ROUND(BY23*$O23/1000,2) | CF23: =ROUND(BZ23*$O23/1000,2) | CG23: =ROUND(CA23*$O23/1000,2) | CH23: =ROUND(CB23*$O23/1000,2) | CI23: =SUM(CE23:CH23) | CK23: =IFERROR(ROUND(BY23*$P23,2),"") | CL23: =IFERROR(ROUND(BZ23*$P23,2),"") | CM23: =IFERROR(ROUND(CA23*$P23,2),"") | CN23: =IFERROR(ROUND(CB23*$P23,2),"") | CO23: =SUM(CK23:CN23)
B24: =_xlfn.XLOOKUP(G24,销售需求表!A:A,销售需求表!C:C) | C24: =IFERROR(MID(F24,FIND("R",F24)+1,4),"") | D24: =B24&C24&"寸" | E24: =LEFT(REPLACE(G24,1,2,""),FIND("[",REPLACE(G24,1,2,""))-1)&"-"&MID(REPLACE(G24,1,2,""),FIND("[",REPLACE(G24,1,2,""))+1,FIND("]",REPLACE(G24,1,2,""))-FIND("[",REPLACE(G24,1,2,""))-1) | F24: =IFERROR(MID(G24,3,FIND("(",G24)-3)&"-"&SUBSTITUTE(MID(G24,FIND("[",G24)+1,FIND("]",G24)-FIND("[",G24)-1),"Strong Guard ",""),"") | G24: ID11R22.5-16PR(148/145L)[AS868]金冠无内 | H24: 2600 | I24: 2 | J24: =IFERROR(LEFT(F24,FIND("-",F24))&MID(F24,FIND("PR",F24,FIND("-",F24))+3,LEN(F24)),F24) | K24: =_xlfn.XLOOKUP(F24,投产规格!E:E,投产规格!D:D,"未投产") | L24: =IFERROR(_xlfn.XLOOKUP(F24,硫化工艺!B:B,硫化工艺!C:C),"") | M24: =IF(L24="","",L24/(L24+$L$1/60)) | N24: =C24&"全钢" | O24: =IFERROR(_xlfn.XLOOKUP(F24,轮胎重量!J:J,轮胎重量!G:G),"") | P24: =IFERROR(_xlfn.XLOOKUP(G24,硫化工艺!I:I,硫化工艺!J:J),"") | Q24: =IFERROR(ROUND(1440/L24*(I24)*M24,0),"") | R24: 60 | S24: 60 | T24: 60 | U24: 60 | V24: 60 | W24: 60 | X24: 60 | Y24: 60 | Z24: 60 | AA24: 60 | AB24: 60 | AC24: 60 | AD24: 60 | AE24: 60 | AF24: 60 | AG24: 60 | AH24: 60 | AI24: 60 | AJ24: 60 | AK24: 60 | AL24: 60 | AM24: 60 | AN24: 60 | AO24: 60 | AP24: 60 | AQ24: 60 | AR24: 60 | AS24: 60 | AT24: 60 | AU24: 60 | AV24: 60 | AW24: =IF(SUM(R24:AV24)=0,"",SUM(R24:AV24)) | AX24: =IFERROR(AW24*O24/1000,"") | AY24: =IFERROR(ROUND(AW24*P24/10000,3),"") | BE24: =AZ24*AW24 | BF24: =BA24*AW24 | BG24: =BB24*AW24 | BH24: =BC24*AW24 | BJ24: {=_xlfn.LET(_xlpm.data,$R24:$AV24,_xlpm.starts,{1,8,16,23},_xlpm.lengths,{7,7,8,9},_xlpm.arr,_xlfn.MAP(_xlpm.starts,_xlpm.lengths,_xlfn.LAMBDA(_xlpm.s,_xlpm.l,SUM(INDEX(_xlpm.data,,_xlfn.SEQUENCE(,_xlpm.l,_xlpm.s))))),ROUND(_xlpm.arr*$O24/1000,2))} | BK24: 24.04 | BL24: 27.47 | BM24: 30.91 | BN24: =SUM(BJ24:BM24) | BO24: 0 | BP24: 0 | BQ24: 0 | BR24: 0 | BT24: {=_xlfn.HSTACK(SUM(INDEX($R24:$AV24,1,1):INDEX($R24:$AV24,1,7)),SUM(INDEX($R24:$AV24,1,7):INDEX($R24:$AV24,1,13)),SUM(INDEX($R24:$AV24,1,16):INDEX($R24:$AV24,1,23)),SUM(INDEX($R24:$AV24,1,23):INDEX($R24:$AV24,1,31)))} | BU24: 420 | BV24: 480 | BW24: 540 | BY24: =SUM(R24:X24) | BZ24: =SUM(Y24:AE24) | CA24: =SUM(AF24:AM24) | CB24: =SUM(AN24:AV24) | CD24: ADA | CE24: =ROUND(BY24*$O24/1000,2) | CF24: =ROUND(BZ24*$O24/1000,2) | CG24: =ROUND(CA24*$O24/1000,2) | CH24: =ROUND(CB24*$O24/1000,2) | CI24: =SUM(CE24:CH24) | CK24: =IFERROR(ROUND(BY24*$P24,2),"") | CL24: =IFERROR(ROUND(BZ24*$P24,2),"") | CM24: =IFERROR(ROUND(CA24*$P24,2),"") | CN24: =IFERROR(ROUND(CB24*$P24,2),"") | CO24: =SUM(CK24:CN24)
B25: =_xlfn.XLOOKUP(G25,销售需求表!A:A,销售需求表!C:C) | C25: =IFERROR(MID(F25,FIND("R",F25)+1,4),"") | D25: =B25&C25&"寸" | E25: =LEFT(REPLACE(G25,1,2,""),FIND("[",REPLACE(G25,1,2,""))-1)&"-"&MID(REPLACE(G25,1,2,""),FIND("[",REPLACE(G25,1,2,""))+1,FIND("]",REPLACE(G25,1,2,""))-FIND("[",REPLACE(G25,1,2,""))-1) | F25: =IFERROR(MID(G25,3,FIND("(",G25)-3)&"-"&SUBSTITUTE(MID(G25,FIND("[",G25)+1,FIND("]",G25)-FIND("[",G25)-1),"Strong Guard ",""),"") | G25: ID11R22.5-16PR(148/145L)[AZ599]威狮无内 | H25: 400 | J25: =IFERROR(LEFT(F25,FIND("-",F25))&MID(F25,FIND("PR",F25,FIND("-",F25))+3,LEN(F25)),F25) | K25: =_xlfn.XLOOKUP(F25,投产规格!E:E,投产规格!D:D,"未投产") | L25: =IFERROR(_xlfn.XLOOKUP(F25,硫化工艺!B:B,硫化工艺!C:C),"") | M25: =IF(L25="","",L25/(L25+$L$1/60)) | N25: =C25&"全钢" | O25: =IFERROR(_xlfn.XLOOKUP(F25,轮胎重量!J:J,轮胎重量!G:G),"") | P25: =IFERROR(_xlfn.XLOOKUP(G25,硫化工艺!I:I,硫化工艺!J:J),"") | Q25: =IFERROR(ROUND(1440/L25*(I25)*M25,0),"") | AO25: 60 | AP25: 60 | AQ25: 60 | AR25: 60 | AS25: 60 | AT25: 60 | AU25: 60 | AV25: 60 | AW25: =IF(SUM(R25:AV25)=0,"",SUM(R25:AV25)) | AX25: =IFERROR(AW25*O25/1000,"") | AY25: =IFERROR(ROUND(AW25*P25/10000,3),"") | BE25: =AZ25*AW25 | BF25: =BA25*AW25 | BG25: =BB25*AW25 | BH25: =BC25*AW25 | BJ25: {=_xlfn.LET(_xlpm.data,$R25:$AV25,_xlpm.starts,{1,8,16,23},_xlpm.lengths,{7,7,8,9},_xlpm.arr,_xlfn.MAP(_xlpm.starts,_xlpm.lengths,_xlfn.LAMBDA(_xlpm.s,_xlpm.l,SUM(INDEX(_xlpm.data,,_xlfn.SEQUENCE(,_xlpm.l,_xlpm.s))))),ROUND(_xlpm.arr*$O25/1000,2))} | BK25: 0 | BL25: 0 | BM25: 24.99 | BN25: =SUM(BJ25:BM25) | BO25: 0 | BP25: 0 | BQ25: 0 | BR25: 0 | BT25: {=_xlfn.HSTACK(SUM(INDEX($R25:$AV25,1,1):INDEX($R25:$AV25,1,7)),SUM(INDEX($R25:$AV25,1,7):INDEX($R25:$AV25,1,13)),SUM(INDEX($R25:$AV25,1,16):INDEX($R25:$AV25,1,23)),SUM(INDEX($R25:$AV25,1,23):INDEX($R25:$AV25,1,31)))} | BU25: 0 | BV25: 0 | BW25: 480 | BY25: =SUM(R25:X25) | BZ25: =SUM(Y25:AE25) | CA25: =SUM(AF25:AM25) | CB25: =SUM(AN25:AV25) | CD25: ADA | CE25: =ROUND(BY25*$O25/1000,2) | CF25: =ROUND(BZ25*$O25/1000,2) | CG25: =ROUND(CA25*$O25/1000,2) | CH25: =ROUND(CB25*$O25/1000,2) | CI25: =SUM(CE25:CH25) | CK25: =IFERROR(ROUND(BY25*$P25,2),"") | CL25: =IFERROR(ROUND(BZ25*$P25,2),"") | CM25: =IFERROR(ROUND(CA25*$P25,2),"") | CN25: =IFERROR(ROUND(CB25*$P25,2),"") | CO25: =SUM(CK25:CN25)
