Workbook

Sheet local items
A1: market | B1: ERP Label Code - Chinese | C1: ERP Label Code - English | D1: 规格 specification | E1: 有无模版template | F1: EANCODE | G1: ERP CODE | H1: 品牌 Brand | I1: TT/TL | J1: M+S标记 | K1: 泥雪地 牵引标识位置 | L1: QTY | M1: RR | N1: W1.24t | O1: 噪音 | P1: 噪音等级 | Q1: pickup date
A2: SNI | B2: (ID-TIANLI-TBR-SNI)ID11.00R20-18PR(152/149F)[TZ101]TIANLI | C2: (ID-TIANLI-TBR-SNI)ID11.00R20-18PR(152/149F)[TZ101]TIANLI | D2: ID11.00R20-18PR(152/149F)[TZ101]TIANLI | G2: 0105045752ID | H2: TIANLI | I2: TT | J2: 18J | M2: 3000
A3: SNI | B3: (ID-EFFIPLUS-TBR-SNI)ID11.00R20-18PR(152/149K)[AM4S.Q679]EFFIPLUS | C3: (ID-EFFIPLUS-TBR-SNI)ID11.00R20-18PR(152/149K)[AM4S.Q679]EFFIPLUS | D3: ID11.00R20-18PR(152/149K)[AM4S.Q679]EFFIPLUS | G3: 01050457782ID | H3: EFFIPLUS | I3: TT | J3: 18J | M3: 3000
A4: SNI | B4: (ID-EFFIPLUS-TBR-SNI)ID11.00R20-18PR(152/149L)[FOLO.R109]EFFIPLUS | C4: (ID-EFFIPLUS-TBR-SNI)ID11.00R20-18PR(152/149L)[FOLO.R109]EFFIPLUS | D4: ID11.00R20-18PR(152/149L)[FOLO.R109]EFFIPLUS | G4: 01050457786ID | H4: EFFIPLUS | I4: TT | J4: 18J | M4: 3000
A5: SNI | B5: (ID-YR-TBR-SNI)ID12.00R20-20PR(156/153F)[EZ345]雅度 | C5: (ID-YR-TBR-SNI)ID12.00R20-20PR(156/153F)[EZ345]YARTU | D5: ID12.00R20-20PR(156/153F)[EZ345]雅度 | G5: 0105045809319ID | H5: YARTU | I5: TT | J5: 20L | M5: 5000
A6: SNI | B6: (ID-TN-TBR-SNI)ID12.00R20-22PR(158/155F)[TRD-79]TRAZANO(全诺) 东南亚 | C6: (ID-TN-TBR-SNI)ID12.00R20-22PR(158/155F)[TRD-79]TRAZANO | D6: ID12.00R20-22PR(158/155F)[TRD-79]TRAZANO(全诺) 东南亚 | G6: 0105045809529ID | H6: TRAZANO | I6: TT | J6: 22M | M6: 3000
A7: SNI | B7: (ID-YR-TBR-SNI)ID12.00R24-20PR(160/157F)[CB972]雅度 | C7: (ID-YR-TBR-SNI)ID12.00R24-20PR(160/157F)[CB972]YARTU | D7: ID12.00R24-20PR(160/157F)[CB972]雅度 | G7: 010504245ID | H7: YARTU | I7: TT | J7: 20L | M7: 5000
A8: SNI | B8: (ID-TN-TBR-SNI)ID12.00R24-20PR(160/157F)[TRD-79]TRAZANO(全诺) | C8: (ID-TN-TBR-SNI)ID12.00R24-20PR(160/157F)[TRD-79]TRAZANO | D8: ID12.00R24-20PR(160/157F)[TRD-79]TRAZANO(全诺) | G8: 0105045809530ID | H8: TRAZANO | I8: TT | J8: 20L | M8: 3000
A9: SNI | B9: (ID-TIANLI-TBR-SNI)ID7.50R16-14PR(122/118L)[TZ202]TIANLI | C9: (ID-TIANLI-TBR-SNI)ID7.50R16-14PR(122/118L)[TZ202]TIANLI | D9: ID7.50R16-14PR(122/118L)[TZ202]TIANLI | G9: 0105045754ID | H9: TIANLI | I9: TT | J9: 14G | M9: 3000
A10: SNI | B10: (ID-WL-BIAS-SNI)ID7.50-16LT-14PR[MR881]122/118K 威狮 | C10: (ID-WL-BIAS-SNI)ID7.50-16LT-14PR[MR881]122/118K WESTLAKE | D10: ID7.50-16LT-14PR[MR881]122/118K 威狮 | G10: 0105045809259ID | H10: WESTLAKE | I10: TT | J10: 14G | M10: 3000
A11: newitems
A12: SNI | B12: (ID-YR-TBR-SNI)ID7.50R16-14PR(122/118F)[CB972pro]雅度 | C12: (ID-YR-TBR-SNI)ID7.50R16-14PR(122/118F)[CB972pro]YARTU | D12: ID7.50R16-14PR(122/118F)[CB972pro]雅度 | F12: 0721688040064 | G12: 01050458095324ID | H12: YARTU | I12: TT | J12: 14G | K12: / | L12: / | M12: 3000
A13: SNI | B13: (ID-GR-TBR-SNI)ID7.50R16-14PR(122/118F)[CB972pro]好运 | C13: (ID-GR-TBR-SNI)ID7.50R16-14PR(122/118F)[CB972pro]GOODRIDE | D13: ID7.50R16-14PR(122/118F)[CB972pro]好运 | F13: 0721688040071 | G13: 01050458095325ID | H13: GOODRIDE | I13: TT | J13: 14G | K13: / | L13: / | M13: 3000
A14: SNI | B14: (ID-WL-TBR-SNI)ID7.50R16-14PR(122/118F)[CB972pro]威狮 | C14: (ID-WL-TBR-SNI)ID7.50R16-14PR(122/118F)[CB972pro]WESTLAKE | D14: ID7.50R16-14PR(122/118F)[CB972pro]威狮 | F14: 0721688040088 | G14: 01050458095326ID | H14: WESTLAKE | I14: TT | J14: 14G | K14: / | L14: / | M14: 3000
A15: SNI | B15: (ID-WL-TBR-SNI)ID7.50R16-14PR(122/118L)[AZ601+]威狮 | C15: (ID-WL-TBR-SNI)ID7.50R16-14PR(122/118L)[AZ601+]WESTLAKE | D15: ID7.50R16-14PR(122/118L)[AZ601+]威狮 | F15: 0721688040057 | G15: 0105045809532ID | H15: WESTLAKE | I15: TT | J15: 14G | K15: / | L15: / | M15: 3000

Sheet expert items
A1: market | B1: ERP Label Code - Chinese | C1: ERP Label Code - English | D1: 规格 specification | E1: 有无模版template | F1: EANCODE | G1: ERP CODE | H1: 品牌 Brand | I1: TT/TL | J1: M+S标记 | K1: 泥雪地 牵引标识位置 | L1: QTY | M1: RR | N1: W1.24t | O1: 噪音 | P1: 噪音等级 | Q1: pickup date
A2: OEM | B2: (ID-ITARO-TBR-OEM)ID11R22.5-16PR(146/143L)[KOBE DPM]ITARO无内 | C2: (ID-ITARO-TBR-OEM)ID11R22.5-16PR(146/143L)[KOBE DPM]ITARO TL | D2: ID11R22.5-16PR(146/143L)[KOBE DPM]ITARO无内 | E2: ✅ | G2: 0105045740ID | H2: ITARO | I2: TL | J2: 16H | M2: 3000
A3: PT | B3: (ID-WL-TBR-PT)ID11R22.5-16PR(148/145L)[AZ599]威狮无内 | C3: (ID-WL-TBR-PT)ID11R22.5-16PR(148/145L)[AZ599]WESTLAKE TL | D3: ID11R22.5-16PR(148/145L)[AZ599]威狮无内 | G3: 0105045672ID | H3: WESTLAKE | I3: TL | J3: 16H | M3: 3000
A4: ATD | B4: (ID-IRONMAN-TBR-ATD)ID11R22.5-16PR(148/145L)[I-28D]IRONMAN无内 SMARTWAY | C4: (ID-IRONMAN-TBR-ATD)ID11R22.5-16PR(148/145L)[I-28D]IRONMAN TL SMARTWAY | D4: ID11R22.5-16PR(148/145L)[I-28D]IRONMAN无内 SMARTWAY | E4: ✅ | G4: 0105045792ID | H4: IRONMAN | I4: TL | J4: 16H | M4: 3000
A5: OEM | B5: (ID-IRONMAN-TBR-OEM)ID215/75R17.5-16PR(135/133L)[I-19A]IRONMAN无内 | C5: (ID-IRONMAN-TBR-OEM)ID215/75R17.5-16PR(135/133L)[I-19A]IRONMAN TL | D5: ID215/75R17.5-16PR(135/133L)[I-19A]IRONMAN无内 | E5: ✅ | G5: 010504326ID | H5: IRONMAN | I5: TL | J5: 16H | M5: 3000
A6: OEM | B6: (ID-HERCULES-TBR-OEM)ID215/75R17.5-16PR(135/133L)[Strong Guard H-RA]HERCULES无内 | C6: (ID-HERCULES-TBR-OEM)ID215/75R17.5-16PR(135/133L)[Strong Guard H-RA]HERCULES TL | D6: ID215/75R17.5-16PR(135/133L)[Strong Guard H-RA]HERCULES无内 | E6: ✅ | G6: 01050457999ID | H6: HERCULES | I6: TL | J6: 16H | M6: 3000
A7: OEM | B7: (ID-HERCULES-TBR-OEM)ID225/70R19.5-14PR(128/126L)[Strong Guard H-RA]HERCULES无内 | C7: (ID-HERCULES-TBR-OEM)ID225/70R19.5-14PR(128/126L)[Strong Guard H-RA]HERCULES TL | D7: ID225/70R19.5-14PR(128/126L)[Strong Guard H-RA]HERCULES无内 | E7: ✅ | G7: 01050458001ID | H7: HERCULES | I7: TL | J7: 14G | M7: 5000
A8: OEM | B8: (ID-IRONMAN-TBR-OEM)ID225/70R19.5-14PR(128/126N)[I-19A]IRONMAN无内 | C8: (ID-IRONMAN-TBR-OEM)ID225/70R19.5-14PR(128/126N)[I-19A]IRONMAN TL | D8: ID225/70R19.5-14PR(128/126N)[I-19A]IRONMAN无内 | E8: ✅ | G8: 01050458003ID | H8: IRONMAN | I8: TL | J8: 14G | M8: 8000
A9: OEM | B9: (ID-IRONMAN-TBR-OEM)ID255/70R22.5-16PR(140/137M)[I-19A]IRONMAN无内 | C9: (ID-IRONMAN-TBR-OEM)ID255/70R22.5-16PR(140/137M)[I-19A]IRONMAN TL | D9: ID255/70R22.5-16PR(140/137M)[I-19A]IRONMAN无内 | E9: ✅ | G9: 01050458004ID | H9: IRONMAN | I9: TL | J9: 16H | M9: 3000
A10: OEM | B10: (ID-MASTERTRACK-TBR-OEM)ID255/70R22.5-16PR(140/137M)[M-TRAC AP]MASTERTRACK无内 | C10: (ID-MASTERTRACK-TBR-OEM)ID255/70R22.5-16PR(140/137M)[M-TRAC AP]MASTERTRACK TL | D10: ID255/70R22.5-16PR(140/137M)[M-TRAC AP]MASTERTRACK无内 | E10: ✅ | G10: 01050458007ID | H10: MASTERTRACK | I10: TL | J10: 16H | M10: 3000
A11: PT | B11: (ID-MASTERTRACK-TBR-PT)ID295/75R22.5-14PR(144/141L)[M-TRAC AP]MASTERTRACK无内 | C11: (ID-MASTERTRACK-TBR-PT)ID295/75R22.5-14PR(144/141L)[M-TRAC AP]MASTERTRACK TL | D11: ID295/75R22.5-14PR(144/141L)[M-TRAC AP]MASTERTRACK无内 | E11: ✅ | G11: 0105045809501ID | H11: MASTERTRACK | I11: TL | J11: 14G | M11: 3000
A12: OEM | B12: (ID-IRONMAN-TBR-OEM)ID295/75R22.5-14PR(144/141M)[I-19A]IRONMAN无内 SMARTWAY | C12: (ID-IRONMAN-TBR-OEM)ID295/75R22.5-14PR(144/141M)[I-19A]IRONMAN TL SMARTWAY | D12: ID295/75R22.5-14PR(144/141M)[I-19A]IRONMAN无内 SMARTWAY | E12: ✅ | G12: 0105045809270ID | H12: IRONMAN | I12: TL | J12: 14G | M12: 3000
A13: OEM | B13: (ID-IRONMAN-TBR-OEM)ID295/75R22.5-14PR(144/141M)[I-48T]IRONMAN无内 SMARTWAY | C13: (ID-IRONMAN-TBR-OEM)ID295/75R22.5-14PR(144/141M)[I-48T]IRONMAN TL SMARTWAY | D13: ID295/75R22.5-14PR(144/141M)[I-48T]IRONMAN无内 SMARTWAY | E13: ✅ | G13: 01050458006ID | H13: IRONMAN | I13: TL | J13: 14G | M13: 3000
A14: OEM | B14: (ID-ITARO-TBR-OEM)ID295/75R22.5-16PR(146/143L)[KOBE APM]ITARO无内 | C14: (ID-ITARO-TBR-OEM)ID295/75R22.5-16PR(146/143L)[KOBE APM]ITARO TL | D14: ID295/75R22.5-16PR(146/143L)[KOBE APM]ITARO无内 | E14: ✅ | G14: 0105045739ID | H14: ITARO | I14: TL | J14: 16H | M14: 3000
A15: OEM | B15: (ID-ITARO-TBR-OEM)ID295/75R22.5-16PR(146/143M)[KOBE TPM]ITARO无内 | C15: (ID-ITARO-TBR-OEM)ID295/75R22.5-16PR(146/143M)[KOBE TPM]ITARO TL | D15: ID295/75R22.5-16PR(146/143M)[KOBE TPM]ITARO无内 | E15: ✅ | G15: 0105045742ID | H15: ITARO | I15: TL | J15: 16H | M15: 3000
A16: OEM | B16: (ID-XBRI-TBR-OEM)ID295/80R22.5-18PR(150/147M)[ECOPLUS]XBRI无内 巴拉圭 | C16: (ID-XBRI-TBR-OEM)ID295/80R22.5-18PR(150/147M)[ECOPLUS]XBRI无内 巴拉圭 | D16: ID295/80R22.5-18PR(150/147M)[ECOPLUS]XBRI无内 巴拉圭 | G16: 0105045726ID | H16: XBRI | I16: TL | J16: 18J | M16: 10000
A17: PT | B17: (ID-WL-TBR-PT)ID315/80R22.5-20PR(157/154K)[CR926B]威狮无内 | C17: (ID-WL-TBR-PT)ID315/80R22.5-20PR(157/154K)[CR926B]WESTLAKE TL | D17: ID315/80R22.5-20PR(157/154K)[CR926B]威狮无内 | G17: 01050457955ID | H17: WESTLAKE | I17: TL | J17: 20L | M17: 3000
A18: PT | B18: (ID-YR-TBR-PT)ID11.00R20-18PR(152/149F)[EZ330A]雅度 | C18: (ID-YR-TBR-PT)ID11.00R20-18PR(152/149F)[EZ330A]YARTU | D18: ID11.00R20-18PR(152/149F)[EZ330A]雅度 | G18: 0105045809269ID | H18: YARTU | I18: TT | J18: 18J | M18: 3000
A19: BX | B19: (ID-WL-PCR-BX)ID175/65R14PR[Z-108]82H 西湖无内 | C19: (ID-WL-PCR-BX)ID175/65R14PR[Z-108]82H WESTLAKE TL | D19: ID175/65R14PR[Z-108]82H 西湖无内 | G19: 0105045809491ID | H19: WESTLAKE | I19: TL | J19: 14G | M19: 10000 | N19: F | O19: E | P19: 73 | Q19: 3
A20: BX | B20: (ID-WL-PCR-BX)ID185/70R14PR[Z-108]88T 西湖无内 | C20: (ID-WL-PCR-BX)ID185/70R14PR[Z-108]88T WESTLAKE TL | D20: ID185/70R14PR[Z-108]88T 西湖无内 | G20: 0105045809490ID | H20: WESTLAKE | I20: TL | J20: 14G | M20: 10000 | N20: F | O20: E | P20: 73 | Q20: 3
A21: BX | B21: (ID-WL-PCR-BX)ID175/70R14PR[Z-108]84T 西湖无内 | C21: (ID-WL-PCR-BX)ID175/70R14PR[Z-108]84T WESTLAKE TL | D21: ID175/70R14PR[Z-108]84T 西湖无内 | G21: 0105045809492ID | H21: WESTLAKE | I21: TL | J21: 14G | M21: 10000 | N21: F | O21: E | P21: 73 | Q21: 3
A22: PT | B22: (ID-WL-ST-PT)IDST175/80R13-6PR[ST100]91/87M 西湖无内 | C22: (ID-WL-ST-PT)IDST175/80R13-6PR[ST100]91/87M WESTLAKE TL | D22: IDST175/80R13-6PR[ST100]91/87M 西湖无内 | G22: 0105045809485ID | H22: WESTLAKE | I22: TL | J22: 6C | M22: 5000
A23: PT | B23: (ID-GR-ST-PT)IDST205/75R15-6PR[ST200]101/97M GOODRIDE(好运)无内 | C23: (ID-GR-ST-PT)IDST205/75R15-6PR[ST200]101/97M GOODRIDE TL | D23: IDST205/75R15-6PR[ST200]101/97M GOODRIDE(好运)无内 | G23: 0105045809384ID | H23: GOODRIDE | I23: TL | J23: 6C | M23: 5000
A24: PT | B24: (ID-WL-ST-PT)IDST235/80R16-10PR[ST100]124/120M 西湖无内 | C24: (ID-WL-ST-PT)IDST235/80R16-10PR[ST100]124/120M WESTLAKE TL | D24: IDST235/80R16-10PR[ST100]124/120M 西湖无内 | G24: 0105045809477ID | H24: WESTLAKE | I24: TL | J24: 10E | M24: 20000
A25: newitems
A26: PT | B26: (ID-MASTERTRACK-TBR-OEM)ID285/75R24.5-16PR(147/144L)[M-TRAC CSD]MASTERTRACK无内 | C26: (ID-MASTERTRACK-TBR-OEM)ID285/75R24.5-16PR(147/144L)[M-TRAC CSD]MASTERTRACK TL | D26: ID285/75R24.5-16PR(147/144L)[M-TRAC CSD]MASTERTRACK无内 | E26: ✅ | G26: 01050458095323ID | H26: MASTERTRACK | I26: TL | J26: 16H | M26: 3000
A27: BX | D27: ID295/80R22.5-18PR(152/149M)[AT161]SUDESTE无内 | H27: SUDESTE | I27: TL | J27: 18J | M27: 5000
A28: PT | B28: (ID-HERCULES-BIAS-OEM)ID5.70-12-6PR[STRONG GUARD SS]97A2 HERCULES无内 | C28: (ID-HERCULES-BIAS-OEM)ID5.70-12-6PR[STRONG GUARD SS]97A2 HERCULES TL | D28: ID5.70-12-6PR[STRONG GUARD SS]97A2 HERCULES无内 | E28: ✅ | G28: 01050458095327ID | H28: HERCULES | I28: TL | J28: 6C | M28: 3000
A29: PT | B29: (ID-HERCULES-BIAS-OEM)ID14.5/75-16.1SL-10PR[STRONG GUARD F-3]121A8 HERCULES无内 | C29: (ID-HERCULES-BIAS-OEM)ID14.5/75-16.1SL-10PR[STRONG GUARD F-3]121A8 HERCULES TL | D29: ID14.5/75-16.1SL-10PR[STRONG GUARD F-3]121A8 HERCULES无内 | E29: ✅ | G29: 01050458095328ID | H29: HERCULES | I29: TL | J29: 10E | M29: 3000
A30: BX | B30: (ID-TN-PCR-BX)ID165/70R13PR[T-118]79T TRAZANO(全诺)无内 | C30: (ID-TN-PCR-BX)ID165/70R13PR[T-118]79T TRAZANO TL | D30: ID165/70R13PR[T-118]79T TRAZANO(全诺)无内 | E30: 等认证 | F30: 0721688040095 | G30: 01050458095329ID | H30: TRAZANO | I30: TL | M30: 6000
A31: BX | B31: (ID-WL-PCR-BX)ID165/70R13PR[Z-108]79T 西湖无内 | C31: (ID-WL-PCR-BX)ID165/70R13PR[Z-108]79T WESTLAKE TL | D31: ID165/70R13PR[Z-108]79T 西湖无内 | F31: 0721688040101 | G31: 01050458095330ID | H31: WESTLAKE | I31: TL | M31: 6000 | N31: F | O31: E | P31: 73 | Q31: 3
A32: BX | B32: (ID-TN-PCR-BX)ID175/70R13PR[T-118]82T TRAZANO(全诺)无内 | C32: (ID-TN-PCR-BX)ID175/70R13PR[T-118]82T TRAZANO TL | D32: ID175/70R13PR[T-118]82T TRAZANO(全诺)无内 | E32: 等认证 | F32: 0721688040118 | G32: 01050458095331ID | H32: TRAZANO | I32: TL | M32: 10000
A33: BX | B33: (ID-WL-PCR-BX)ID175/70R13PR[Z-108]82T 西湖无内 | C33: (ID-WL-PCR-BX)ID175/70R13PR[Z-108]82T WESTLAKE TL | D33: ID175/70R13PR[Z-108]82T 西湖无内 | F33: 0721688040125 | G33: 01050458095332ID | H33: WESTLAKE | I33: TL | M33: 10000 | N33: F | O33: E | P33: 73 | Q33: 3
A34: BX | B34: (ID-TN-PCR-BX)ID175/65R14PR[T-118]82H TRAZANO(全诺)无内 | C34: (ID-TN-PCR-BX)ID175/65R14PR[T-118]82H TRAZANO TL | D34: ID175/65R14PR[T-118]82H TRAZANO(全诺)无内 | E34: 等认证 | F34: 0721688040132 | G34: 01050458095333ID | H34: TRAZANO | I34: TL | M34: 6000
A35: BX | B35: (ID-TN-PCR-BX)ID165/70R14PR[T-118]81T TRAZANO(全诺)无内 | C35: (ID-TN-PCR-BX)ID165/70R14PR[T-118]81T TRAZANO TL | D35: ID165/70R14PR[T-118]81T TRAZANO(全诺)无内 | E35: 等认证 | F35: 0721688040149 | G35: 01050458095334ID | H35: TRAZANO | I35: TL | M35: 6000
A36: BX | B36: (ID-WL-PCR-BX)ID165/70R14PR[Z-108]81T 西湖无内 | C36: (ID-WL-PCR-BX)ID165/70R14PR[Z-108]81T WESTLAKE TL | D36: ID165/70R14PR[Z-108]81T 西湖无内 | F36: 0721688040156 | G36: 01050458095335ID | H36: WESTLAKE | I36: TL | M36: 6000 | N36: F | O36: E | P36: 73 | Q36: 3
A37: BX | B37: (ID-TN-PCR-BX)ID185/65R14PR[T-118]86H TRAZANO(全诺)无内 | C37: (ID-TN-PCR-BX)ID185/65R14PR[T-118]86H TRAZANO TL | D37: ID185/65R14PR[T-118]86H TRAZANO(全诺)无内 | E37: 等认证 | F37: 0721688040163 | G37: 01050458095336ID | H37: TRAZANO | I37: TL | M37: 6000
A38: BX | B38: (ID-WL-PCR-BX)ID185/65R14PR[Z-108]86H 西湖无内 | C38: (ID-WL-PCR-BX)ID185/65R14PR[Z-108]86H WESTLAKE TL | D38: ID185/65R14PR[Z-108]86H 西湖无内 | F38: 0721688040170 | G38: 01050458095337ID | H38: WESTLAKE | I38: TL | M38: 6000 | N38: F | O38: E | P38: 73 | Q38: 3
A39: BX | B39: (ID-TN-PCR-BX)ID185/70R14PR[T-118]88T TRAZANO(全诺)无内 | C39: (ID-TN-PCR-BX)ID185/70R14PR[T-118]88T TRAZANO TL | D39: ID185/70R14PR[T-118]88T TRAZANO(全诺)无内 | E39: 等认证 | F39: 0721688040187 | G39: 01050458095338ID | H39: TRAZANO | I39: TL | M39: 10000
A40: BX | B40: (ID-TN-PCR-BX)ID175/70R14PR[T-118]84T TRAZANO(全诺)无内 | C40: (ID-TN-PCR-BX)ID175/70R14PR[T-118]84T TRAZANO TL | D40: ID175/70R14PR[T-118]84T TRAZANO(全诺)无内 | E40: 等认证 | F40: 0721688040194 | G40: 01050458095339ID | H40: TRAZANO | I40: TL | M40: 10000
...

Sheet Sheet1
A1: market | B1: ERP Label Code - Chinese | C1: ERP Label Code - English | D1: 规格 specification | E1: 有无模版template | F1: EANCODE | G1: ERP CODE | H1: 品牌 Brand | I1: TT/TL | J1: PR | K1: M+S标记 | L1: 泥雪地 牵引标识位置 | M1: QTY | N1: RR | O1: W1.24t | P1: 噪音 | Q1: 噪音等级 | R1: pickup date
A2: OEM | B2: (ID-ITARO-TBR-OEM)ID11R22.5-16PR(146/143L)[KOBE DPM]ITARO无内 | C2: (ID-ITARO-TBR-OEM)ID11R22.5-16PR(146/143L)[KOBE DPM]ITARO TL | D2: ID11R22.5-16PR(146/143L)[KOBE DPM]ITARO无内 | E2: ✅ | G2: 0105045740ID | H2: ITARO | I2: TL | J2: 16H | M2: 3000
A3: PT | B3: (ID-WL-TBR-PT)ID11R22.5-16PR(148/145L)[AZ599]威狮无内 | C3: (ID-WL-TBR-PT)ID11R22.5-16PR(148/145L)[AZ599]WESTLAKE TL | D3: ID11R22.5-16PR(148/145L)[AZ599]威狮无内 | G3: 0105045672ID | H3: WESTLAKE | I3: TL | J3: 16H | M3: 3000
A4: ATD | B4: (ID-IRONMAN-TBR-ATD)ID11R22.5-16PR(148/145L)[I-28D]IRONMAN无内 SMARTWAY | C4: (ID-IRONMAN-TBR-ATD)ID11R22.5-16PR(148/145L)[I-28D]IRONMAN TL SMARTWAY | D4: ID11R22.5-16PR(148/145L)[I-28D]IRONMAN无内 SMARTWAY | E4: ✅ | G4: 0105045792ID | H4: IRONMAN | I4: TL | J4: 16H | M4: 3000
A5: OEM | B5: (ID-IRONMAN-TBR-OEM)ID215/75R17.5-16PR(135/133L)[I-19A]IRONMAN无内 | C5: (ID-IRONMAN-TBR-OEM)ID215/75R17.5-16PR(135/133L)[I-19A]IRONMAN TL | D5: ID215/75R17.5-16PR(135/133L)[I-19A]IRONMAN无内 | E5: ✅ | G5: 010504326ID | H5: IRONMAN | I5: TL | J5: 16H | M5: 3000
A6: OEM | B6: (ID-HERCULES-TBR-OEM)ID215/75R17.5-16PR(135/133L)[Strong Guard H-RA]HERCULES无内 | C6: (ID-HERCULES-TBR-OEM)ID215/75R17.5-16PR(135/133L)[Strong Guard H-RA]HERCULES TL | D6: ID215/75R17.5-16PR(135/133L)[Strong Guard H-RA]HERCULES无内 | E6: ✅ | G6: 01050457999ID | H6: HERCULES | I6: TL | J6: 16H | M6: 3000
A7: OEM | B7: (ID-HERCULES-TBR-OEM)ID225/70R19.5-14PR(128/126L)[Strong Guard H-RA]HERCULES无内 | C7: (ID-HERCULES-TBR-OEM)ID225/70R19.5-14PR(128/126L)[Strong Guard H-RA]HERCULES TL | D7: ID225/70R19.5-14PR(128/126L)[Strong Guard H-RA]HERCULES无内 | E7: ✅ | G7: 01050458001ID | H7: HERCULES | I7: TL | J7: 14G | M7: 5000
A8: OEM | B8: (ID-IRONMAN-TBR-OEM)ID225/70R19.5-14PR(128/126N)[I-19A]IRONMAN无内 | C8: (ID-IRONMAN-TBR-OEM)ID225/70R19.5-14PR(128/126N)[I-19A]IRONMAN TL | D8: ID225/70R19.5-14PR(128/126N)[I-19A]IRONMAN无内 | E8: ✅ | G8: 01050458003ID | H8: IRONMAN | I8: TL | J8: 14G | M8: 8000
A9: OEM | B9: (ID-IRONMAN-TBR-OEM)ID255/70R22.5-16PR(140/137M)[I-19A]IRONMAN无内 | C9: (ID-IRONMAN-TBR-OEM)ID255/70R22.5-16PR(140/137M)[I-19A]IRONMAN TL | D9: ID255/70R22.5-16PR(140/137M)[I-19A]IRONMAN无内 | E9: ✅ | G9: 01050458004ID | H9: IRONMAN | I9: TL | J9: 16H | M9: 3000
A10: OEM | B10: (ID-MASTERTRACK-TBR-OEM)ID255/70R22.5-16PR(140/137M)[M-TRAC AP]MASTERTRACK无内 | C10: (ID-MASTERTRACK-TBR-OEM)ID255/70R22.5-16PR(140/137M)[M-TRAC AP]MASTERTRACK TL | D10: ID255/70R22.5-16PR(140/137M)[M-TRAC AP]MASTERTRACK无内 | E10: ✅ | G10: 01050458007ID | H10: MASTERTRACK | I10: TL | J10: 16H | M10: 3000
A11: PT | B11: (ID-MASTERTRACK-TBR-PT)ID295/75R22.5-14PR(144/141L)[M-TRAC AP]MASTERTRACK无内 | C11: (ID-MASTERTRACK-TBR-PT)ID295/75R22.5-14PR(144/141L)[M-TRAC AP]MASTERTRACK TL | D11: ID295/75R22.5-14PR(144/141L)[M-TRAC AP]MASTERTRACK无内 | E11: ✅ | G11: 0105045809501ID | H11: MASTERTRACK | I11: TL | J11: 14G | M11: 3000
A12: OEM | B12: (ID-IRONMAN-TBR-OEM)ID295/75R22.5-14PR(144/141M)[I-19A]IRONMAN无内 SMARTWAY | C12: (ID-IRONMAN-TBR-OEM)ID295/75R22.5-14PR(144/141M)[I-19A]IRONMAN TL SMARTWAY | D12: ID295/75R22.5-14PR(144/141M)[I-19A]IRONMAN无内 SMARTWAY | E12: ✅ | G12: 0105045809270ID | H12: IRONMAN | I12: TL | J12: 14G | M12: 3000
A13: OEM | B13: (ID-IRONMAN-TBR-OEM)ID295/75R22.5-14PR(144/141M)[I-48T]IRONMAN无内 SMARTWAY | C13: (ID-IRONMAN-TBR-OEM)ID295/75R22.5-14PR(144/141M)[I-48T]IRONMAN TL SMARTWAY | D13: ID295/75R22.5-14PR(144/141M)[I-48T]IRONMAN无内 SMARTWAY | E13: ✅ | G13: 01050458006ID | H13: IRONMAN | I13: TL | J13: 14G | M13: 3000
A14: OEM | B14: (ID-ITARO-TBR-OEM)ID295/75R22.5-16PR(146/143L)[KOBE APM]ITARO无内 | C14: (ID-ITARO-TBR-OEM)ID295/75R22.5-16PR(146/143L)[KOBE APM]ITARO TL | D14: ID295/75R22.5-16PR(146/143L)[KOBE APM]ITARO无内 | E14: ✅ | G14: 0105045739ID | H14: ITARO | I14: TL | J14: 16H | M14: 3000
A15: OEM | B15: (ID-ITARO-TBR-OEM)ID295/75R22.5-16PR(146/143M)[KOBE TPM]ITARO无内 | C15: (ID-ITARO-TBR-OEM)ID295/75R22.5-16PR(146/143M)[KOBE TPM]ITARO TL | D15: ID295/75R22.5-16PR(146/143M)[KOBE TPM]ITARO无内 | E15: ✅ | G15: 0105045742ID | H15: ITARO | I15: TL | J15: 16H | M15: 3000
A16: OEM | B16: (ID-XBRI-TBR-OEM)ID295/80R22.5-18PR(150/147M)[ECOPLUS]XBRI无内 巴拉圭 | C16: (ID-XBRI-TBR-OEM)ID295/80R22.5-18PR(150/147M)[ECOPLUS]XBRI无内 巴拉圭 | D16: ID295/80R22.5-18PR(150/147M)[ECOPLUS]XBRI无内 巴拉圭 | G16: 0105045726ID | H16: XBRI | I16: TL | J16: 18J | M16: 10000
A17: PT | B17: (ID-WL-TBR-PT)ID315/80R22.5-20PR(157/154K)[CR926B]威狮无内 | C17: (ID-WL-TBR-PT)ID315/80R22.5-20PR(157/154K)[CR926B]WESTLAKE TL | D17: ID315/80R22.5-20PR(157/154K)[CR926B]威狮无内 | G17: 01050457955ID | H17: WESTLAKE | I17: TL | J17: 20L | M17: 3000
A18: PT | B18: (ID-YR-TBR-PT)ID11.00R20-18PR(152/149F)[EZ330A]雅度 | C18: (ID-YR-TBR-PT)ID11.00R20-18PR(152/149F)[EZ330A]YARTU | D18: ID11.00R20-18PR(152/149F)[EZ330A]雅度 | G18: 0105045809269ID | H18: YARTU | I18: TT | J18: 18J | M18: 3000
A19: SNI | B19: (ID-TIANLI-TBR-SNI)ID11.00R20-18PR(152/149F)[TZ101]TIANLI | C19: (ID-TIANLI-TBR-SNI)ID11.00R20-18PR(152/149F)[TZ101]TIANLI | D19: ID11.00R20-18PR(152/149F)[TZ101]TIANLI | G19: 0105045752ID | H19: TIANLI | I19: TT | J19: 18J | M19: 3000
A20: SNI | B20: (ID-EFFIPLUS-TBR-SNI)ID11.00R20-18PR(152/149K)[AM4S.Q679]EFFIPLUS | C20: (ID-EFFIPLUS-TBR-SNI)ID11.00R20-18PR(152/149K)[AM4S.Q679]EFFIPLUS | D20: ID11.00R20-18PR(152/149K)[AM4S.Q679]EFFIPLUS | G20: 01050457782ID | H20: EFFIPLUS | I20: TT | J20: 18J | M20: 3000
A21: SNI | B21: (ID-EFFIPLUS-TBR-SNI)ID11.00R20-18PR(152/149L)[FOLO.R109]EFFIPLUS | C21: (ID-EFFIPLUS-TBR-SNI)ID11.00R20-18PR(152/149L)[FOLO.R109]EFFIPLUS | D21: ID11.00R20-18PR(152/149L)[FOLO.R109]EFFIPLUS | G21: 01050457786ID | H21: EFFIPLUS | I21: TT | J21: 18J | M21: 3000
A22: SNI | B22: (ID-YR-TBR-SNI)ID12.00R20-20PR(156/153F)[EZ345]雅度 | C22: (ID-YR-TBR-SNI)ID12.00R20-20PR(156/153F)[EZ345]YARTU | D22: ID12.00R20-20PR(156/153F)[EZ345]雅度 | G22: 0105045809319ID | H22: YARTU | I22: TT | J22: 20L | M22: 5000
A23: SNI | B23: (ID-TN-TBR-SNI)ID12.00R20-22PR(158/155F)[TRD-79]TRAZANO(全诺) 东南亚 | C23: (ID-TN-TBR-SNI)ID12.00R20-22PR(158/155F)[TRD-79]TRAZANO | D23: ID12.00R20-22PR(158/155F)[TRD-79]TRAZANO(全诺) 东南亚 | G23: 0105045809529ID | H23: TRAZANO | I23: TT | J23: 22M | M23: 3000
A24: SNI | B24: (ID-YR-TBR-SNI)ID12.00R24-20PR(160/157F)[CB972]雅度 | C24: (ID-YR-TBR-SNI)ID12.00R24-20PR(160/157F)[CB972]YARTU | D24: ID12.00R24-20PR(160/157F)[CB972]雅度 | G24: 010504245ID | H24: YARTU | I24: TT | J24: 20L | M24: 5000
A25: SNI | B25: (ID-TN-TBR-SNI)ID12.00R24-20PR(160/157F)[TRD-79]TRAZANO(全诺) | C25: (ID-TN-TBR-SNI)ID12.00R24-20PR(160/157F)[TRD-79]TRAZANO | D25: ID12.00R24-20PR(160/157F)[TRD-79]TRAZANO(全诺) | G25: 0105045809530ID | H25: TRAZANO | I25: TT | J25: 20L | M25: 3000
A26: SNI | B26: (ID-TIANLI-TBR-SNI)ID7.50R16-14PR(122/118L)[TZ202]TIANLI | C26: (ID-TIANLI-TBR-SNI)ID7.50R16-14PR(122/118L)[TZ202]TIANLI | D26: ID7.50R16-14PR(122/118L)[TZ202]TIANLI | G26: 0105045754ID | H26: TIANLI | I26: TT | J26: 14G | M26: 3000
A27: SNI | B27: (ID-WL-BIAS-SNI)ID7.50-16LT-14PR[MR881]122/118K 威狮 | C27: (ID-WL-BIAS-SNI)ID7.50-16LT-14PR[MR881]122/118K WESTLAKE | D27: ID7.50-16LT-14PR[MR881]122/118K 威狮 | G27: 0105045809259ID | H27: WESTLAKE | I27: TT | J27: 14G | M27: 3000
... A33: PT | B33: (ID-WL-ST-PT)IDST235/80R16-10PR[ST100]124/120M 西湖无内 | C33: (ID-WL-ST-PT)IDST235/80R16-10PR[ST100]124/120M WESTLAKE TL | D33: IDST235/80R16-10PR[ST100]124/120M 西湖无内 | G33: 0105045809477ID | H33: WESTLAKE | I33: TL | J33: 10E | M33: 20000
A34: newitems
A35: PT | B35: (ID-MASTERTRACK-TBR-OEM)ID285/75R24.5-16PR(147/144L)[M-TRAC CSD]MASTERTRACK无内 | C35: (ID-MASTERTRACK-TBR-OEM)ID285/75R24.5-16PR(147/144L)[M-TRAC CSD]MASTERTRACK TL | D35: ID285/75R24.5-16PR(147/144L)[M-TRAC CSD]MASTERTRACK无内 | E35: ✅ | G35: 01050458095323ID | H35: MASTERTRACK | I35: TL | J35: 16H | M35: 3000
A36: BX | D36: ID295/80R22.5-18PR(152/149M)[AT161]SUDESTE无内 | H36: SUDESTE | I36: TL | J36: 18J | M36: 5000
A37: SNI | B37: (ID-YR-TBR-SNI)ID7.50R16-14PR(122/118F)[CB972pro]雅度 | C37: (ID-YR-TBR-SNI)ID7.50R16-14PR(122/118F)[CB972pro]YARTU | D37: ID7.50R16-14PR(122/118F)[CB972pro]雅度 | F37: 0721688040064 | G37: 01050458095324ID | H37: YARTU | I37: TT | J37: 14G | K37: / | L37: / | M37: 3000
A38: SNI | B38: (ID-GR-TBR-SNI)ID7.50R16-14PR(122/118F)[CB972pro]好运 | C38: (ID-GR-TBR-SNI)ID7.50R16-14PR(122/118F)[CB972pro]GOODRIDE | D38: ID7.50R16-14PR(122/118F)[CB972pro]好运 | F38: 0721688040071 | G38: 01050458095325ID | H38: GOODRIDE | I38: TT | J38: 14G | K38: / | L38: / | M38: 3000
A39: SNI | B39: (ID-WL-TBR-SNI)ID7.50R16-14PR(122/118F)[CB972pro]威狮 | C39: (ID-WL-TBR-SNI)ID7.50R16-14PR(122/118F)[CB972pro]WESTLAKE | D39: ID7.50R16-14PR(122/118F)[CB972pro]威狮 | F39: 0721688040088 | G39: 01050458095326ID | H39: WESTLAKE | I39: TT | J39: 14G | K39: / | L39: / | M39: 3000
A40: SNI | B40: (ID-WL-TBR-SNI)ID7.50R16-14PR(122/118L)[AZ601+]威狮 | C40: (ID-WL-TBR-SNI)ID7.50R16-14PR(122/118L)[AZ601+]WESTLAKE | D40: ID7.50R16-14PR(122/118L)[AZ601+]威狮 | F40: 0721688040057 | G40: 0105045809532ID | H40: WESTLAKE | I40: TT | J40: 14G | K40: / | L40: / | M40: 3000
A41: PT | B41: (ID-HERCULES-BIAS-OEM)ID5.70-12-6PR[STRONG GUARD SS]97A2 HERCULES无内 | C41: (ID-HERCULES-BIAS-OEM)ID5.70-12-6PR[STRONG GUARD SS]97A2 HERCULES TL | D41: ID5.70-12-6PR[STRONG GUARD SS]97A2 HERCULES无内 | E41: ✅ | G41: 01050458095327ID | H41: HERCULES | I41: TL | J41: 6C | M41: 3000
A42: PT | B42: (ID-HERCULES-BIAS-OEM)ID14.5/75-16.1SL-10PR[STRONG GUARD F-3]121A8 HERCULES无内 | C42: (ID-HERCULES-BIAS-OEM)ID14.5/75-16.1SL-10PR[STRONG GUARD F-3]121A8 HERCULES TL | D42: ID14.5/75-16.1SL-10PR[STRONG GUARD F-3]121A8 HERCULES无内 | E42: ✅ | G42: 01050458095328ID | H42: HERCULES | I42: TL | J42: 10E | M42: 3000
A43: BX | B43: (ID-TN-PCR-BX)ID165/70R13PR[T-118]79T TRAZANO(全诺)无内 | C43: (ID-TN-PCR-BX)ID165/70R13PR[T-118]79T TRAZANO TL | D43: ID165/70R13PR[T-118]79T TRAZANO(全诺)无内 | E43: 等认证 | F43: 0721688040095 | G43: 01050458095329ID | H43: TRAZANO | I43: TL | M43: 6000
A44: BX | B44: (ID-WL-PCR-BX)ID165/70R13PR[Z-108]79T 西湖无内 | C44: (ID-WL-PCR-BX)ID165/70R13PR[Z-108]79T WESTLAKE TL | D44: ID165/70R13PR[Z-108]79T 西湖无内 | F44: 0721688040101 | G44: 01050458095330ID | H44: WESTLAKE | I44: TL | M44: 6000 | N44: F | O44: E | P44: 73 | Q44: 3
A45: BX | B45: (ID-TN-PCR-BX)ID175/70R13PR[T-118]82T TRAZANO(全诺)无内 | C45: (ID-TN-PCR-BX)ID175/70R13PR[T-118]82T TRAZANO TL | D45: ID175/70R13PR[T-118]82T TRAZANO(全诺)无内 | E45: 等认证 | F45: 0721688040118 | G45: 01050458095331ID | H45: TRAZANO | I45: TL | M45: 10000
...

Sheet 销售需求表
A1: 2025年7月外贸印尼计划需求
A2: 产品名称
A3: ID10.00-20-14PR[CR918]威狮 | B3: 450 | C3: 北美 | D3: =MID(A3,FIND("-",A3)+1,2) -> 20 | E3: 载重 | F3: =E3&D3&"寸" -> 载重20寸 | G3: =VLOOKUP(A3,'7月排产计划'!G3:G517,1,0) -> ID10.00-20-14PR[CR918]威狮
A4: ID10.00-20-16PR[CR952]146/142G 威狮 | B4: 280 | C4: 亚 | D4: =MID(A4,FIND("-",A4)+1,2) -> 20 | E4: 载重 | F4: =E4&D4&"寸" -> 载重20寸 | G4: =VLOOKUP(A4,'7月排产计划'!G4:G518,1,0) -> ID10.00-20-16PR[CR952]146/142G 威狮
A5: ID10.00-20-16PR[R9037]146/142G 朝阳 | B5: 2000 | C5: 亚 | D5: =MID(A5,FIND("-",A5)+1,2) -> 20 | E5: 载重 | F5: =E5&D5&"寸" -> 载重20寸 | G5: =VLOOKUP(A5,'7月排产计划'!G5:G519,1,0) -> ID10.00-20-16PR[R9037]146/142G 朝阳
A6: ID10.00-20-16PR[R9037]146/142G 金冠 | B6: 2000 | C6: 亚 | D6: =MID(A6,FIND("-",A6)+1,2) -> 20 | E6: 载重 | F6: =E6&D6&"寸" -> 载重20寸 | G6: =VLOOKUP(A6,'7月排产计划'!G6:G520,1,0) -> ID10.00-20-16PR[R9037]146/142G 金冠
A7: ID10.00-20-18PR[AB111]150/145G ASCENDO | B7: 180 | C7: 亚 | D7: =MID(A7,FIND("-",A7)+1,2) -> 20 | E7: 载重 | F7: =E7&D7&"寸" -> 载重20寸 | G7: =VLOOKUP(A7,'7月排产计划'!G7:G521,1,0) -> ID10.00-20-18PR[AB111]150/145G ASCENDO
A8: ID10.00-20-18PR[AB316]150/145G ASCENDO | B8: 500 | C8: 亚 | D8: =MID(A8,FIND("-",A8)+1,2) -> 20 | E8: 载重 | F8: =E8&D8&"寸" -> 载重20寸 | G8: =VLOOKUP(A8,'7月排产计划'!G8:G522,1,0) -> ID10.00-20-18PR[AB316]150/145G ASCENDO
A9: ID10.00-20-18PR[CL956]150/145G 金冠 | B9: 1000 | C9: 亚 | D9: =MID(A9,FIND("-",A9)+1,2) -> 20 | E9: 载重 | F9: =E9&D9&"寸" -> 载重20寸 | G9: =VLOOKUP(A9,'7月排产计划'!G9:G523,1,0) -> ID10.00-20-18PR[CL956]150/145G 金冠
A10: ID10.00-20-18PR[CR952]150/145G TRAZANO(全诺) | B10: 2000 | C10: 亚 | D10: =MID(A10,FIND("-",A10)+1,2) -> 20 | E10: 载重 | F10: =E10&D10&"寸" -> 载重20寸 | G10: =VLOOKUP(A10,'7月排产计划'!G10:G524,1,0) -> ID10.00-20-18PR[CR952]150/145G TRAZANO(全诺)
A11: ID10.00-20-18PR[CR952]150/145G 金冠 | B11: 2000 | C11: 亚 | D11: =MID(A11,FIND("-",A11)+1,2) -> 20 | E11: 载重 | F11: =E11&D11&"寸" -> 载重20寸 | G11: =VLOOKUP(A11,'7月排产计划'!G11:G525,1,0) -> ID10.00-20-18PR[CR952]150/145G 金冠
A12: ID10.00-20-18PR[CR952]150/145G 威狮 | B12: 560 | C12: 亚 | D12: =MID(A12,FIND("-",A12)+1,2) -> 20 | E12: 载重 | F12: =E12&D12&"寸" -> 载重20寸 | G12: =VLOOKUP(A12,'7月排产计划'!G12:G526,1,0) -> ID10.00-20-18PR[CR952]150/145G 威狮
A13: ID10.00-20-18PR[M9097]150/145G 朝阳 | B13: 2000 | C13: 亚 | D13: =MID(A13,FIND("-",A13)+1,2) -> 20 | E13: 载重 | F13: =E13&D13&"寸" -> 载重20寸 | G13: =VLOOKUP(A13,'7月排产计划'!G13:G527,1,0) -> ID10.00-20-18PR[M9097]150/145G 朝阳
A14: ID10.00-20-18PR[M9097]150/145G 金冠 | B14: 850 | C14: 亚 | D14: =MID(A14,FIND("-",A14)+1,2) -> 20 | E14: 载重 | F14: =E14&D14&"寸" -> 载重20寸 | G14: =VLOOKUP(A14,'7月排产计划'!G14:G528,1,0) -> ID10.00-20-18PR[M9097]150/145G 金冠
... A41: ID7.50-16LT-14PR[MX882]122/118K 威狮 | B41: 1300 | C41: 亚 | D41: =MID(A41,FIND("-",A41)+1,2) -> 16 | E41: 轻卡 | F41: =E41&D41&"寸" -> 轻卡16寸 | G41: =VLOOKUP(A41,'7月排产计划'!G41:G555,1,0) -> ID7.50-16LT-14PR[MX882]122/118K 威狮
A42: IDST205/75D15-6PR[TE898]101/97L TRANSEAGLE无内 | B42: 500 | C42: 北美 | D42: =MID(A42,FIND("-",A42)-2,2) -> 15 | E42: ST | F42: =E42&D42&"寸" -> ST15寸 | G42: =VLOOKUP(A42,'7月排产计划'!G42:G556,1,0) -> IDST205/75D15-6PR[TE898]101/97L TRANSEAGLE无内
A43: ID14.5/75-16.1SL-10PR[STRONG GUARD F-3]121A8 HERCULES无内 | B43: 140 | C43: 天津 | D43: =MID(A43,FIND("-",A43)+1,4) -> 16.1 | E43: ATD | F43: =E43&D43&"寸" -> ATD16.1寸 | G43: =VLOOKUP(A43,'7月排产计划'!G49:G563,1,0) -> ID14.5/75-16.1SL-10PR[STRONG GUARD F-3]121A8 HERCULES无内
A44: ID23.5-25-20PR[T318]天力 | B44: 40 | C44: OTR | D44: =MID(A44,FIND("-",A44)+1,2) -> 25 | E44: 工程胎 | F44: =E44&D44&"寸" -> 工程胎25寸 | G44: =VLOOKUP(A44,'7月排产计划'!G50:G564,1,0) -> ID23.5-25-20PR[T318]天力
A45: ID23.5-25-24PR[CL728]威狮 东南亚 | B45: 240 | C45: 亚 | D45: =MID(A45,FIND("-",A45)+1,2) -> 25 | E45: 工程胎 | F45: =E45&D45&"寸" -> 工程胎25寸 | G45: =VLOOKUP(A45,'7月排产计划'!G51:G565,1,0) -> ID23.5-25-24PR[CL728]威狮 东南亚
A46: ID23×8.50-12-6PR[STRONG GUARD SS]101A2 HERCULES无内 | B46: 160 | C46: 天津 | D46: =MID(A46,FIND("-",A46)+1,2) -> 12 | E46: ATD | F46: =E46&D46&"寸" -> ATD12寸 | G46: =VLOOKUP(A46,'7月排产计划'!G52:G566,1,0) -> ID23×8.50-12-6PR[STRONG GUARD SS]101A2 HERCULES无内
A47: ID26×12-12-8PR[STRONG GUARD R1]119A2 HERCULES无内 | B47: 250 | C47: 天津 | D47: =MID(A47,FIND("-",A47)+1,2) -> 12 | E47: ATD | F47: =E47&D47&"寸" -> ATD12寸 | G47: =VLOOKUP(A47,'7月排产计划'!G53:G567,1,0) -> ID26×12-12-8PR[STRONG GUARD R1]119A2 HERCULES无内
A48: ID27×8.5-15-8PR[STRONG GUARD SS]HERCULES无内 | B48: 420 | C48: 天津 | D48: =MID(A48,FIND("-",A48)+1,2) -> 15 | E48: ATD | F48: =E48&D48&"寸" -> ATD15寸 | G48: =VLOOKUP(A48,'7月排产计划'!G54:G568,1,0) -> ID27×8.5-15-8PR[STRONG GUARD SS]HERCULES无内
A49: ID29×12.5-15-8PR[STRONG GUARD R1]123A2 HERCULES无内 | B49: 100 | C49: 天津 | D49: =MID(A49,FIND("-",A49)+1,2) -> 15 | E49: ATD | F49: =E49&D49&"寸" -> ATD15寸 | G49: =VLOOKUP(A49,'7月排产计划'!G55:G569,1,0) -> ID29×12.5-15-8PR[STRONG GUARD R1]123A2 HERCULES无内
A50: ID5.70-12-6PR[STRONG GUARD SS]97A2 HERCULES无内 | B50: 180 | C50: 天津 | D50: =MID(A50,FIND("-",A50)+1,2) -> 12 | E50: ATD | F50: =E50&D50&"寸" -> ATD12寸 | G50: =VLOOKUP(A50,'7月排产计划'!G56:G570,1,0) -> ID5.70-12-6PR[STRONG GUARD SS]97A2 HERCULES无内
G51: =VLOOKUP(A51,'7月排产计划'!G57:G571,1,0) -> #N/A
B52: =SUM(B3:B51) -> 61940 | G52: =VLOOKUP(A52,'7月排产计划'!G58:G572,1,0) -> #N/A
G53: =VLOOKUP(A53,'7月排产计划'!G59:G573,1,0) -> #N/A
G54: =VLOOKUP(A54,'7月排产计划'!G60:G574,1,0) -> #N/A
G55: =VLOOKUP(A55,'7月排产计划'!G61:G575,1,0) -> #N/A
G56: =VLOOKUP(A56,'7月排产计划'!G62:G576,1,0) -> #N/A
A57: ID11R22.5-14PR(144/142M)[AT552]ARISUN无内 | B57: 700 | C57: 亚 | D57: =MID(A57,FIND("R",A57)+1,4) -> 22.5 | E57: =_xlfn.XLOOKUP(A57,'7月排产计划'!G:G,'7月排产计划'!B:B) -> 亚 | F57: =E57&D57&"寸" -> 亚22.5寸 | G57: =VLOOKUP(A57,'7月排产计划'!G63:G577,1,0) -> #N/A | H57: =D57&G57 -> #N/A | I57: =VLOOKUP(A57,[2]Sheet1!$C$3:$G$310,5,0) -> #N/A | J57: =VLOOKUP(A57,[3]KCBB0101!$C$3:$F$691,4,0) -> 8214 | K57: =VLOOKUP(A57,'7月排产计划'!G3:G517,1,0) -> ID11R22.5-14PR(144/142M)[AT552]ARISUN无内
A58: ID11R22.5-14PR(144/142M)[AT563]ARISUN无内 | B58: 300 | C58: 北美 | D58: =MID(A58,FIND("R",A58)+1,4) -> 22.5 | E58: =_xlfn.XLOOKUP(A58,'7月排产计划'!G:G,'7月排产计划'!B:B) -> 北美 | F58: =E58&D58&"寸" -> 北美22.5寸 | G58: =VLOOKUP(A58,'7月排产计划'!G64:G578,1,0) -> #N/A | H58: =D58&G58 -> #N/A | I58: =VLOOKUP(A58,[2]Sheet1!$C$3:$G$310,5,0) -> #N/A | J58: =VLOOKUP(A58,[3]KCBB0101!$C$3:$F$691,4,0) -> 2573 | K58: =VLOOKUP(A58,'7月排产计划'!G4:G518,1,0) -> ID11R22.5-14PR(144/142M)[AT563]ARISUN无内
A59: ID11R22.5-14PR(144/142M)[CR915]威狮无内 | B59: 500 | C59: 北美 | D59: =MID(A59,FIND("R",A59)+1,4) -> 22.5 | E59: =_xlfn.XLOOKUP(A59,'7月排产计划'!G:G,'7月排产计划'!B:B) -> 北美 | F59: =E59&D59&"寸" -> 北美22.5寸 | G59: =VLOOKUP(A59,'7月排产计划'!G65:G579,1,0) -> #N/A | H59: =D59&G59 -> #N/A | I59: =VLOOKUP(A59,[2]Sheet1!$C$3:$G$310,5,0) -> 5700 | J59: =VLOOKUP(A59,[3]KCBB0101!$C$3:$F$691,4,0) -> #N/A | K59: =VLOOKUP(A59,'7月排产计划'!G5:G519,1,0) -> ID11R22.5-14PR(144/142M)[CR915]威狮无内
A60: ID11R22.5-14PR(144/142M)[HT1 Plus]SUPERMAX无内 | B60: 580 | C60: 北美 | D60: =MID(A60,FIND("R",A60)+1,4) -> 22.5 | E60: =_xlfn.XLOOKUP(A60,'7月排产计划'!G:G,'7月排产计划'!B:B) -> 北美 | F60: =E60&D60&"寸" -> 北美22.5寸 | G60: =VLOOKUP(A60,'7月排产计划'!G66:G580,1,0) -> #N/A | H60: =D60&G60 -> #N/A | I60: =VLOOKUP(A60,[2]Sheet1!$C$3:$G$310,5,0) -> #N/A | J60: =VLOOKUP(A60,[3]KCBB0101!$C$3:$F$691,4,0) -> 5000 | K60: =VLOOKUP(A60,'7月排产计划'!G6:G520,1,0) -> ID11R22.5-14PR(144/142M)[HT1 Plus]SUPERMAX无内
A61: ID11R22.5-14PR(144/142M)[I-48T]IRONMAN无内 SMARTWAY | B61: 800 | C61: 北美 | D61: =MID(A61,FIND("R",A61)+1,4) -> 22.5 | E61: =_xlfn.XLOOKUP(A61,'7月排产计划'!G:G,'7月排产计划'!B:B) -> 北美 | F61: =E61&D61&"寸" -> 北美22.5寸 | G61: =VLOOKUP(A61,'7月排产计划'!G67:G581,1,0) -> #N/A | H61: =D61&G61 -> #N/A | I61: =VLOOKUP(A61,[2]Sheet1!$C$3:$G$310,5,0) -> 7500 | J61: =VLOOKUP(A61,[3]KCBB0101!$C$3:$F$691,4,0) -> #N/A | K61: =VLOOKUP(A61,'7月排产计划'!G7:G521,1,0) -> ID11R22.5-14PR(144/142M)[I-48T]IRONMAN无内 SMARTWAY
A62: ID11R22.5-14PR(144/142M)[M-TRAC TR]MASTERTRACK无内 | B62: 620 | C62: 北美 | D62: =MID(A62,FIND("R",A62)+1,4) -> 22.5 | E62: =_xlfn.XLOOKUP(A62,'7月排产计划'!G:G,'7月排产计划'!B:B) -> 北美 | F62: =E62&D62&"寸" -> 北美22.5寸 | G62: =VLOOKUP(A62,'7月排产计划'!G68:G582,1,0) -> #N/A | H62: =D62&G62 -> #N/A | I62: =VLOOKUP(A62,[2]Sheet1!$C$3:$G$310,5,0) -> #N/A | J62: =VLOOKUP(A62,[3]KCBB0101!$C$3:$F$691,4,0) -> 8000 | K62: =VLOOKUP(A62,'7月排产计划'!G8:G522,1,0) -> ID11R22.5-14PR(144/142M)[M-TRAC TR]MASTERTRACK无内
A63: ID11R22.5-14PR(144/142M)[Strong Guard H-TL]HERCULES无内 | B63: 280 | C63: 北美 | D63: =MID(A63,FIND("R",A63)+1,4) -> 22.5 | E63: =_xlfn.XLOOKUP(A63,'7月排产计划'!G:G,'7月排产计划'!B:B) -> 北美 | F63: =E63&D63&"寸" -> 北美22.5寸 | G63: =VLOOKUP(A63,'7月排产计划'!G69:G583,1,0) -> #N/A | H63: =D63&G63 -> #N/A | I63: =VLOOKUP(A63,[2]Sheet1!$C$3:$G$310,5,0) -> 11500 | J63: =VLOOKUP(A63,[3]KCBB0101!$C$3:$F$691,4,0) -> #N/A | K63: =VLOOKUP(A63,'7月排产计划'!G9:G523,1,0) -> ID11R22.5-14PR(144/142M)[Strong Guard H-TL]HERCULES无内
A64: ID11R22.5-16PR(146/143L)[DOMINATE D01]BLACKARROW无内 | B64: 280 | C64: 北美 | D64: =MID(A64,FIND("R",A64)+1,4) -> 22.5 | E64: =_xlfn.XLOOKUP(A64,'7月排产计划'!G:G,'7月排产计划'!B:B) -> 北美 | F64: =E64&D64&"寸" -> 北美22.5寸 | G64: =VLOOKUP(A64,'7月排产计划'!G70:G584,1,0) -> #N/A | H64: =D64&G64 -> #N/A | I64: =VLOOKUP(A64,[2]Sheet1!$C$3:$G$310,5,0) -> #N/A | J64: =VLOOKUP(A64,[3]KCBB0101!$C$3:$F$691,4,0) -> 3000 | K64: =VLOOKUP(A64,'7月排产计划'!G10:G524,1,0) -> ID11R22.5-16PR(146/143L)[DOMINATE D01]BLACKARROW无内
A65: ID11R22.5-16PR(146/143L)[HD1 PlusX]SUPERMAX ECO无内 | B65: 750 | C65: 北美 | D65: =MID(A65,FIND("R",A65)+1,4) -> 22.5 | E65: =_xlfn.XLOOKUP(A65,'7月排产计划'!G:G,'7月排产计划'!B:B) -> 北美 | F65: =E65&D65&"寸" -> 北美22.5寸 | G65: =VLOOKUP(A65,'7月排产计划'!G71:G585,1,0) -> #N/A | H65: =D65&G65 -> #N/A | I65: =VLOOKUP(A65,[2]Sheet1!$C$3:$G$310,5,0) -> #N/A | J65: =VLOOKUP(A65,[3]KCBB0101!$C$3:$F$691,4,0) -> 4200 | K65: =VLOOKUP(A65,'7月排产计划'!G11:G525,1,0) -> ID11R22.5-16PR(146/143L)[HD1 PlusX]SUPERMAX ECO无内
A66: ID11R22.5-16PR(146/143L)[KOBE DPM]ITARO无内 | B66: 1700 | C66: 北美 | D66: =MID(A66,FIND("R",A66)+1,4) -> 22.5 | E66: =_xlfn.XLOOKUP(A66,'7月排产计划'!G:G,'7月排产计划'!B:B) -> 北美 | F66: =E66&D66&"寸" -> 北美22.5寸 | G66: =VLOOKUP(A66,'7月排产计划'!G72:G586,1,0) -> #N/A | H66: =D66&G66 -> #N/A | I66: =VLOOKUP(A66,[2]Sheet1!$C$3:$G$310,5,0) -> #N/A | J66: =VLOOKUP(A66,[3]KCBB0101!$C$3:$F$691,4,0) -> 3503 | K66: =VLOOKUP(A66,'7月排产计划'!G12:G526,1,0) -> ID11R22.5-16PR(146/143L)[KOBE DPM]ITARO无内
...

Sheet 7月排产计划
G1: , | I1: {=SUM((I3:I376)/2)} -> 142 | L1: 350 | Q1: =SUM(Q3:Q375) -> 8999 | AZ1: 定额 | BE1: 计划产生
B2: 市场 | C2: 尺寸 | E2: 规格花纹 | G2: 全钢规格 | H2: 订单数 | I2: 模具 | J2: 发出模具 | K2: 优先级别 | L2: 硫化时间 | M2: 运转率 | N2: 轮胎库存 | O2: 单胎重量 | P2: 中策价 | Q2: 硫化机 条/天 | R2: 1 | S2: 2 | T2: 3 | U2: 4 | V2: 5 | W2: 6 | X2: 7 | Y2: 8 | Z2: 9 | AA2: 10 | AB2: 11 | AC2: 12 | AD2: 13 | AE2: 14 | AF2: 15 | AG2: 16 | AH2: 17 | AI2: 18 | AJ2: 19 | AK2: 20 | AL2: 21 | AM2: 22 | AN2: 23 | AO2: 24 | AP2: 25 | AQ2: 26 | AR2: 27 | AS2: 28 | AT2: 29 | AU2: 30 | AV2: 31 | AW2: 合计 | AX2: 吨位 | AY2: 产值(万元) | AZ2: 原材料 | BA2: 动力 | BB2: 工资 | BC2: 车间经费 | BE2: 原材料 | BF2: 动力 | BG2: 工资 | BH2: 车间经费 | BY2: =SUM(BY3:BY376) -> 57034 | BZ2: =SUM(BZ3:BZ376) -> 62050 | CA2: =SUM(CA3:CA376) -> 72418 | CB2: =SUM(CB3:CB376) -> 82194
B3: =_xlfn.XLOOKUP(G3,销售需求表!A:A,销售需求表!C:C) -> 亚 | C3: =IFERROR(MID(F3,FIND("R",F3)+1,4),"") -> 22.5 | D3: =B3&C3&"寸" -> 亚22.5寸 | E3: =LEFT(REPLACE(G3,1,2,""),FIND("[",REPLACE(G3,1,2,""))-1)&"-"&MID(REPLACE(G3,1,2,""),FIND("[",REPLACE(G3,1,2,""))+1,FIND("]",REPLACE(G3,1,2,""))-FIND("[",REPLACE(G3,1,2,""))-1) -> 11R22.5-14PR(144/142M)-AT552 | F3: =IFERROR(MID(G3,3,FIND("(",G3)-3)&"-"&SUBSTITUTE(MID(G3,FIND("[",G3)+1,FIND("]",G3)-FIND("[",G3)-1),"Strong Guard ",""),"") -> 11R22.5-14PR-AT552 | G3: ID11R22.5-14PR(144/142M)[AT552]ARISUN无内 | H3: 700 | J3: =IFERROR(LEFT(F3,FIND("-",F3))&MID(F3,FIND("PR",F3,FIND("-",F3))+3,LEN(F3)),F3) -> 11R22.5-AT552 | K3: =_xlfn.XLOOKUP(F3,投产规格!E:E,投产规格!D:D,"未投产") -> ✔ | L3: =IFERROR(_xlfn.XLOOKUP(F3,硫化工艺!B:B,硫化工艺!C:C),"") -> 36.5 | M3: =IF(L3="","",L3/(L3+$L$1/60)) -> 0.86220472 | N3: =C3&"全钢" -> 22.5全钢 | O3: =IFERROR(_xlfn.XLOOKUP(F3,轮胎重量!J:J,轮胎重量!G:G),"") -> 48.15 | P3: =IFERROR(_xlfn.XLOOKUP(G3,硫化工艺!I:I,硫化工艺!J:J),"") -> 707.7168 | Q3: =IFERROR(ROUND(1440/L3*(I3)*M3,0),"") -> 0 | AR3: 130 | AS3: 130 | AT3: 130 | AU3: 130 | AV3: 130 | AW3: =IF(SUM(R3:AV3)=0,"",SUM(R3:AV3)) -> 650 | AX3: =IFERROR(AW3*O3/1000,"") -> 31.2975 | AY3: =IFERROR(ROUND(AW3*P3/10000,3),"") -> 46.002 | AZ3: 464.56 | BA3: 29.9 | BB3: 49.85 | BC3: 52.38 | BE3: =AZ3*AW3 -> 301964 | BF3: =BA3*AW3 -> 19435 | BG3: =BB3*AW3 -> 32402.5 | BH3: =BC3*AW3 -> 34047 | BJ3: {=_xlfn.LET(_xlpm.data,$R3:$AV3,_xlpm.starts,{1,8,16,23},_xlpm.lengths,{7,7,8,9},_xlpm.arr,_xlfn.MAP(_xlpm.starts,_xlpm.lengths,_xlfn.LAMBDA(_xlpm.s,_xlpm.l,SUM(INDEX(_xlpm.data,,_xlfn.SEQUENCE(,_xlpm.l,_xlpm.s))))),ROUND(_xlpm.arr*$O3/1000,2))} -> 0 | BK3: 0 | BL3: 0 | BM3: 31.3 | BN3: =SUM(BJ3:BM3) -> 31.3 | BO3: 0 | BP3: 0 | BQ3: 0 | BR3: 0 | BT3: {=_xlfn.HSTACK(SUM(INDEX($R3:$AV3,1,1):INDEX($R3:$AV3,1,7)),SUM(INDEX($R3:$AV3,1,7):INDEX($R3:$AV3,1,13)),SUM(INDEX($R3:$AV3,1,16):INDEX($R3:$AV3,1,23)),SUM(INDEX($R3:$AV3,1,23):INDEX($R3:$AV3,1,31)))} -> 0 | BU3: 0 | BV3: 0 | BW3: 650 | BX3: 全钢 | BY3: =SUM(R3:X3) -> 0 | BZ3: =SUM(Y3:AE3) -> 0 | CA3: =SUM(AF3:AM3) -> 0 | CB3: =SUM(AN3:AV3) -> 650 | CE3: =ROUND(BY3*$O3/1000,2) -> 0 | CF3: =ROUND(BZ3*$O3/1000,2) -> 0 | CG3: =ROUND(CA3*$O3/1000,2) -> 0 | CH3: =ROUND(CB3*$O3/1000,2) -> 31.3 | CI3: =SUM(CE3:CH3) -> 31.3 | CK3: =IFERROR(ROUND(BY3*$P3,2),"") -> 0 | CL3: =IFERROR(ROUND(BZ3*$P3,2),"") -> 0 | CM3: =IFERROR(ROUND(CA3*$P3,2),"") -> 0 | CN3: =IFERROR(ROUND(CB3*$P3,2),"") -> 460015.92 | CO3: =SUM(CK3:CN3) -> 460015.92 | CP3: =VLOOKUP(G3,[2]Sheet1!$C$3:$G$310,5,0) -> #N/A | CQ3: =VLOOKUP(G3,[3]KCBB0101!$C$3:$F$691,4,0) -> 8214
B4: =_xlfn.XLOOKUP(G4,销售需求表!A:A,销售需求表!C:C) -> 北美 | C4: =IFERROR(MID(F4,FIND("R",F4)+1,4),"") -> 22.5 | D4: =B4&C4&"寸" -> 北美22.5寸 | E4: =LEFT(REPLACE(G4,1,2,""),FIND("[",REPLACE(G4,1,2,""))-1)&"-"&MID(REPLACE(G4,1,2,""),FIND("[",REPLACE(G4,1,2,""))+1,FIND("]",REPLACE(G4,1,2,""))-FIND("[",REPLACE(G4,1,2,""))-1) -> 11R22.5-14PR(144/142M)-AT563 | F4: =IFERROR(MID(G4,3,FIND("(",G4)-3)&"-"&SUBSTITUTE(MID(G4,FIND("[",G4)+1,FIND("]",G4)-FIND("[",G4)-1),"Strong Guard ",""),"") -> 11R22.5-14PR-AT563 | G4: ID11R22.5-14PR(144/142M)[AT563]ARISUN无内 | H4: 300 | J4: =IFERROR(LEFT(F4,FIND("-",F4))&MID(F4,FIND("PR",F4,FIND("-",F4))+3,LEN(F4)),F4) -> 11R22.5-AT563 | K4: =_xlfn.XLOOKUP(F4,投产规格!E:E,投产规格!D:D,"未投产") -> ✔ | L4: =IFERROR(_xlfn.XLOOKUP(F4,硫化工艺!B:B,硫化工艺!C:C),"") -> 38.5 | M4: =IF(L4="","",L4/(L4+$L$1/60)) -> 0.86842105 | N4: =C4&"全钢" -> 22.5全钢 | O4: =IFERROR(_xlfn.XLOOKUP(F4,轮胎重量!J:J,轮胎重量!G:G),"") -> 50.98 | P4: =IFERROR(_xlfn.XLOOKUP(G4,硫化工艺!I:I,硫化工艺!J:J),"") -> 750.2593 | Q4: =IFERROR(ROUND(1440/L4*(I4)*M4,0),"") -> 0 | AN4: 60 | AO4: 60 | AP4: 60 | AQ4: 60 | AR4: 60 | AS4: 60 | AT4: 60 | AU4: 60 | AV4: 60 | AW4: =IF(SUM(R4:AV4)=0,"",SUM(R4:AV4)) -> 540 | AX4: =IFERROR(AW4*O4/1000,"") -> 27.5292 | AY4: =IFERROR(ROUND(AW4*P4/10000,3),"") -> 40.514 | AZ4: 464.56 | BA4: 29.9 | BB4: 49.85 | BC4: 52.38 | BE4: =AZ4*AW4 -> 250862.4 | BF4: =BA4*AW4 -> 16146 | BG4: =BB4*AW4 -> 26919 | BH4: =BC4*AW4 -> 28285.2 | BJ4: {=_xlfn.LET(_xlpm.data,$R4:$AV4,_xlpm.starts,{1,8,16,23},_xlpm.lengths,{7,7,8,9},_xlpm.arr,_xlfn.MAP(_xlpm.starts,_xlpm.lengths,_xlfn.LAMBDA(_xlpm.s,_xlpm.l,SUM(INDEX(_xlpm.data,,_xlfn.SEQUENCE(,_xlpm.l,_xlpm.s))))),ROUND(_xlpm.arr*$O4/1000,2))} -> 0 | BK4: 0 | BL4: 3.06 | BM4: 27.53 | BN4: =SUM(BJ4:BM4) -> 30.59 | BO4: 0 | BP4: 0 | BQ4: 0 | BR4: 0 | BT4: {=_xlfn.HSTACK(SUM(INDEX($R4:$AV4,1,1):INDEX($R4:$AV4,1,7)),SUM(INDEX($R4:$AV4,1,7):INDEX($R4:$AV4,1,13)),SUM(INDEX($R4:$AV4,1,16):INDEX($R4:$AV4,1,23)),SUM(INDEX($R4:$AV4,1,23):INDEX($R4:$AV4,1,31)))} -> 0 | BU4: 0 | BV4: 60 | BW4: 540 | BY4: =SUM(R4:X4) -> 0 | BZ4: =SUM(Y4:AE4) -> 0 | CA4: =SUM(AF4:AM4) -> 0 | CB4: =SUM(AN4:AV4) -> 540 | CE4: =ROUND(BY4*$O4/1000,2) -> 0 | CF4: =ROUND(BZ4*$O4/1000,2) -> 0 | CG4: =ROUND(CA4*$O4/1000,2) -> 0 | CH4: =ROUND(CB4*$O4/1000,2) -> 27.53 | CI4: =SUM(CE4:CH4) -> 27.53 | CK4: =IFERROR(ROUND(BY4*$P4,2),"") -> 0 | CL4: =IFERROR(ROUND(BZ4*$P4,2),"") -> 0 | CM4: =IFERROR(ROUND(CA4*$P4,2),"") -> 0 | CN4: =IFERROR(ROUND(CB4*$P4,2),"") -> 405140.02 | CO4: =SUM(CK4:CN4) -> 405140.02 | CP4: =VLOOKUP(G4,[2]Sheet1!$C$3:$G$310,5,0) -> #N/A | CQ4: =VLOOKUP(G4,[3]KCBB0101!$C$3:$F$691,4,0) -> 2573
B5: =_xlfn.XLOOKUP(G5,销售需求表!A:A,销售需求表!C:C) -> 北美 | C5: =IFERROR(MID(F5,FIND("R",F5)+1,4),"") -> 22.5 | D5: =B5&C5&"寸" -> 北美22.5寸 | E5: =LEFT(REPLACE(G5,1,2,""),FIND("[",REPLACE(G5,1,2,""))-1)&"-"&MID(REPLACE(G5,1,2,""),FIND("[",REPLACE(G5,1,2,""))+1,FIND("]",REPLACE(G5,1,2,""))-FIND("[",REPLACE(G5,1,2,""))-1) -> 11R22.5-14PR(144/142M)-CR915 | F5: =IFERROR(MID(G5,3,FIND("(",G5)-3)&"-"&SUBSTITUTE(MID(G5,FIND("[",G5)+1,FIND("]",G5)-FIND("[",G5)-1),"Strong Guard ",""),"") -> 11R22.5-14PR-CR915 | G5: ID11R22.5-14PR(144/142M)[CR915]威狮无内 | H5: 500 | J5: =IFERROR(LEFT(F5,FIND("-",F5))&MID(F5,FIND("PR",F5,FIND("-",F5))+3,LEN(F5)),F5) -> 11R22.5-CR915 | K5: =_xlfn.XLOOKUP(F5,投产规格!E:E,投产规格!D:D,"未投产") -> ✔ | L5: =IFERROR(_xlfn.XLOOKUP(F5,硫化工艺!B:B,硫化工艺!C:C),"") -> 33.5 | M5: =IF(L5="","",L5/(L5+$L$1/60)) -> 0.85169492 | N5: =C5&"全钢" -> 22.5全钢 | O5: =IFERROR(_xlfn.XLOOKUP(F5,轮胎重量!J:J,轮胎重量!G:G),"") -> 48.51 | P5: =IFERROR(_xlfn.XLOOKUP(G5,硫化工艺!I:I,硫化工艺!J:J),"") -> 708.6732 | Q5: =IFERROR(ROUND(1440/L5*(I5)*M5,0),"") -> 0 | AK5: 60 | AL5: 60 | AM5: 60 | AN5: 60 | AO5: 60 | AP5: 60 | AQ5: 60 | AR5: 60 | AS5: 60 | AT5: 60 | AU5: 60 | AV5: 60 | AW5: =IF(SUM(R5:AV5)=0,"",SUM(R5:AV5)) -> 720 | AX5: =IFERROR(AW5*O5/1000,"") -> 34.9272 | AY5: =IFERROR(ROUND(AW5*P5/10000,3),"") -> 51.024 | AZ5: 461.01 | BA5: 30.13 | BB5: 49.93 | BC5: 53.65 | BE5: =AZ5*AW5 -> 331927.2 | BF5: =BA5*AW5 -> 21693.6 | BG5: =BB5*AW5 -> 35949.6 | BH5: =BC5*AW5 -> 38628 | BJ5: {=_xlfn.LET(_xlpm.data,$R5:$AV5,_xlpm.starts,{1,8,16,23},_xlpm.lengths,{7,7,8,9},_xlpm.arr,_xlfn.MAP(_xlpm.starts,_xlpm.lengths,_xlfn.LAMBDA(_xlpm.s,_xlpm.l,SUM(INDEX(_xlpm.data,,_xlfn.SEQUENCE(,_xlpm.l,_xlpm.s))))),ROUND(_xlpm.arr*$O5/1000,2))} -> 0 | BK5: 0 | BL5: 11.64 | BM5: 26.2 | BN5: =SUM(BJ5:BM5) -> 37.84 | BO5: 111.71 | BP5: 91.4 | BQ5: 46.43 | BR5: 52.23 | BT5: {=_xlfn.HSTACK(SUM(INDEX($R5:$AV5,1,1):INDEX($R5:$AV5,1,7)),SUM(INDEX($R5:$AV5,1,7):INDEX($R5:$AV5,1,13)),SUM(INDEX($R5:$AV5,1,16):INDEX($R5:$AV5,1,23)),SUM(INDEX($R5:$AV5,1,23):INDEX($R5:$AV5,1,31)))} -> 0 | BU5: 0 | BV5: 240 | BW5: 540 | BY5: =SUM(R5:X5) -> 0 | BZ5: =SUM(Y5:AE5) -> 0 | CA5: =SUM(AF5:AM5) -> 180 | CB5: =SUM(AN5:AV5) -> 540 | CE5: =ROUND(BY5*$O5/1000,2) -> 0 | CF5: =ROUND(BZ5*$O5/1000,2) -> 0 | CG5: =ROUND(CA5*$O5/1000,2) -> 8.73 | CH5: =ROUND(CB5*$O5/1000,2) -> 26.2 | CI5: =SUM(CE5:CH5) -> 34.93 | CK5: =IFERROR(ROUND(BY5*$P5,2),"") -> 0 | CL5: =IFERROR(ROUND(BZ5*$P5,2),"") -> 0 | CM5: =IFERROR(ROUND(CA5*$P5,2),"") -> 127561.18 | CN5: =IFERROR(ROUND(CB5*$P5,2),"") -> 382683.53 | CO5: =SUM(CK5:CN5) -> 510244.71 | CP5: =VLOOKUP(G5,[2]Sheet1!$C$3:$G$310,5,0) -> 5700 | CQ5: =VLOOKUP(G5,[3]KCBB0101!$C$3:$F$691,4,0) -> #N/A
B6: =_xlfn.XLOOKUP(G6,销售需求表!A:A,销售需求表!C:C) -> 北美 | C6: =IFERROR(MID(F6,FIND("R",F6)+1,4),"") -> 22.5 | D6: =B6&C6&"寸" -> 北美22.5寸 | E6: =LEFT(REPLACE(G6,1,2,""),FIND("[",REPLACE(G6,1,2,""))-1)&"-"&MID(REPLACE(G6,1,2,""),FIND("[",REPLACE(G6,1,2,""))+1,FIND("]",REPLACE(G6,1,2,""))-FIND("[",REPLACE(G6,1,2,""))-1) -> 11R22.5-14PR(144/142M)-HT1 Plus | F6: =IFERROR(MID(G6,3,FIND("(",G6)-3)&"-"&SUBSTITUTE(MID(G6,FIND("[",G6)+1,FIND("]",G6)-FIND("[",G6)-1),"Strong Guard ",""),"") -> 11R22.5-14PR-HT1 Plus | G6: ID11R22.5-14PR(144/142M)[HT1 Plus]SUPERMAX无内 | H6: 580 | I6: 2 | J6: =IFERROR(LEFT(F6,FIND("-",F6))&MID(F6,FIND("PR",F6,FIND("-",F6))+3,LEN(F6)),F6) -> 11R22.5-HT1 Plus | K6: =_xlfn.XLOOKUP(F6,投产规格!E:E,投产规格!D:D,"未投产") -> ✔ | L6: =IFERROR(_xlfn.XLOOKUP(F6,硫化工艺!B:B,硫化工艺!C:C),"") -> 33.5 | M6: =IF(L6="","",L6/(L6+$L$1/60)) -> 0.85169492 | N6: =C6&"全钢" -> 22.5全钢 | O6: =IFERROR(_xlfn.XLOOKUP(F6,轮胎重量!J:J,轮胎重量!G:G),"") -> 48.51 | P6: =O6*13.9 -> 674.289 | Q6: =IFERROR(ROUND(1440/L6*(I6)*M6,0),"") -> 73 | R6: 66 | S6: 66 | T6: 66 | U6: 66 | V6: 66 | AW6: =IF(SUM(R6:AV6)=0,"",SUM(R6:AV6)) -> 330 | AX6: =IFERROR(AW6*O6/1000,"") -> 16.0083 | AY6: =IFERROR(ROUND(AW6*P6/10000,3),"") -> 22.252 | BE6: =AZ6*AW6 -> 0 | BF6: =BA6*AW6 -> 0 | BG6: =BB6*AW6 -> 0 | BH6: =BC6*AW6 -> 0 | BJ6: {=_xlfn.LET(_xlpm.data,$R6:$AV6,_xlpm.starts,{1,8,16,23},_xlpm.lengths,{7,7,8,9},_xlpm.arr,_xlfn.MAP(_xlpm.starts,_xlpm.lengths,_xlfn.LAMBDA(_xlpm.s,_xlpm.l,SUM(INDEX(_xlpm.data,,_xlfn.SEQUENCE(,_xlpm.l,_xlpm.s))))),ROUND(_xlpm.arr*$O6/1000,2))} -> 16.01 | BK6: 0 | BL6: 0 | BM6: 0 | BN6: =SUM(BJ6:BM6) -> 16.01 | BO6: 15.39 | BP6: 0 | BQ6: 0 | BR6: 0 | BT6: {=_xlfn.HSTACK(SUM(INDEX($R6:$AV6,1,1):INDEX($R6:$AV6,1,7)),SUM(INDEX($R6:$AV6,1,7):INDEX($R6:$AV6,1,13)),SUM(INDEX($R6:$AV6,1,16):INDEX($R6:$AV6,1,23)),SUM(INDEX($R6:$AV6,1,23):INDEX($R6:$AV6,1,31)))} -> 330 | BU6: 0 | BV6: 0 | BW6: 0 | BY6: =SUM(R6:X6) -> 330 | BZ6: =SUM(Y6:AE6) -> 0 | CA6: =SUM(AF6:AM6) -> 0 | CB6: =SUM(AN6:AV6) -> 0 | CE6: =ROUND(BY6*$O6/1000,2) -> 16.01 | CF6: =ROUND(BZ6*$O6/1000,2) -> 0 | CG6: =ROUND(CA6*$O6/1000,2) -> 0 | CH6: =ROUND(CB6*$O6/1000,2) -> 0 | CI6: =SUM(CE6:CH6) -> 16.01 | CK6: =IFERROR(ROUND(BY6*$P6,2),"") -> 222515.37 | CL6: =IFERROR(ROUND(BZ6*$P6,2),"") -> 0 | CM6: =IFERROR(ROUND(CA6*$P6,2),"") -> 0 | CN6: =IFERROR(ROUND(CB6*$P6,2),"") -> 0 | CO6: =SUM(CK6:CN6) -> 222515.37 | CP6: =VLOOKUP(G6,[2]Sheet1!$C$3:$G$310,5,0) -> #N/A | CQ6: =VLOOKUP(G6,[3]KCBB0101!$C$3:$F$691,4,0) -> 5000
B7: =_xlfn.XLOOKUP(G7,销售需求表!A:A,销售需求表!C:C) -> 北美 | C7: =IFERROR(MID(F7,FIND("R",F7)+1,4),"") -> 22.5 | D7: =B7&C7&"寸" -> 北美22.5寸 | E7: =LEFT(REPLACE(G7,1,2,""),FIND("[",REPLACE(G7,1,2,""))-1)&"-"&MID(REPLACE(G7,1,2,""),FIND("[",REPLACE(G7,1,2,""))+1,FIND("]",REPLACE(G7,1,2,""))-FIND("[",REPLACE(G7,1,2,""))-1) -> 11R22.5-14PR(144/142M)-I-48T | F7: =IFERROR(MID(G7,3,FIND("(",G7)-3)&"-"&SUBSTITUTE(MID(G7,FIND("[",G7)+1,FIND("]",G7)-FIND("[",G7)-1),"Strong Guard ",""),"") -> 11R22.5-14PR-I-48T | G7: ID11R22.5-14PR(144/142M)[I-48T]IRONMAN无内 SMARTWAY | H7: 800 | J7: =IFERROR(LEFT(F7,FIND("-",F7))&MID(F7,FIND("PR",F7,FIND("-",F7))+3,LEN(F7)),F7) -> 11R22.5-I-48T | K7: =_xlfn.XLOOKUP(F7,投产规格!E:E,投产规格!D:D,"未投产") -> ✔ | L7: =IFERROR(_xlfn.XLOOKUP(F7,硫化工艺!B:B,硫化工艺!C:C),"") -> 33.5 | M7: =IF(L7="","",L7/(L7+$L$1/60)) -> 0.85169492 | N7: =C7&"全钢" -> 22.5全钢 | O7: =IFERROR(_xlfn.XLOOKUP(F7,轮胎重量!J:J,轮胎重量!G:G),"") -> 48.51 | P7: =IFERROR(_xlfn.XLOOKUP(G7,硫化工艺!I:I,硫化工艺!J:J),"") -> 706.6458 | Q7: =IFERROR(ROUND(1440/L7*(I7)*M7,0),"") -> 0 | AI7: 60 | AJ7: 60 | AK7: 60 | AL7: 60 | AM7: 60 | AN7: 60 | AO7: 60 | AP7: 60 | AQ7: 60 | AR7: 60 | AS7: 60 | AT7: 60 | AU7: 60 | AV7: 60 | AW7: =IF(SUM(R7:AV7)=0,"",SUM(R7:AV7)) -> 840 | AX7: =IFERROR(AW7*O7/1000,"") -> 40.7484 | AY7: =IFERROR(ROUND(AW7*P7/10000,3),"") -> 59.358 | BE7: =AZ7*AW7 -> 0 | BF7: =BA7*AW7 -> 0 | BG7: =BB7*AW7 -> 0 | BH7: =BC7*AW7 -> 0 | BJ7: {=_xlfn.LET(_xlpm.data,$R7:$AV7,_xlpm.starts,{1,8,16,23},_xlpm.lengths,{7,7,8,9},_xlpm.arr,_xlfn.MAP(_xlpm.starts,_xlpm.lengths,_xlfn.LAMBDA(_xlpm.s,_xlpm.l,SUM(INDEX(_xlpm.data,,_xlfn.SEQUENCE(,_xlpm.l,_xlpm.s))))),ROUND(_xlpm.arr*$O7/1000,2))} -> 0 | BK7: 0 | BL7: 17.46 | BM7: 26.2 | BN7: =SUM(BJ7:BM7) -> 43.66 | BO7: 22.16 | BP7: 22.16 | BQ7: 25.32 | BR7: 28.49 | BT7: {=_xlfn.HSTACK(SUM(INDEX($R7:$AV7,1,1):INDEX($R7:$AV7,1,7)),SUM(INDEX($R7:$AV7,1,7):INDEX($R7:$AV7,1,13)),SUM(INDEX($R7:$AV7,1,16):INDEX($R7:$AV7,1,23)),SUM(INDEX($R7:$AV7,1,23):INDEX($R7:$AV7,1,31)))} -> 0 | BU7: 0 | BV7: 360 | BW7: 540 | BY7: =SUM(R7:X7) -> 0 | BZ7: =SUM(Y7:AE7) -> 0 | CA7: =SUM(AF7:AM7) -> 300 | CB7: =SUM(AN7:AV7) -> 540 | CE7: =ROUND(BY7*$O7/1000,2) -> 0 | CF7: =ROUND(BZ7*$O7/1000,2) -> 0 | CG7: =ROUND(CA7*$O7/1000,2) -> 14.55 | CH7: =ROUND(CB7*$O7/1000,2) -> 26.2 | CI7: =SUM(CE7:CH7) -> 40.75 | CK7: =IFERROR(ROUND(BY7*$P7,2),"") -> 0 | CL7: =IFERROR(ROUND(BZ7*$P7,2),"") -> 0 | CM7: =IFERROR(ROUND(CA7*$P7,2),"") -> 211993.74 | CN7: =IFERROR(ROUND(CB7*$P7,2),"") -> 381588.73 | CO7: =SUM(CK7:CN7) -> 593582.47 | CP7: =VLOOKUP(G7,[2]Sheet1!$C$3:$G$310,5,0) -> 7500 | CQ7: =VLOOKUP(G7,[3]KCBB0101!$C$3:$F$691,4,0) -> #N/A
B8: =_xlfn.XLOOKUP(G8,销售需求表!A:A,销售需求表!C:C) -> 北美 | C8: =IFERROR(MID(F8,FIND("R",F8)+1,4),"") -> 22.5 | D8: =B8&C8&"寸" -> 北美22.5寸 | E8: =LEFT(REPLACE(G8,1,2,""),FIND("[",REPLACE(G8,1,2,""))-1)&"-"&MID(REPLACE(G8,1,2,""),FIND("[",REPLACE(G8,1,2,""))+1,FIND("]",REPLACE(G8,1,2,""))-FIND("[",REPLACE(G8,1,2,""))-1) -> 11R22.5-14PR(144/142M)-M-TRAC TR | F8: =IFERROR(MID(G8,3,FIND("(",G8)-3)&"-"&SUBSTITUTE(MID(G8,FIND("[",G8)+1,FIND("]",G8)-FIND("[",G8)-1),"Strong Guard ",""),"") -> 11R22.5-14PR-M-TRAC TR | G8: ID11R22.5-14PR(144/142M)[M-TRAC TR]MASTERTRACK无内 | H8: 620 | J8: =IFERROR(LEFT(F8,FIND("-",F8))&MID(F8,FIND("PR",F8,FIND("-",F8))+3,LEN(F8)),F8) -> 11R22.5-M-TRAC TR | K8: =_xlfn.XLOOKUP(F8,投产规格!E:E,投产规格!D:D,"未投产") -> ✔ | L8: =IFERROR(_xlfn.XLOOKUP(F8,硫化工艺!B:B,硫化工艺!C:C),"") -> 33.5 | M8: =IF(L8="","",L8/(L8+$L$1/60)) -> 0.85169492 | N8: =C8&"全钢" -> 22.5全钢 | O8: =IFERROR(_xlfn.XLOOKUP(F8,轮胎重量!J:J,轮胎重量!G:G),"") -> 59.57 | P8: =O8*13.9 -> 828.023 | Q8: =IFERROR(ROUND(1440/L8*(I8)*M8,0),"") -> 0 | AI8: 60 | AJ8: 60 | AK8: 60 | AL8: 60 | AM8: 60 | AN8: 60 | AO8: 60 | AP8: 60 | AQ8: 60 | AR8: 60 | AW8: =IF(SUM(R8:AV8)=0,"",SUM(R8:AV8)) -> 600 | AX8: =IFERROR(AW8*O8/1000,"") -> 35.742 | AY8: =IFERROR(ROUND(AW8*P8/10000,3),"") -> 49.681 | BE8: =AZ8*AW8 -> 0 | BF8: =BA8*AW8 -> 0 | BG8: =BB8*AW8 -> 0 | BH8: =BC8*AW8 -> 0 | BJ8: {=_xlfn.LET(_xlpm.data,$R8:$AV8,_xlpm.starts,{1,8,16,23},_xlpm.lengths,{7,7,8,9},_xlpm.arr,_xlfn.MAP(_xlpm.starts,_xlpm.lengths,_xlfn.LAMBDA(_xlpm.s,_xlpm.l,SUM(INDEX(_xlpm.data,,_xlfn.SEQUENCE(,_xlpm.l,_xlpm.s))))),ROUND(_xlpm.arr*$O8/1000,2))} -> 0 | BK8: 0 | BL8: 21.45 | BM8: 17.87 | BN8: =SUM(BJ8:BM8) -> 39.32 | BO8: 0 | BP8: 0 | BQ8: 0 | BR8: 0 | BT8: {=_xlfn.HSTACK(SUM(INDEX($R8:$AV8,1,1):INDEX($R8:$AV8,1,7)),SUM(INDEX($R8:$AV8,1,7):INDEX($R8:$AV8,1,13)),SUM(INDEX($R8:$AV8,1,16):INDEX($R8:$AV8,1,23)),SUM(INDEX($R8:$AV8,1,23):INDEX($R8:$AV8,1,31)))} -> 0 | BU8: 0 | BV8: 360 | BW8: 300 | BY8: =SUM(R8:X8) -> 0 | BZ8: =SUM(Y8:AE8) -> 0 | CA8: =SUM(AF8:AM8) -> 300 | CB8: =SUM(AN8:AV8) -> 300 | CE8: =ROUND(BY8*$O8/1000,2) -> 0 | CF8: =ROUND(BZ8*$O8/1000,2) -> 0 | CG8: =ROUND(CA8*$O8/1000,2) -> 17.87 | CH8: =ROUND(CB8*$O8/1000,2) -> 17.87 | CI8: =SUM(CE8:CH8) -> 35.74 | CK8: =IFERROR(ROUND(BY8*$P8,2),"") -> 0 | CL8: =IFERROR(ROUND(BZ8*$P8,2),"") -> 0 | CM8: =IFERROR(ROUND(CA8*$P8,2),"") -> 248406.9 | CN8: =IFERROR(ROUND(CB8*$P8,2),"") -> 248406.9 | CO8: =SUM(CK8:CN8) -> 496813.8 | CP8: =VLOOKUP(G8,[2]Sheet1!$C$3:$G$310,5,0) -> #N/A | CQ8: =VLOOKUP(G8,[3]KCBB0101!$C$3:$F$691,4,0) -> 8000
B9: =_xlfn.XLOOKUP(G9,销售需求表!A:A,销售需求表!C:C) -> 北美 | C9: =IFERROR(MID(F9,FIND("R",F9)+1,4),"") -> 22.5 | D9: =B9&C9&"寸" -> 北美22.5寸 | E9: =LEFT(REPLACE(G9,1,2,""),FIND("[",REPLACE(G9,1,2,""))-1)&"-"&MID(REPLACE(G9,1,2,""),FIND("[",REPLACE(G9,1,2,""))+1,FIND("]",REPLACE(G9,1,2,""))-FIND("[",REPLACE(G9,1,2,""))-1) -> 11R22.5-14PR(144/142M)-Strong Guard H-TL | F9: =IFERROR(MID(G9,3,FIND("(",G9)-3)&"-"&SUBSTITUTE(MID(G9,FIND("[",G9)+1,FIND("]",G9)-FIND("[",G9)-1),"Strong Guard ",""),"") -> 11R22.5-14PR-H-TL | G9: ID11R22.5-14PR(144/142M)[Strong Guard H-TL]HERCULES无内 | H9: 280 | J9: =IFERROR(LEFT(F9,FIND("-",F9))&MID(F9,FIND("PR",F9,FIND("-",F9))+3,LEN(F9)),F9) -> 11R22.5-H-TL | K9: =_xlfn.XLOOKUP(F9,投产规格!E:E,投产规格!D:D,"未投产") -> ✔ | L9: =IFERROR(_xlfn.XLOOKUP(F9,硫化工艺!B:B,硫化工艺!C:C),"") -> 34 | M9: =IF(L9="","",L9/(L9+$L$1/60)) -> 0.85355649 | N9: =C9&"全钢" -> 22.5全钢 | O9: =IFERROR(_xlfn.XLOOKUP(F9,轮胎重量!J:J,轮胎重量!G:G),"") -> 49.075 | P9: =IFERROR(_xlfn.XLOOKUP(G9,硫化工艺!I:I,硫化工艺!J:J),"") -> 711.92999 | Q9: =IFERROR(ROUND(1440/L9*(I9)*M9,0),"") -> 0 | AN9: 60 | AO9: 60 | AP9: 60 | AQ9: 60 | AR9: 60 | AS9: 60 | AT9: 60 | AU9: 60 | AV9: 60 | AW9: =IF(SUM(R9:AV9)=0,"",SUM(R9:AV9)) -> 540 | AX9: =IFERROR(AW9*O9/1000,"") -> 26.5005 | AY9: =IFERROR(ROUND(AW9*P9/10000,3),"") -> 38.444 | BE9: =AZ9*AW9 -> 0 | BF9: =BA9*AW9 -> 0 | BG9: =BB9*AW9 -> 0 | BH9: =BC9*AW9 -> 0 | BJ9: {=_xlfn.LET(_xlpm.data,$R9:$AV9,_xlpm.starts,{1,8,16,23},_xlpm.lengths,{7,7,8,9},_xlpm.arr,_xlfn.MAP(_xlpm.starts,_xlpm.lengths,_xlfn.LAMBDA(_xlpm.s,_xlpm.l,SUM(INDEX(_xlpm.data,,_xlfn.SEQUENCE(,_xlpm.l,_xlpm.s))))),ROUND(_xlpm.arr*$O9/1000,2))} -> 0 | BK9: 0 | BL9: 2.94 | BM9: 26.5 | BN9: =SUM(BJ9:BM9) -> 29.44 | BO9: 0 | BP9: 0 | BQ9: 0 | BR9: 0 | BT9: {=_xlfn.HSTACK(SUM(INDEX($R9:$AV9,1,1):INDEX($R9:$AV9,1,7)),SUM(INDEX($R9:$AV9,1,7):INDEX($R9:$AV9,1,13)),SUM(INDEX($R9:$AV9,1,16):INDEX($R9:$AV9,1,23)),SUM(INDEX($R9:$AV9,1,23):INDEX($R9:$AV9,1,31)))} -> 0 | BU9: 0 | BV9: 60 | BW9: 540 | BY9: =SUM(R9:X9) -> 0 | BZ9: =SUM(Y9:AE9) -> 0 | CA9: =SUM(AF9:AM9) -> 0 | CB9: =SUM(AN9:AV9) -> 540 | CE9: =ROUND(BY9*$O9/1000,2) -> 0 | CF9: =ROUND(BZ9*$O9/1000,2) -> 0 | CG9: =ROUND(CA9*$O9/1000,2) -> 0 | CH9: =ROUND(CB9*$O9/1000,2) -> 26.5 | CI9: =SUM(CE9:CH9) -> 26.5 | CK9: =IFERROR(ROUND(BY9*$P9,2),"") -> 0 | CL9: =IFERROR(ROUND(BZ9*$P9,2),"") -> 0 | CM9: =IFERROR(ROUND(CA9*$P9,2),"") -> 0 | CN9: =IFERROR(ROUND(CB9*$P9,2),"") -> 384442.2 | CO9: =SUM(CK9:CN9) -> 384442.2 | CP9: =VLOOKUP(G9,[2]Sheet1!$C$3:$G$310,5,0) -> 11500 | CQ9: =VLOOKUP(G9,[3]KCBB0101!$C$3:$F$691,4,0) -> #N/A
B10: =_xlfn.XLOOKUP(G10,销售需求表!A:A,销售需求表!C:C) -> 北美 | C10: =IFERROR(MID(F10,FIND("R",F10)+1,4),"") -> 22.5 | D10: =B10&C10&"寸" -> 北美22.5寸 | E10: =LEFT(REPLACE(G10,1,2,""),FIND("[",REPLACE(G10,1,2,""))-1)&"-"&MID(REPLACE(G10,1,2,""),FIND("[",REPLACE(G10,1,2,""))+1,FIND("]",REPLACE(G10,1,2,""))-FIND("[",REPLACE(G10,1,2,""))-1) -> 11R22.5-16PR(146/143L)-DOMINATE D01 | F10: =IFERROR(MID(G10,3,FIND("(",G10)-3)&"-"&SUBSTITUTE(MID(G10,FIND("[",G10)+1,FIND("]",G10)-FIND("[",G10)-1),"Strong Guard ",""),"") -> 11R22.5-16PR-DOMINATE D01 | G10: ID11R22.5-16PR(146/143L)[DOMINATE D01]BLACKARROW无内 | H10: 280 | J10: =IFERROR(LEFT(F10,FIND("-",F10))&MID(F10,FIND("PR",F10,FIND("-",F10))+3,LEN(F10)),F10) -> 11R22.5-DOMINATE D01 | K10: =_xlfn.XLOOKUP(F10,投产规格!E:E,投产规格!D:D,"未投产") -> 未投产 | L10: =IFERROR(_xlfn.XLOOKUP(F10,硫化工艺!B:B,硫化工艺!C:C),"") -> 37 | M10: =IF(L10="","",L10/(L10+$L$1/60)) -> 0.86381323 | N10: =C10&"全钢" -> 22.5全钢 | O10: =IFERROR(_xlfn.XLOOKUP(F10,轮胎重量!J:J,轮胎重量!G:G),"") -> 58.509 | P10: =IFERROR(_xlfn.XLOOKUP(G10,硫化工艺!I:I,硫化工艺!J:J),"") -> 854.69822 | Q10: =IFERROR(ROUND(1440/L10*(I10)*M10,0),"") -> 0 | AW10: =IF(SUM(R10:AV10)=0,"",SUM(R10:AV10)) | AX10: =IFERROR(AW10*O10/1000,"") | AY10: =IFERROR(ROUND(AW10*P10/10000,3),"") | BE10: =AZ10*AW10 -> #VALUE! | BF10: =BA10*AW10 -> #VALUE! | BG10: =BB10*AW10 -> #VALUE! | BH10: =BC10*AW10 -> #VALUE! | BJ10: {=_xlfn.LET(_xlpm.data,$R10:$AV10,_xlpm.starts,{1,8,16,23},_xlpm.lengths,{7,7,8,9},_xlpm.arr,_xlfn.MAP(_xlpm.starts,_xlpm.lengths,_xlfn.LAMBDA(_xlpm.s,_xlpm.l,SUM(INDEX(_xlpm.data,,_xlfn.SEQUENCE(,_xlpm.l,_xlpm.s))))),ROUND(_xlpm.arr*$O10/1000,2))} -> 0 | BK10: 0 | BL10: 0 | BM10: 0 | BN10: =SUM(BJ10:BM10) -> 0 | BO10: 0 | BP10: 0 | BQ10: 0 | BR10: 0 | BT10: {=_xlfn.HSTACK(SUM(INDEX($R10:$AV10,1,1):INDEX($R10:$AV10,1,7)),SUM(INDEX($R10:$AV10,1,7):INDEX($R10:$AV10,1,13)),SUM(INDEX($R10:$AV10,1,16):INDEX($R10:$AV10,1,23)),SUM(INDEX($R10:$AV10,1,23):INDEX($R10:$AV10,1,31)))} -> 0 | BU10: 0 | BV10: 0 | BW10: 0 | BY10: =SUM(R10:X10) -> 0 | BZ10: =SUM(Y10:AE10) -> 0 | CA10: =SUM(AF10:AM10) -> 0 | CB10: =SUM(AN10:AV10) -> 0 | CE10: =ROUND(BY10*$O10/1000,2) -> 0 | CF10: =ROUND(BZ10*$O10/1000,2) -> 0 | CG10: =ROUND(CA10*$O10/1000,2) -> 0 | CH10: =ROUND(CB10*$O10/1000,2) -> 0 | CI10: =SUM(CE10:CH10) -> 0 | CK10: =IFERROR(ROUND(BY10*$P10,2),"") -> 0 | CL10: =IFERROR(ROUND(BZ10*$P10,2),"") -> 0 | CM10: =IFERROR(ROUND(CA10*$P10,2),"") -> 0 | CN10: =IFERROR(ROUND(CB10*$P10,2),"") -> 0 | CO10: =SUM(CK10:CN10) -> 0
B11: =_xlfn.XLOOKUP(G11,销售需求表!A:A,销售需求表!C:C) -> 北美 | C11: =IFERROR(MID(F11,FIND("R",F11)+1,4),"") -> 22.5 | D11: =B11&C11&"寸" -> 北美22.5寸 | E11: =LEFT(REPLACE(G11,1,2,""),FIND("[",REPLACE(G11,1,2,""))-1)&"-"&MID(REPLACE(G11,1,2,""),FIND("[",REPLACE(G11,1,2,""))+1,FIND("]",REPLACE(G11,1,2,""))-FIND("[",REPLACE(G11,1,2,""))-1) -> 11R22.5-16PR(146/143L)-HD1 PlusX | F11: =IFERROR(MID(G11,3,FIND("(",G11)-3)&"-"&SUBSTITUTE(MID(G11,FIND("[",G11)+1,FIND("]",G11)-FIND("[",G11)-1),"Strong Guard ",""),"") -> 11R22.5-16PR-HD1 PlusX | G11: ID11R22.5-16PR(146/143L)[HD1 PlusX]SUPERMAX ECO无内 | H11: 750 | J11: =IFERROR(LEFT(F11,FIND("-",F11))&MID(F11,FIND("PR",F11,FIND("-",F11))+3,LEN(F11)),F11) -> 11R22.5-HD1 PlusX | K11: =_xlfn.XLOOKUP(F11,投产规格!E:E,投产规格!D:D,"未投产") -> 未投产 | L11: =IFERROR(_xlfn.XLOOKUP(F11,硫化工艺!B:B,硫化工艺!C:C),"") -> 38 | M11: =IF(L11="","",L11/(L11+$L$1/60)) -> 0.86692015 | N11: =C11&"全钢" -> 22.5全钢 | O11: =IFERROR(_xlfn.XLOOKUP(F11,轮胎重量!J:J,轮胎重量!G:G),"") -> 54.54 | P11: =IFERROR(_xlfn.XLOOKUP(G11,硫化工艺!I:I,硫化工艺!J:J),"") -> 748.79548 | Q11: =IFERROR(ROUND(1440/L11*(I11)*M11,0),"") -> 0 | AW11: =IF(SUM(R11:AV11)=0,"",SUM(R11:AV11)) | AX11: =IFERROR(AW11*O11/1000,"") | AY11: =IFERROR(ROUND(AW11*P11/10000,3),"") | BE11: =AZ11*AW11 -> #VALUE! | BF11: =BA11*AW11 -> #VALUE! | BG11: =BB11*AW11 -> #VALUE! | BH11: =BC11*AW11 -> #VALUE! | BJ11: {=_xlfn.LET(_xlpm.data,$R11:$AV11,_xlpm.starts,{1,8,16,23},_xlpm.lengths,{7,7,8,9},_xlpm.arr,_xlfn.MAP(_xlpm.starts,_xlpm.lengths,_xlfn.LAMBDA(_xlpm.s,_xlpm.l,SUM(INDEX(_xlpm.data,,_xlfn.SEQUENCE(,_xlpm.l,_xlpm.s))))),ROUND(_xlpm.arr*$O11/1000,2))} -> 0 | BK11: 0 | BL11: 0 | BM11: 0 | BN11: =SUM(BJ11:BM11) -> 0 | BO11: 0 | BP11: 0 | BQ11: 0 | BR11: 0 | BT11: {=_xlfn.HSTACK(SUM(INDEX($R11:$AV11,1,1):INDEX($R11:$AV11,1,7)),SUM(INDEX($R11:$AV11,1,7):INDEX($R11:$AV11,1,13)),SUM(INDEX($R11:$AV11,1,16):INDEX($R11:$AV11,1,23)),SUM(INDEX($R11:$AV11,1,23):INDEX($R11:$AV11,1,31)))} -> 0 | BU11: 0 | BV11: 0 | BW11: 0 | BY11: =SUM(R11:X11) -> 0 | BZ11: =SUM(Y11:AE11) -> 0 | CA11: =SUM(AF11:AM11) -> 0 | CB11: =SUM(AN11:AV11) -> 0 | CE11: =ROUND(BY11*$O11/1000,2) -> 0 | CF11: =ROUND(BZ11*$O11/1000,2) -> 0 | CG11: =ROUND(CA11*$O11/1000,2) -> 0 | CH11: =ROUND(CB11*$O11/1000,2) -> 0 | CI11: =SUM(CE11:CH11) -> 0 | CK11: =IFERROR(ROUND(BY11*$P11,2),"") -> 0 | CL11: =IFERROR(ROUND(BZ11*$P11,2),"") -> 0 | CM11: =IFERROR(ROUND(CA11*$P11,2),"") -> 0 | CN11: =IFERROR(ROUND(CB11*$P11,2),"") -> 0 | CO11: =SUM(CK11:CN11) -> 0
